Workbook

Sheet 🌱 Configuração
B2: 🌿 PLANILHA MESTRA DE CULTIVO — Cannabis Medicinal Indoor
B3: Configure abaixo. As durações em SEMANAS se propagam automaticamente por toda a planilha.
B5: ⚙️ CONFIGURAÇÕES DO CULTIVO — preencha as células destacadas
B6: 📅 Data Dia 1 (Clone) | D6: 46023 | F6: 🌱 Semanas de Clone | H6: 2 | J6: ← sem (1–4)
B7: 🌿 Strain / Cultivar | D7: Ex: Blue Dream, OG Kush | F7: 🌿 Semanas de Vegetativo | H7: 6 | J7: ← sem (4–12)
B8: 💡 Ambiente | D8: Indoor LED | F8: 🌸 Semanas de Floração | H8: 9 | J8: ← sem (8–16)
B9: 📐 Área de cultivo (m²) | D9: 1.2 | F9: 🚿 Semanas de Flush | H9: 1 | J9: ← sem (1–2)
B10: 🪴 Nº de Plantas | D10: 4
B11: 🌡️ PARÂMETROS AMBIENTAIS (opcionais — para referência no diário)
B12: 🔆 Horas de luz — Vega | D12: 18 | F12: 🔆 Horas de luz — Flora | H12: 12
B13: 🌡️ Temperatura ideal (°C) | D13: 24 | F13: 💧 Umidade Vega (%) | H13: 65
B14: 💧 Umidade Flora (%) | D14: 50 | F14: 💧 Umidade Flora final (%) | H14: 40
B16: 📆 CALENDÁRIO DE FASES (calculado automaticamente)
B17: Fase | D17: Semanas | F17: Início | H17: Fim | J17: Total dias
B18: 🌱 CLONE | D18: =H6&" sem" -> 2 sem | F18: =B51 -> 46023 | H18: =B51+B50-1 -> 46036 | J18: =B50 -> 14
B19: 🌿 VEGETATIVO | D19: =H7&" sem" -> 6 sem | F19: =C51 -> 46037 | H19: =C51+C50-1 -> 46078 | J19: =C50 -> 42
B20: 🌸 FLORAÇÃO | D20: =H8&" sem" -> 9 sem | F20: =D51 -> 46079 | H20: =D51+D50-1 -> 46141 | J20: =D50 -> 63
B21: 🚿 FLUSH | D21: =H9&" sem" -> 1 sem | F21: =E51 -> 46142 | H21: =E51+E50-1 -> 46148 | J21: =E50 -> 7
B22: ✂️ COLHEITA | D22: "—" | F22: =F51 -> 46149 | H22: =F51 -> 46149 | J22: "1 dia"
B24: 📌 COMO USAR — Altere as semanas (células amarelas) e toda a planilha se recalcula
B25: 🟡 Célula amarela (data) | F25: Preencha a Data do Dia 1 do clone
B26: 🟡 Células amarelas (sem) | F26: Escolha o nº de semanas de cada fase no dropdown
B27: 📅 Aba Cronograma | F27: Gerado automaticamente — mostra apenas os dias do seu cultivo
B28: 💊 Aba Adubação | F28: Datas calculadas por semana relativa à fase (Vega S1, Flora S3, etc.)
B29: 🐛 Aba MIP | F29: Calendário de aplicações ajustado às fases configuradas
B30: 📊 Aba Diário | F30: Linhas geradas conforme duração total configurada
B50: =H6*7 -> 14 | C50: =H7*7 -> 42 | D50: =H8*7 -> 63 | E50: =H9*7 -> 7 | F50: =B50+C50+D50+E50 -> 126
B51: =D6 -> 46023 | C51: =B51+B50 -> 46037 | D51: =C51+C50 -> 46079 | E51: =D51+D50 -> 46142 | F51: =E51+E50 -> 46149

Sheet 📅 Cronograma
B2: 📅 CRONOGRAMA COMPLETO DO CULTIVO — Dinâmico por Semanas
B3: Calculado automaticamente. Linhas além do total configurado ficam em branco.
B5: Dia | C5: Data | D5: Fase | E5: Semana | F5: Adubação | G5: MIP / Pragas | H5: Ação / Alerta
B6: =IF(1<='🌱 Configuração'!$F$50,1,"") -> 1 | C6: =IF(1<='🌱 Configuração'!$F$50,'🌱 Configuração'!$B$51+0,"") -> 46023 | D6: =IF(1>'🌱 Configuração'!$F$50,"",IF('🌱 Configuração'!$B$51+0<'🌱 Configuração'!$C$51,"🌱 Clone",IF('🌱 Configuração'!$B$51+0<'🌱 Configuração'!$D$51,"🌿 Vegetativo",IF('🌱 Configuração'!$B$51+0<'🌱 Configuração'!$E$51,"🌸 Floração","🚿 Flush")))) -> 🌱 Clone | E6: =IF(1>'🌱 Configuração'!$F$50,"",IF('🌱 Configuração'!$B$51+0<'🌱 Configuração'!$C$51,"Clone S"&INT((1-1)/7)+1,IF('🌱 Configuração'!$B$51+0<'🌱 Configuração'!$D$51,"Vega S"&INT(('🌱 Configuração'!$B$51+0-'🌱 Configuração'!$C$51)/7)+1,IF('🌱 Configuração'!$B$51+0<'🌱 Configuração'!$E$51,"Flora S"&INT(('🌱 Configuração'!$B$51+0-'🌱 Configuração'!$D$51)/7)+1,"Flush S"&INT(('🌱 Configuração'!$B$51+0-'🌱 Configuração'!$E$51)/7)+1)))) -> Clone S1 | F6: =IF(1>'🌱 Configuração'!$F$50,"",IF(AND('🌱 Configuração'!$B$51+0<'🌱 Configuração'!$C$51,INT((1-1)/7)+1=1,MOD(1-1,7)=0),"🌱 Enraizador (0.5 mL/L)",IF(AND('🌱 Configuração'!$B$51+0<'🌱 Configuração'!$C$51,INT((1-1)/7)+1=2,MOD(1-1,7)=0),"🌱 Enraizador + Vitamina B1",IF(AND('🌱 Configuração'!$B$51+0>='🌱 Configuração'!$C$51,'🌱 Configuração'!$B$51+0<'🌱 Configuração'!$D$51,INT(('🌱 Configuração'!$B$51+0-'🌱 Configuração'!$C$51)/7)+1=1,MOD('🌱 Configuração'!$B$51+0-'🌱 Configuração'!$C$51,7)=0),"🌿 Grow A+B início — EC 0.8",IF(AND('🌱 Configuração'!$B$51+0>='🌱 Configuração'!$C$51,'🌱 Configuração'!$B$51+0<'🌱 Configuração'!$D$51,INT(('🌱 Configuração'!$B$51+0-'🌱 Configuração'!$C$51)/7)+1=2,MOD('🌱 Configuração'!$B$51+0-'🌱 Configuração'!$C$51,7)=0),"🌿 Grow A+B + CalMag — EC 1.0",IF(AND('🌱 Configuração'!$B$51+0>='🌱 Configuração'!$C$51,'🌱 Configuração'!$B$51+0<'🌱 Configuração'!$D$51,INT(('🌱 Configuração'!$B$51+0-'🌱 Configuração'!$C$51)/7)+1=3,MOD('🌱 Configuração'!$B$51+0-'🌱 Configuração'!$C$51,7)=0),"🌿 Grow A+B + CalMag — EC 1.2",IF(AND('🌱 Configuração'!$B$51+0>='🌱 Configuração'!$C$51,'🌱 Configuração'!$B$51+0<'🌱 Configuração'!$D$51,INT(('🌱 Configuração'!$B$51+0-'🌱 Configuração'!$C$51)/7)+1=4,MOD('🌱 Configuração'!$B$51+0-'🌱 Configuração'!$C$51,7)=0),"🌿 Grow A+B + Enzimas — EC 1.4",IF(AND('🌱 Configuração'!$B$51+0>='🌱 Configuração'!$C$51,'🌱 Configuração'!$B$51+0<'🌱 Configuração'!$D$51,INT(('🌱 Configuração'!$B$51+0-'🌱 Configuração'!$C$51)/7)+1=5,MOD('🌱 Configuração'!$B$51+0-'🌱 Configuração'!$C$51,7)=0),"🌿 Grow A+B + Biorrizas — EC 1.5",IF(AND('🌱 Configuração'!$B$51+0>='🌱 Configuração'!$C$51,'🌱 Configuração'!$B$51+0<'🌱 Configuração'!$D$51,INT(('🌱 Configuração'!$B$51+0-'🌱 Configuração'!$C$51)/7)+1=6,MOD('🌱 Configuração'!$B$51+0-'🌱 Configuração'!$C$51,7)=0),"🌿 Transição Bloom — EC 1.4",IF(AND('🌱 Configuração'!$B$51+0>='🌱 Configuração'!$C$51,'🌱 Configuração'!$B$51+0<'🌱 Configuração'!$D$51,INT(('🌱 Configuração'!$B$51+0-'🌱 Configuração'!$C$51)/7)+1=7,MOD('🌱 Configuração'!$B$51+0-'🌱 Configuração'!$C$51,7)=0),"🌿 Bloom A+B transição — EC 1.4",IF(AND('🌱 Configuração'!$B$51+0>='🌱 Configuração'!$C$51,'🌱 Configuração'!$B$51+0<'🌱 Configuração'!$D$51,INT(('🌱 Configuração'!$B$51+0-'🌱 Configuração'!$C$51)/7)+1=8,MOD('🌱 Configuração'!$B$51+0-'🌱 Configuração'!$C$51,7)=0),"🌿 Bloom A+B — EC 1.4",IF(AND('🌱 Configuração'!$B$51+0>='🌱 Configuração'!$D$51,'🌱 Configuração'!$B$51+0<'🌱 Configuração'!$E$51,INT(('🌱 Configuração'!$B$51+0-'🌱 Configuração'!$D$51)/7)+1=1,MOD('🌱 Configuração'!$B$51+0-'🌱 Configuração'!$D$51,7)=0),"🌸 Bloom A+B — EC 1.6",IF(AND('🌱 Configuração'!$B$51+0>='🌱 Configuração'!$D$51,'🌱 Configuração'!$B$51+0<'🌱 Configuração'!$E$51,INT(('🌱 Configuração'!$B$51+0-'🌱 Configuração'!$D$51)/7)+1=2,MOD('🌱 Configuração'!$B$51+0-'🌱 Configuração'!$D$51,7)=0),"🌸 Bloom + PK 13/14 início",IF(AND('🌱 Configuração'!$B$51+0>='🌱 Configuração'!$D$51,'🌱 Configuração'!$B$51+0<'🌱 Configuração'!$E$51,INT(('🌱 Configuração'!$B$51+0-'🌱 Configuração'!$D$51)/7)+1=3,MOD('🌱 Configuração'!$B$51+0-'🌱 Configuração'!$D$51,7)=0),"🌸 Bloom + PK + CalMag — EC 1.8",IF(AND('🌱 Configuração'!$B$51+0>='🌱 Configuração'!$D$51,'🌱 Configuração'!$B$51+0<'🌱 Configuração'!$E$51,INT(('🌱 Configuração'!$B$51+0-'🌱 Configuração'!$D$51)/7)+1=4,MOD('🌱 Configuração'!$B$51+0-'🌱 Configuração'!$D$51,7)=0),"🌸 Bloom + PK + Boost Floral — EC 2.0",IF(AND('🌱 Configuração'!$B$51+0>='🌱 Configuração'!$D$51,'🌱 Configuração'!$B$51+0<'🌱 Configuração'!$E$51,INT(('🌱 Configuração'!$B$51+0-'🌱 Configuração'!$D$51)/7)+1=5,MOD('🌱 Configuração'!$B$51+0-'🌱 Configuração'!$D$51,7)=0),"🌸 Bloom + Boost + Amino",IF(AND('🌱 Configuração'!$B$51+0>='🌱 Configuração'!$D$51,'🌱 Configuração'!$B$51+0<'🌱 Configuração'!$E$51,INT(('🌱 Configuração'!$B$51+0-'🌱 Configuração'!$D$51)/7)+1=6,MOD('🌱 Configuração'!$B$51+0-'🌱 Configuração'!$D$51,7)=0),"🌸 Bloom + Enzimas + Amino",IF(AND('🌱 Configuração'!$B$51+0>='🌱 Configuração'!$D$51,'🌱 Configuração'!$B$51+0<'🌱 Configuração'!$E$51,INT(('🌱 Configuração'!$B$51+0-'🌱 Configuração'!$D$51)/7)+1=7,MOD('🌱 Configuração'!$B$51+0-'🌱 Configuração'!$D$51,7)=0),"🌸 Reduzir N — Bloom puro — EC 1.6",IF(AND('🌱 Configuração'!$B$51+0>='🌱 Configuração'!$D$51,'🌱 Configuração'!$B$51+0<'🌱 Configuração'!$E$51,INT(('🌱 Configuração'!$B$51+0-'🌱 Configuração'!$D$51)/7)+1=8,MOD('🌱 Configuração'!$B$51+0-'🌱 Configuração'!$D$51,7)=0),"🌸 Bloom puro — EC 1.4 (pré-flush)",IF(AND('🌱 Configuração'!$B$51+0>='🌱 Configuração'!$D$51,'🌱 Configuração'!$B$51+0<'🌱 Configuração'!$E$51,INT(('🌱 Configuração'!$B$51+0-'🌱 Configuração'!$D$51)/7)+1=9,MOD('🌱 Configuração'!$B$51+0-'🌱 Configuração'!$D$51,7)=0),"🌸 Último Bloom — EC 0.8",IF(AND('🌱 Configuração'!$B$51+0>='🌱 Configuração'!$E$51,INT(('🌱 Configuração'!$B$51+0-'🌱 Configuração'!$E$51)/7)+1=1,MOD('🌱 Configuração'!$B$51+0-'🌱 Configuração'!$E$51,7)=0),"🚿 Água pura + Enzimas (EC < 0.3)",IF(AND('🌱 Configuração'!$B$51+0>='🌱 Configuração'!$E$51,INT(('🌱 Configuração'!$B$51+0-'🌱 Configuração'!$E$51)/7)+1=2,MOD('🌱 Configuração'!$B$51+0-'🌱 Configuração'!$E$51,7)=0),"🚿 Água pura (EC < 0.2)","")))))))))))))))))))))) -> 🌱 Enraizador (0.5 mL/L) | G6: =IF(1>'🌱 Configuração'!$F$50,"",IF(AND('🌱 Configuração'!$B$51+0<'🌱 Configuração'!$C$51,INT((1-1)/7)+1=1,MOD(1-1,7)=0),"🐛 Nim 2mL/L foliar — preventivo",IF(AND('🌱 Configuração'!$B$51+0<'🌱 Configuração'!$C$51,INT((1-1)/7)+1=2,MOD(1-1,7)=0),"🐛 Beauveria bassiana foliar + solo",IF(AND('🌱 Configuração'!$B$51+0>='🌱 Configuração'!$C$51,'🌱 Configuração'!$B$51+0<'🌱 Configuração'!$D$51,INT(('🌱 Configuração'!$B$51+0-'🌱 Configuração'!$C$51)/7)+1=1,MOD('🌱 Configuração'!$B$51+0-'🌱 Configuração'!$C$51,7)=0),"🐛 Nim 2mL/L foliar",IF(AND('🌱 Configuração'!$B$51+0>='🌱 Configuração'!$C$51,'🌱 Configuração'!$B$51+0<'🌱 Configuração'!$D$51,INT(('🌱 Configuração'!$B$51+0-'🌱 Configuração'!$C$51)/7)+1=2,MOD('🌱 Configuração'!$B$51+0-'🌱 Configuração'!$C$51,7)=0),"🐛 Beauveria bassiana foliar",IF(AND('🌱 Configuração'!$B$51+0>='🌱 Configuração'!$C$51,'🌱 Configuração'!$B$51+0<'🌱 Configuração'!$D$51,INT(('🌱 Configuração'!$B$51+0-'🌱 Configuração'!$C$51)/7)+1=3,MOD('🌱 Configuração'!$B$51+0-'🌱 Configuração'!$C$51,7)=0),"🐛 Nim + Calda Sulfocálcica 1%",IF(AND('🌱 Configuração'!$B$51+0>='🌱 Configuração'!$C$51,'🌱 Configuração'!$B$51+0<'🌱 Configuração'!$D$51,INT(('🌱 Configuração'!$B$51+0-'🌱 Configuração'!$C$51)/7)+1=4,MOD('🌱 Configuração'!$B$51+0-'🌱 Configuração'!$C$51,7)=0),"🐛 Trichoderma solo + Beauveria",IF(AND('🌱 Configuração'!$B$51+0>='🌱 Configuração'!$C$51,'🌱 Configuração'!$B$51+0<'🌱 Configuração'!$D$51,INT(('🌱 Configuração'!$B$51+0-'🌱 Configuração'!$C$51)/7)+1=5,MOD('🌱 Configuração'!$B$51+0-'🌱 Configuração'!$C$51,7)=0),"🐛 Calda Bordalesa 0.5% foliar",IF(AND('🌱 Configuração'!$B$51+0>='🌱 Configuração'!$C$51,'🌱 Configuração'!$B$51+0<'🌱 Configuração'!$D$51,INT(('🌱 Configuração'!$B$51+0-'🌱 Configuração'!$C$51)/7)+1=6,MOD('🌱 Configuração'!$B$51+0-'🌱 Configuração'!$C$51,7)=0),"🐛 Nim 2mL/L — ÚLTIMA foliar",IF(AND('🌱 Configuração'!$B$51+0>='🌱 Configuração'!$D$51,'🌱 Configuração'!$B$51+0<'🌱 Configuração'!$E$51,INT(('🌱 Configuração'!$B$51+0-'🌱 Configuração'!$D$51)/7)+1=1,MOD('🌱 Configuração'!$B$51+0-'🌱 Configuração'!$D$51,7)=0),"🐛 Beauveria bassiana solo (sem foliar)",IF(AND('🌱 Configuração'!$B$51+0>='🌱 Configuração'!$D$51,'🌱 Configuração'!$B$51+0<'🌱 Configuração'!$E$51,INT(('🌱 Configuração'!$B$51+0-'🌱 Configuração'!$D$51)/7)+1=2,MOD('🌱 Configuração'!$B$51+0-'🌱 Configuração'!$D$51,7)=0),"🐛 Trichoderma solo",IF(AND('🌱 Configuração'!$B$51+0>='🌱 Configuração'!$D$51,'🌱 Configuração'!$B$51+0<'🌱 Configuração'!$E$51,INT(('🌱 Configuração'!$B$51+0-'🌱 Configuração'!$D$51)/7)+1=3,MOD('🌱 Configuração'!$B$51+0-'🌱 Configuração'!$D$51,7)=0),"🐛 Beauveria bassiana solo",IF(AND('🌱 Configuração'!$B$51+0>='🌱 Configuração'!$D$51,'🌱 Configuração'!$B$51+0<'🌱 Configuração'!$E$51,INT(('🌱 Configuração'!$B$51+0-'🌱 Configuração'!$D$51)/7)+1=4,MOD('🌱 Configuração'!$B$51+0-'🌱 Configuração'!$D$51,7)=0),"🐛 Trichoderma solo",IF(AND('🌱 Configuração'!$B$51+0>='🌱 Configuração'!$E$51,INT(('🌱 Configuração'!$B$51+0-'🌱 Configuração'!$E$51)/7)+1=1,MOD('🌱 Configuração'!$B$51+0-'🌱 Configuração'!$E$51,7)=0),"🐛 Inspeção final — sem aplicação","")))))))))))))) -> 🐛 Nim 2mL/L foliar — preventivo | H6: =IF(1>'🌱 Configuração'!$F$50,"","✂️ Receber clone — verificar raízes | pH: 5.8–6.0 | Umidade 70–80%") -> ✂️ Receber clone — verificar raízes | pH: 5.8–6.0 | Umidade 70–80%
B7: =IF(2<='🌱 Configuração'!$F$50,2,"") -> 2 | C7: =IF(2<='🌱 Configuração'!$F$50,'🌱 Configuração'!$B$51+1,"") -> 46024 | D7: =IF(2>'🌱 Configuração'!$F$50,"",IF('🌱 Configuração'!$B$51+1<'🌱 Configuração'!$C$51,"🌱 Clone",IF('🌱 Configuração'!$B$51+1<'🌱 Configuração'!$D$51,"🌿 Vegetativo",IF('🌱 Configuração'!$B$51+1<'🌱 Configuração'!$E$51,"🌸 Floração","🚿 Flush")))) -> 🌱 Clone | E7: =IF(2>'🌱 Configuração'!$F$50,"",IF('🌱 Configuração'!$B$51+1<'🌱 Configuração'!$C$51,"Clone S"&INT((2-1)/7)+1,IF('🌱 Configuração'!$B$51+1<'🌱 Configuração'!$D$51,"Vega S"&INT(('🌱 Configuração'!$B$51+1-'🌱 Configuração'!$C$51)/7)+1,IF('🌱 Configuração'!$B$51+1<'🌱 Configuração'!$E$51,"Flora S"&INT(('🌱 Configuração'!$B$51+1-'🌱 Configuração'!$D$51)/7)+1,"Flush S"&INT(('🌱 Configuração'!$B$51+1-'🌱 Configuração'!$E$51)/7)+1)))) -> Clone S1 | F7: =IF(2>'🌱 Configuração'!$F$50,"",IF(AND('🌱 Configuração'!$B$51+1<'🌱 Configuração'!$C$51,INT((2-1)/7)+1=1,MOD(2-1,7)=0),"🌱 Enraizador (0.5 mL/L)",IF(AND('🌱 Configuração'!$B$51+1<'🌱 Configuração'!$C$51,INT((2-1)/7)+1=2,MOD(2-1,7)=0),"🌱 Enraizador + Vitamina B1",IF(AND('🌱 Configuração'!$B$51+1>='🌱 Configuração'!$C$51,'🌱 Configuração'!$B$51+1<'🌱 Configuração'!$D$51,INT(('🌱 Configuração'!$B$51+1-'🌱 Configuração'!$C$51)/7)+1=1,MOD('🌱 Configuração'!$B$51+1-'🌱 Configuração'!$C$51,7)=0),"🌿 Grow A+B início — EC 0.8",IF(AND('🌱 Configuração'!$B$51+1>='🌱 Configuração'!$C$51,'🌱 Configuração'!$B$51+1<'🌱 Configuração'!$D$51,INT(('🌱 Configuração'!$B$51+1-'🌱 Configuração'!$C$51)/7)+1=2,MOD('🌱 Configuração'!$B$51+1-'🌱 Configuração'!$C$51,7)=0),"🌿 Grow A+B + CalMag — EC 1.0",IF(AND('🌱 Configuração'!$B$51+1>='🌱 Configuração'!$C$51,'🌱 Configuração'!$B$51+1<'🌱 Configuração'!$D$51,INT(('🌱 Configuração'!$B$51+1-'🌱 Configuração'!$C$51)/7)+1=3,MOD('🌱 Configuração'!$B$51+1-'🌱 Configuração'!$C$51,7)=0),"🌿 Grow A+B + CalMag — EC 1.2",IF(AND('🌱 Configuração'!$B$51+1>='🌱 Configuração'!$C$51,'🌱 Configuração'!$B$51+1<'🌱 Configuração'!$D$51,INT(('🌱 Configuração'!$B$51+1-'🌱 Configuração'!$C$51)/7)+1=4,MOD('🌱 Configuração'!$B$51+1-'🌱 Configuração'!$C$51,7)=0),"🌿 Grow A+B + Enzimas — EC 1.4",IF(AND('🌱 Configuração'!$B$51+1>='🌱 Configuração'!$C$51,'🌱 Configuração'!$B$51+1<'🌱 Configuração'!$D$51,INT(('🌱 Configuração'!$B$51+1-'🌱 Configuração'!$C$51)/7)+1=5,MOD('🌱 Configuração'!$B$51+1-'🌱 Configuração'!$C$51,7)=0),"🌿 Grow A+B + Biorrizas — EC 1.5",IF(AND('🌱 Configuração'!$B$51+1>='🌱 Configuração'!$C$51,'🌱 Configuração'!$B$51+1<'🌱 Configuração'!$D$51,INT(('🌱 Configuração'!$B$51+1-'🌱 Configuração'!$C$51)/7)+1=6,MOD('🌱 Configuração'!$B$51+1-'🌱 Configuração'!$C$51,7)=0),"🌿 Transição Bloom — EC 1.4",IF(AND('🌱 Configuração'!$B$51+1>='🌱 Configuração'!$C$51,'🌱 Configuração'!$B$51+1<'🌱 Configuração'!$D$51,INT(('🌱 Configuração'!$B$51+1-'🌱 Configuração'!$C$51)/7)+1=7,MOD('🌱 Configuração'!$B$51+1-'🌱 Configuração'!$C$51,7)=0),"🌿 Bloom A+B transição — EC 1.4",IF(AND('🌱 Configuração'!$B$51+1>='🌱 Configuração'!$C$51,'🌱 Configuração'!$B$51+1<'🌱 Configuração'!$D$51,INT(('🌱 Configuração'!$B$51+1-'🌱 Configuração'!$C$51)/7)+1=8,MOD('🌱 Configuração'!$B$51+1-'🌱 Configuração'!$C$51,7)=0),"🌿 Bloom A+B — EC 1.4",IF(AND('🌱 Configuração'!$B$51+1>='🌱 Configuração'!$D$51,'🌱 Configuração'!$B$51+1<'🌱 Configuração'!$E$51,INT(('🌱 Configuração'!$B$51+1-'🌱 Configuração'!$D$51)/7)+1=1,MOD('🌱 Configuração'!$B$51+1-'🌱 Configuração'!$D$51,7)=0),"🌸 Bloom A+B — EC 1.6",IF(AND('🌱 Configuração'!$B$51+1>='🌱 Configuração'!$D$51,'🌱 Configuração'!$B$51+1<'🌱 Configuração'!$E$51,INT(('🌱 Configuração'!$B$51+1-'🌱 Configuração'!$D$51)/7)+1=2,MOD('🌱 Configuração'!$B$51+1-'🌱 Configuração'!$D$51,7)=0),"🌸 Bloom + PK 13/14 início",IF(AND('🌱 Configuração'!$B$51+1>='🌱 Configuração'!$D$51,'🌱 Configuração'!$B$51+1<'🌱 Configuração'!$E$51,INT(('🌱 Configuração'!$B$51+1-'🌱 Configuração'!$D$51)/7)+1=3,MOD('🌱 Configuração'!$B$51+1-'🌱 Configuração'!$D$51,7)=0),"🌸 Bloom + PK + CalMag — EC 1.8",IF(AND('🌱 Configuração'!$B$51+1>='🌱 Configuração'!$D$51,'🌱 Configuração'!$B$51+1<'🌱 Configuração'!$E$51,INT(('🌱 Configuração'!$B$51+1-'🌱 Configuração'!$D$51)/7)+1=4,MOD('🌱 Configuração'!$B$51+1-'🌱 Configuração'!$D$51,7)=0),"🌸 Bloom + PK + Boost Floral — EC 2.0",IF(AND('🌱 Configuração'!$B$51+1>='🌱 Configuração'!$D$51,'🌱 Configuração'!$B$51+1<'🌱 Configuração'!$E$51,INT(('🌱 Configuração'!$B$51+1-'🌱 Configuração'!$D$51)/7)+1=5,MOD('🌱 Configuração'!$B$51+1-'🌱 Configuração'!$D$51,7)=0),"🌸 Bloom + Boost + Amino",IF(AND('🌱 Configuração'!$B$51+1>='🌱 Configuração'!$D$51,'🌱 Configuração'!$B$51+1<'🌱 Configuração'!$E$51,INT(('🌱 Configuração'!$B$51+1-'🌱 Configuração'!$D$51)/7)+1=6,MOD('🌱 Configuração'!$B$51+1-'🌱 Configuração'!$D$51,7)=0),"🌸 Bloom + Enzimas + Amino",IF(AND('🌱 Configuração'!$B$51+1>='🌱 Configuração'!$D$51,'🌱 Configuração'!$B$51+1<'🌱 Configuração'!$E$51,INT(('🌱 Configuração'!$B$51+1-'🌱 Configuração'!$D$51)/7)+1=7,MOD('🌱 Configuração'!$B$51+1-'🌱 Configuração'!$D$51,7)=0),"🌸 Reduzir N — Bloom puro — EC 1.6",IF(AND('🌱 Configuração'!$B$51+1>='🌱 Configuração'!$D$51,'🌱 Configuração'!$B$51+1<'🌱 Configuração'!$E$51,INT(('🌱 Configuração'!$B$51+1-'🌱 Configuração'!$D$51)/7)+1=8,MOD('🌱 Configuração'!$B$51+1-'🌱 Configuração'!$D$51,7)=0),"🌸 Bloom puro — EC 1.4 (pré-flush)",IF(AND('🌱 Configuração'!$B$51+1>='🌱 Configuração'!$D$51,'🌱 Configuração'!$B$51+1<'🌱 Configuração'!$E$51,INT(('🌱 Configuração'!$B$51+1-'🌱 Configuração'!$D$51)/7)+1=9,MOD('🌱 Configuração'!$B$51+1-'🌱 Configuração'!$D$51,7)=0),"🌸 Último Bloom — EC 0.8",IF(AND('🌱 Configuração'!$B$51+1>='🌱 Configuração'!$E$51,INT(('🌱 Configuração'!$B$51+1-'🌱 Configuração'!$E$51)/7)+1=1,MOD('🌱 Configuração'!$B$51+1-'🌱 Configuração'!$E$51,7)=0),"🚿 Água pura + Enzimas (EC < 0.3)",IF(AND('🌱 Configuração'!$B$51+1>='🌱 Configuração'!$E$51,INT(('🌱 Configuração'!$B$51+1-'🌱 Configuração'!$E$51)/7)+1=2,MOD('🌱 Configuração'!$B$51+1-'🌱 Configuração'!$E$51,7)=0),"🚿 Água pura (EC < 0.2)","")))))))))))))))))))))) | G7: =IF(2>'🌱 Configuração'!$F$50,"",IF(AND('🌱 Configuração'!$B$51+1<'🌱 Configuração'!$C$51,INT((2-1)/7)+1=1,MOD(2-1,7)=0),"🐛 Nim 2mL/L foliar — preventivo",IF(AND('🌱 Configuração'!$B$51+1<'🌱 Configuração'!$C$51,INT((2-1)/7)+1=2,MOD(2-1,7)=0),"🐛 Beauveria bassiana foliar + solo",IF(AND('🌱 Configuração'!$B$51+1>='🌱 Configuração'!$C$51,'🌱 Configuração'!$B$51+1<'🌱 Configuração'!$D$51,INT(('🌱 Configuração'!$B$51+1-'🌱 Configuração'!$C$51)/7)+1=1,MOD('🌱 Configuração'!$B$51+1-'🌱 Configuração'!$C$51,7)=0),"🐛 Nim 2mL/L foliar",IF(AND('🌱 Configuração'!$B$51+1>='🌱 Configuração'!$C$51,'🌱 Configuração'!$B$51+1<'🌱 Configuração'!$D$51,INT(('🌱 Configuração'!$B$51+1-'🌱 Configuração'!$C$51)/7)+1=2,MOD('🌱 Configuração'!$B$51+1-'🌱 Configuração'!$C$51,7)=0),"🐛 Beauveria bassiana foliar",IF(AND('🌱 Configuração'!$B$51+1>='🌱 Configuração'!$C$51,'🌱 Configuração'!$B$51+1<'🌱 Configuração'!$D$51,INT(('🌱 Configuração'!$B$51+1-'🌱 Configuração'!$C$51)/7)+1=3,MOD('🌱 Configuração'!$B$51+1-'🌱 Configuração'!$C$51,7)=0),"🐛 Nim + Calda Sulfocálcica 1%",IF(AND('🌱 Configuração'!$B$51+1>='🌱 Configuração'!$C$51,'🌱 Configuração'!$B$51+1<'🌱 Configuração'!$D$51,INT(('🌱 Configuração'!$B$51+1-'🌱 Configuração'!$C$51)/7)+1=4,MOD('🌱 Configuração'!$B$51+1-'🌱 Configuração'!$C$51,7)=0),"🐛 Trichoderma solo + Beauveria",IF(AND('🌱 Configuração'!$B$51+1>='🌱 Configuração'!$C$51,'🌱 Configuração'!$B$51+1<'🌱 Configuração'!$D$51,INT(('🌱 Configuração'!$B$51+1-'🌱 Configuração'!$C$51)/7)+1=5,MOD('🌱 Configuração'!$B$51+1-'🌱 Configuração'!$C$51,7)=0),"🐛 Calda Bordalesa 0.5% foliar",IF(AND('🌱 Configuração'!$B$51+1>='🌱 Configuração'!$C$51,'🌱 Configuração'!$B$51+1<'🌱 Configuração'!$D$51,INT(('🌱 Configuração'!$B$51+1-'🌱 Configuração'!$C$51)/7)+1=6,MOD('🌱 Configuração'!$B$51+1-'🌱 Configuração'!$C$51,7)=0),"🐛 Nim 2mL/L — ÚLTIMA foliar",IF(AND('🌱 Configuração'!$B$51+1>='🌱 Configuração'!$D$51,'🌱 Configuração'!$B$51+1<'🌱 Configuração'!$E$51,INT(('🌱 Configuração'!$B$51+1-'🌱 Configuração'!$D$51)/7)+1=1,MOD('🌱 Configuração'!$B$51+1-'🌱 Configuração'!$D$51,7)=0),"🐛 Beauveria bassiana solo (sem foliar)",IF(AND('🌱 Configuração'!$B$51+1>='🌱 Configuração'!$D$51,'🌱 Configuração'!$B$51+1<'🌱 Configuração'!$E$51,INT(('🌱 Configuração'!$B$51+1-'🌱 Configuração'!$D$51)/7)+1=2,MOD('🌱 Configuração'!$B$51+1-'🌱 Configuração'!$D$51,7)=0),"🐛 Trichoderma solo",IF(AND('🌱 Configuração'!$B$51+1>='🌱 Configuração'!$D$51,'🌱 Configuração'!$B$51+1<'🌱 Configuração'!$E$51,INT(('🌱 Configuração'!$B$51+1-'🌱 Configuração'!$D$51)/7)+1=3,MOD('🌱 Configuração'!$B$51+1-'🌱 Configuração'!$D$51,7)=0),"🐛 Beauveria bassiana solo",IF(AND('🌱 Configuração'!$B$51+1>='🌱 Configuração'!$D$51,'🌱 Configuração'!$B$51+1<'🌱 Configuração'!$E$51,INT(('🌱 Configuração'!$B$51+1-'🌱 Configuração'!$D$51)/7)+1=4,MOD('🌱 Configuração'!$B$51+1-'🌱 Configuração'!$D$51,7)=0),"🐛 Trichoderma solo",IF(AND('🌱 Configuração'!$B$51+1>='🌱 Configuração'!$E$51,INT(('🌱 Configuração'!$B$51+1-'🌱 Configuração'!$E$51)/7)+1=1,MOD('🌱 Configuração'!$B$51+1-'🌱 Configuração'!$E$51,7)=0),"🐛 Inspeção final — sem aplicação","")))))))))))))) | H7: =IF(2>'🌱 Configuração'!$F$50,"",IF('🌱 Configuração'!$B$51+1='🌱 Configuração'!$C$51,"🌿 INÍCIO VEGA — ajustar espaço, luz 18h/dia — EC 0.8",IF('🌱 Configuração'!$B$51+1='🌱 Configuração'!$D$51,"🌸 INÍCIO FLORAÇÃO — mudar para 12h/12h — 🔴 atenção ao fotoperíodo",IF('🌱 Configuração'!$B$51+1='🌱 Configuração'!$E$51,"🚿 INÍCIO FLUSH — PARAR nutrição, somente água pura",IF('🌱 Configuração'!$B$51+1='🌱 Configuração'!$F$51-1,"🔬 Véspera da colheita — analisar tricomas âmbar",IF('🌱 Configuração'!$B$51+1='🌱 Configuração'!$F$51,"✂️ COLHEITA! Parabéns! 🎉",""))))))
B8: =IF(3<='🌱 Configuração'!$F$50,3,"") -> 3 | C8: =IF(3<='🌱 Configuração'!$F$50,'🌱 Configuração'!$B$51+2,"") -> 46025 | D8: =IF(3>'🌱 Configuração'!$F$50,"",IF('🌱 Configuração'!$B$51+2<'🌱 Configuração'!$C$51,"🌱 Clone",IF('🌱 Configuração'!$B$51+2<'🌱 Configuração'!$D$51,"🌿 Vegetativo",IF('🌱 Configuração'!$B$51+2<'🌱 Configuração'!$E$51,"🌸 Floração","🚿 Flush")))) -> 🌱 Clone | E8: =IF(3>'🌱 Configuração'!$F$50,"",IF('🌱 Configuração'!$B$51+2<'🌱 Configuração'!$C$51,"Clone S"&INT((3-1)/7)+1,IF('🌱 Configuração'!$B$51+2<'🌱 Configuração'!$D$51,"Vega S"&INT(('🌱 Configuração'!$B$51+2-'🌱 Configuração'!$C$51)/7)+1,IF('🌱 Configuração'!$B$51+2<'🌱 Configuração'!$E$51,"Flora S"&INT(('🌱 Configuração'!$B$51+2-'🌱 Configuração'!$D$51)/7)+1,"Flush S"&INT(('🌱 Configuração'!$B$51+2-'🌱 Configuração'!$E$51)/7)+1)))) -> Clone S1 | F8: =IF(3>'🌱 Configuração'!$F$50,"",IF(AND('🌱 Configuração'!$B$51+2<'🌱 Configuração'!$C$51,INT((3-1)/7)+1=1,MOD(3-1,7)=0),"🌱 Enraizador (0.5 mL/L)",IF(AND('🌱 Configuração'!$B$51+2<'🌱 Configuração'!$C$51,INT((3-1)/7)+1=2,MOD(3-1,7)=0),"🌱 Enraizador + Vitamina B1",IF(AND('🌱 Configuração'!$B$51+2>='🌱 Configuração'!$C$51,'🌱 Configuração'!$B$51+2<'🌱 Configuração'!$D$51,INT(('🌱 Configuração'!$B$51+2-'🌱 Configuração'!$C$51)/7)+1=1,MOD('🌱 Configuração'!$B$51+2-'🌱 Configuração'!$C$51,7)=0),"🌿 Grow A+B início — EC 0.8",IF(AND('🌱 Configuração'!$B$51+2>='🌱 Configuração'!$C$51,'🌱 Configuração'!$B$51+2<'🌱 Configuração'!$D$51,INT(('🌱 Configuração'!$B$51+2-'🌱 Configuração'!$C$51)/7)+1=2,MOD('🌱 Configuração'!$B$51+2-'🌱 Configuração'!$C$51,7)=0),"🌿 Grow A+B + CalMag — EC 1.0",IF(AND('🌱 Configuração'!$B$51+2>='🌱 Configuração'!$C$51,'🌱 Configuração'!$B$51+2<'🌱 Configuração'!$D$51,INT(('🌱 Configuração'!$B$51+2-'🌱 Configuração'!$C$51)/7)+1=3,MOD('🌱 Configuração'!$B$51+2-'🌱 Configuração'!$C$51,7)=0),"🌿 Grow A+B + CalMag — EC 1.2",IF(AND('🌱 Configuração'!$B$51+2>='🌱 Configuração'!$C$51,'🌱 Configuração'!$B$51+2<'🌱 Configuração'!$D$51,INT(('🌱 Configuração'!$B$51+2-'🌱 Configuração'!$C$51)/7)+1=4,MOD('🌱 Configuração'!$B$51+2-'🌱 Configuração'!$C$51,7)=0),"🌿 Grow A+B + Enzimas — EC 1.4",IF(AND('🌱 Configuração'!$B$51+2>='🌱 Configuração'!$C$51,'🌱 Configuração'!$B$51+2<'🌱 Configuração'!$D$51,INT(('🌱 Configuração'!$B$51+2-'🌱 Configuração'!$C$51)/7)+1=5,MOD('🌱 Configuração'!$B$51+2-'🌱 Configuração'!$C$51,7)=0),"🌿 Grow A+B + Biorrizas — EC 1.5",IF(AND('🌱 Configuração'!$B$51+2>='🌱 Configuração'!$C$51,'🌱 Configuração'!$B$51+2<'🌱 Configuração'!$D$51,INT(('🌱 Configuração'!$B$51+2-'🌱 Configuração'!$C$51)/7)+1=6,MOD('🌱 Configuração'!$B$51+2-'🌱 Configuração'!$C$51,7)=0),"🌿 Transição Bloom — EC 1.4",IF(AND('🌱 Configuração'!$B$51+2>='🌱 Configuração'!$C$51,'🌱 Configuração'!$B$51+2<'🌱 Configuração'!$D$51,INT(('🌱 Configuração'!$B$51+2-'🌱 Configuração'!$C$51)/7)+1=7,MOD('🌱 Configuração'!$B$51+2-'🌱 Configuração'!$C$51,7)=0),"🌿 Bloom A+B transição — EC 1.4",IF(AND('🌱 Configuração'!$B$51+2>='🌱 Configuração'!$C$51,'🌱 Configuração'!$B$51+2<'🌱 Configuração'!$D$51,INT(('🌱 Configuração'!$B$51+2-'🌱 Configuração'!$C$51)/7)+1=8,MOD('🌱 Configuração'!$B$51+2-'🌱 Configuração'!$C$51,7)=0),"🌿 Bloom A+B — EC 1.4",IF(AND('🌱 Configuração'!$B$51+2>='🌱 Configuração'!$D$51,'🌱 Configuração'!$B$51+2<'🌱 Configuração'!$E$51,INT(('🌱 Configuração'!$B$51+2-'🌱 Configuração'!$D$51)/7)+1=1,MOD('🌱 Configuração'!$B$51+2-'🌱 Configuração'!$D$51,7)=0),"🌸 Bloom A+B — EC 1.6",IF(AND('🌱 Configuração'!$B$51+2>='🌱 Configuração'!$D$51,'🌱 Configuração'!$B$51+2<'🌱 Configuração'!$E$51,INT(('🌱 Configuração'!$B$51+2-'🌱 Configuração'!$D$51)/7)+1=2,MOD('🌱 Configuração'!$B$51+2-'🌱 Configuração'!$D$51,7)=0),"🌸 Bloom + PK 13/14 início",IF(AND('🌱 Configuração'!$B$51+2>='🌱 Configuração'!$D$51,'🌱 Configuração'!$B$51+2<'🌱 Configuração'!$E$51,INT(('🌱 Configuração'!$B$51+2-'🌱 Configuração'!$D$51)/7)+1=3,MOD('🌱 Configuração'!$B$51+2-'🌱 Configuração'!$D$51,7)=0),"🌸 Bloom + PK + CalMag — EC 1.8",IF(AND('🌱 Configuração'!$B$51+2>='🌱 Configuração'!$D$51,'🌱 Configuração'!$B$51+2<'🌱 Configuração'!$E$51,INT(('🌱 Configuração'!$B$51+2-'🌱 Configuração'!$D$51)/7)+1=4,MOD('🌱 Configuração'!$B$51+2-'🌱 Configuração'!$D$51,7)=0),"🌸 Bloom + PK + Boost Floral — EC 2.0",IF(AND('🌱 Configuração'!$B$51+2>='🌱 Configuração'!$D$51,'🌱 Configuração'!$B$51+2<'🌱 Configuração'!$E$51,INT(('🌱 Configuração'!$B$51+2-'🌱 Configuração'!$D$51)/7)+1=5,MOD('🌱 Configuração'!$B$51+2-'🌱 Configuração'!$D$51,7)=0),"🌸 Bloom + Boost + Amino",IF(AND('🌱 Configuração'!$B$51+2>='🌱 Configuração'!$D$51,'🌱 Configuração'!$B$51+2<'🌱 Configuração'!$E$51,INT(('🌱 Configuração'!$B$51+2-'🌱 Configuração'!$D$51)/7)+1=6,MOD('🌱 Configuração'!$B$51+2-'🌱 Configuração'!$D$51,7)=0),"🌸 Bloom + Enzimas + Amino",IF(AND('🌱 Configuração'!$B$51+2>='🌱 Configuração'!$D$51,'🌱 Configuração'!$B$51+2<'🌱 Configuração'!$E$51,INT(('🌱 Configuração'!$B$51+2-'🌱 Configuração'!$D$51)/7)+1=7,MOD('🌱 Configuração'!$B$51+2-'🌱 Configuração'!$D$51,7)=0),"🌸 Reduzir N — Bloom puro — EC 1.6",IF(AND('🌱 Configuração'!$B$51+2>='🌱 Configuração'!$D$51,'🌱 Configuração'!$B$51+2<'🌱 Configuração'!$E$51,INT(('🌱 Configuração'!$B$51+2-'🌱 Configuração'!$D$51)/7)+1=8,MOD('🌱 Configuração'!$B$51+2-'🌱 Configuração'!$D$51,7)=0),"🌸 Bloom puro — EC 1.4 (pré-flush)",IF(AND('🌱 Configuração'!$B$51+2>='🌱 Configuração'!$D$51,'🌱 Configuração'!$B$51+2<'🌱 Configuração'!$E$51,INT(('🌱 Configuração'!$B$51+2-'🌱 Configuração'!$D$51)/7)+1=9,MOD('🌱 Configuração'!$B$51+2-'🌱 Configuração'!$D$51,7)=0),"🌸 Último Bloom — EC 0.8",IF(AND('🌱 Configuração'!$B$51+2>='🌱 Configuração'!$E$51,INT(('🌱 Configuração'!$B$51+2-'🌱 Configuração'!$E$51)/7)+1=1,MOD('🌱 Configuração'!$B$51+2-'🌱 Configuração'!$E$51,7)=0),"🚿 Água pura + Enzimas (EC < 0.3)",IF(AND('🌱 Configuração'!$B$51+2>='🌱 Configuração'!$E$51,INT(('🌱 Configuração'!$B$51+2-'🌱 Configuração'!$E$51)/7)+1=2,MOD('🌱 Configuração'!$B$51+2-'🌱 Configuração'!$E$51,7)=0),"🚿 Água pura (EC < 0.2)","")))))))))))))))))))))) | G8: =IF(3>'🌱 Configuração'!$F$50,"",IF(AND('🌱 Configuração'!$B$51+2<'🌱 Configuração'!$C$51,INT((3-1)/7)+1=1,MOD(3-1,7)=0),"🐛 Nim 2mL/L foliar — preventivo",IF(AND('🌱 Configuração'!$B$51+2<'🌱 Configuração'!$C$51,INT((3-1)/7)+1=2,MOD(3-1,7)=0),"🐛 Beauveria bassiana foliar + solo",IF(AND('🌱 Configuração'!$B$51+2>='🌱 Configuração'!$C$51,'🌱 Configuração'!$B$51+2<'🌱 Configuração'!$D$51,INT(('🌱 Configuração'!$B$51+2-'🌱 Configuração'!$C$51)/7)+1=1,MOD('🌱 Configuração'!$B$51+2-'🌱 Configuração'!$C$51,7)=0),"🐛 Nim 2mL/L foliar",IF(AND('🌱 Configuração'!$B$51+2>='🌱 Configuração'!$C$51,'🌱 Configuração'!$B$51+2<'🌱 Configuração'!$D$51,INT(('🌱 Configuração'!$B$51+2-'🌱 Configuração'!$C$51)/7)+1=2,MOD('🌱 Configuração'!$B$51+2-'🌱 Configuração'!$C$51,7)=0),"🐛 Beauveria bassiana foliar",IF(AND('🌱 Configuração'!$B$51+2>='🌱 Configuração'!$C$51,'🌱 Configuração'!$B$51+2<'🌱 Configuração'!$D$51,INT(('🌱 Configuração'!$B$51+2-'🌱 Configuração'!$C$51)/7)+1=3,MOD('🌱 Configuração'!$B$51+2-'🌱 Configuração'!$C$51,7)=0),"🐛 Nim + Calda Sulfocálcica 1%",IF(AND('🌱 Configuração'!$B$51+2>='🌱 Configuração'!$C$51,'🌱 Configuração'!$B$51+2<'🌱 Configuração'!$D$51,INT(('🌱 Configuração'!$B$51+2-'🌱 Configuração'!$C$51)/7)+1=4,MOD('🌱 Configuração'!$B$51+2-'🌱 Configuração'!$C$51,7)=0),"🐛 Trichoderma solo + Beauveria",IF(AND('🌱 Configuração'!$B$51+2>='🌱 Configuração'!$C$51,'🌱 Configuração'!$B$51+2<'🌱 Configuração'!$D$51,INT(('🌱 Configuração'!$B$51+2-'🌱 Configuração'!$C$51)/7)+1=5,MOD('🌱 Configuração'!$B$51+2-'🌱 Configuração'!$C$51,7)=0),"🐛 Calda Bordalesa 0.5% foliar",IF(AND('🌱 Configuração'!$B$51+2>='🌱 Configuração'!$C$51,'🌱 Configuração'!$B$51+2<'🌱 Configuração'!$D$51,INT(('🌱 Configuração'!$B$51+2-'🌱 Configuração'!$C$51)/7)+1=6,MOD('🌱 Configuração'!$B$51+2-'🌱 Configuração'!$C$51,7)=0),"🐛 Nim 2mL/L — ÚLTIMA foliar",IF(AND('🌱 Configuração'!$B$51+2>='🌱 Configuração'!$D$51,'🌱 Configuração'!$B$51+2<'🌱 Configuração'!$E$51,INT(('🌱 Configuração'!$B$51+2-'🌱 Configuração'!$D$51)/7)+1=1,MOD('🌱 Configuração'!$B$51+2-'🌱 Configuração'!$D$51,7)=0),"🐛 Beauveria bassiana solo (sem foliar)",IF(AND('🌱 Configuração'!$B$51+2>='🌱 Configuração'!$D$51,'🌱 Configuração'!$B$51+2<'🌱 Configuração'!$E$51,INT(('🌱 Configuração'!$B$51+2-'🌱 Configuração'!$D$51)/7)+1=2,MOD('🌱 Configuração'!$B$51+2-'🌱 Configuração'!$D$51,7)=0),"🐛 Trichoderma solo",IF(AND('🌱 Configuração'!$B$51+2>='🌱 Configuração'!$D$51,'🌱 Configuração'!$B$51+2<'🌱 Configuração'!$E$51,INT(('🌱 Configuração'!$B$51+2-'🌱 Configuração'!$D$51)/7)+1=3,MOD('🌱 Configuração'!$B$51+2-'🌱 Configuração'!$D$51,7)=0),"🐛 Beauveria bassiana solo",IF(AND('🌱 Configuração'!$B$51+2>='🌱 Configuração'!$D$51,'🌱 Configuração'!$B$51+2<'🌱 Configuração'!$E$51,INT(('🌱 Configuração'!$B$51+2-'🌱 Configuração'!$D$51)/7)+1=4,MOD('🌱 Configuração'!$B$51+2-'🌱 Configuração'!$D$51,7)=0),"🐛 Trichoderma solo",IF(AND('🌱 Configuração'!$B$51+2>='🌱 Configuração'!$E$51,INT(('🌱 Configuração'!$B$51+2-'🌱 Configuração'!$E$51)/7)+1=1,MOD('🌱 Configuração'!$B$51+2-'🌱 Configuração'!$E$51,7)=0),"🐛 Inspeção final — sem aplicação","")))))))))))))) | H8: =IF(3>'🌱 Configuração'!$F$50,"",IF('🌱 Configuração'!$B$51+2='🌱 Configuração'!$C$51,"🌿 INÍCIO VEGA — ajustar espaço, luz 18h/dia — EC 0.8",IF('🌱 Configuração'!$B$51+2='🌱 Configuração'!$D$51,"🌸 INÍCIO FLORAÇÃO — mudar para 12h/12h — 🔴 atenção ao fotoperíodo",IF('🌱 Configuração'!$B$51+2='🌱 Configuração'!$E$51,"🚿 INÍCIO FLUSH — PARAR nutrição, somente água pura",IF('🌱 Configuração'!$B$51+2='🌱 Configuração'!$F$51-1,"🔬 Véspera da colheita — analisar tricomas âmbar",IF('🌱 Configuração'!$B$51+2='🌱 Configuração'!$F$51,"✂️ COLHEITA! Parabéns! 🎉",""))))))
B9: =IF(4<='🌱 Configuração'!$F$50,4,"") -> 4 | C9: =IF(4<='🌱 Configuração'!$F$50,'🌱 Configuração'!$B$51+3,"") -> 46026 | D9: =IF(4>'🌱 Configuração'!$F$50,"",IF('🌱 Configuração'!$B$51+3<'🌱 Configuração'!$C$51,"🌱 Clone",IF('🌱 Configuração'!$B$51+3<'🌱 Configuração'!$D$51,"🌿 Vegetativo",IF('🌱 Configuração'!$B$51+3<'🌱 Configuração'!$E$51,"🌸 Floração","🚿 Flush")))) -> 🌱 Clone | E9: =IF(4>'🌱 Configuração'!$F$50,"",IF('🌱 Configuração'!$B$51+3<'🌱 Configuração'!$C$51,"Clone S"&INT((4-1)/7)+1,IF('🌱 Configuração'!$B$51+3<'🌱 Configuração'!$D$51,"Vega S"&INT(('🌱 Configuração'!$B$51+3-'🌱 Configuração'!$C$51)/7)+1,IF('🌱 Configuração'!$B$51+3<'🌱 Configuração'!$E$51,"Flora S"&INT(('🌱 Configuração'!$B$51+3-'🌱 Configuração'!$D$51)/7)+1,"Flush S"&INT(('🌱 Configuração'!$B$51+3-'🌱 Configuração'!$E$51)/7)+1)))) -> Clone S1 | F9: =IF(4>'🌱 Configuração'!$F$50,"",IF(AND('🌱 Configuração'!$B$51+3<'🌱 Configuração'!$C$51,INT((4-1)/7)+1=1,MOD(4-1,7)=0),"🌱 Enraizador (0.5 mL/L)",IF(AND('🌱 Configuração'!$B$51+3<'🌱 Configuração'!$C$51,INT((4-1)/7)+1=2,MOD(4-1,7)=0),"🌱 Enraizador + Vitamina B1",IF(AND('🌱 Configuração'!$B$51+3>='🌱 Configuração'!$C$51,'🌱 Configuração'!$B$51+3<'🌱 Configuração'!$D$51,INT(('🌱 Configuração'!$B$51+3-'🌱 Configuração'!$C$51)/7)+1=1,MOD('🌱 Configuração'!$B$51+3-'🌱 Configuração'!$C$51,7)=0),"🌿 Grow A+B início — EC 0.8",IF(AND('🌱 Configuração'!$B$51+3>='🌱 Configuração'!$C$51,'🌱 Configuração'!$B$51+3<'🌱 Configuração'!$D$51,INT(('🌱 Configuração'!$B$51+3-'🌱 Configuração'!$C$51)/7)+1=2,MOD('🌱 Configuração'!$B$51+3-'🌱 Configuração'!$C$51,7)=0),"🌿 Grow A+B + CalMag — EC 1.0",IF(AND('🌱 Configuração'!$B$51+3>='🌱 Configuração'!$C$51,'🌱 Configuração'!$B$51+3<'🌱 Configuração'!$D$51,INT(('🌱 Configuração'!$B$51+3-'🌱 Configuração'!$C$51)/7)+1=3,MOD('🌱 Configuração'!$B$51+3-'🌱 Configuração'!$C$51,7)=0),"🌿 Grow A+B + CalMag — EC 1.2",IF(AND('🌱 Configuração'!$B$51+3>='🌱 Configuração'!$C$51,'🌱 Configuração'!$B$51+3<'🌱 Configuração'!$D$51,INT(('🌱 Configuração'!$B$51+3-'🌱 Configuração'!$C$51)/7)+1=4,MOD('🌱 Configuração'!$B$51+3-'🌱 Configuração'!$C$51,7)=0),"🌿 Grow A+B + Enzimas — EC 1.4",IF(AND('🌱 Configuração'!$B$51+3>='🌱 Configuração'!$C$51,'🌱 Configuração'!$B$51+3<'🌱 Configuração'!$D$51,INT(('🌱 Configuração'!$B$51+3-'🌱 Configuração'!$C$51)/7)+1=5,MOD('🌱 Configuração'!$B$51+3-'🌱 Configuração'!$C$51,7)=0),"🌿 Grow A+B + Biorrizas — EC 1.5",IF(AND('🌱 Configuração'!$B$51+3>='🌱 Configuração'!$C$51,'🌱 Configuração'!$B$51+3<'🌱 Configuração'!$D$51,INT(('🌱 Configuração'!$B$51+3-'🌱 Configuração'!$C$51)/7)+1=6,MOD('🌱 Configuração'!$B$51+3-'🌱 Configuração'!$C$51,7)=0),"🌿 Transição Bloom — EC 1.4",IF(AND('🌱 Configuração'!$B$51+3>='🌱 Configuração'!$C$51,'🌱 Configuração'!$B$51+3<'🌱 Configuração'!$D$51,INT(('🌱 Configuração'!$B$51+3-'🌱 Configuração'!$C$51)/7)+1=7,MOD('🌱 Configuração'!$B$51+3-'🌱 Configuração'!$C$51,7)=0),"🌿 Bloom A+B transição — EC 1.4",IF(AND('🌱 Configuração'!$B$51+3>='🌱 Configuração'!$C$51,'🌱 Configuração'!$B$51+3<'🌱 Configuração'!$D$51,INT(('🌱 Configuração'!$B$51+3-'🌱 Configuração'!$C$51)/7)+1=8,MOD('🌱 Configuração'!$B$51+3-'🌱 Configuração'!$C$51,7)=0),"🌿 Bloom A+B — EC 1.4",IF(AND('🌱 Configuração'!$B$51+3>='🌱 Configuração'!$D$51,'🌱 Configuração'!$B$51+3<'🌱 Configuração'!$E$51,INT(('🌱 Configuração'!$B$51+3-'🌱 Configuração'!$D$51)/7)+1=1,MOD('🌱 Configuração'!$B$51+3-'🌱 Configuração'!$D$51,7)=0),"🌸 Bloom A+B — EC 1.6",IF(AND('🌱 Configuração'!$B$51+3>='🌱 Configuração'!$D$51,'🌱 Configuração'!$B$51+3<'🌱 Configuração'!$E$51,INT(('🌱 Configuração'!$B$51+3-'🌱 Configuração'!$D$51)/7)+1=2,MOD('🌱 Configuração'!$B$51+3-'🌱 Configuração'!$D$51,7)=0),"🌸 Bloom + PK 13/14 início",IF(AND('🌱 Configuração'!$B$51+3>='🌱 Configuração'!$D$51,'🌱 Configuração'!$B$51+3<'🌱 Configuração'!$E$51,INT(('🌱 Configuração'!$B$51+3-'🌱 Configuração'!$D$51)/7)+1=3,MOD('🌱 Configuração'!$B$51+3-'🌱 Configuração'!$D$51,7)=0),"🌸 Bloom + PK + CalMag — EC 1.8",IF(AND('🌱 Configuração'!$B$51+3>='🌱 Configuração'!$D$51,'🌱 Configuração'!$B$51+3<'🌱 Configuração'!$E$51,INT(('🌱 Configuração'!$B$51+3-'🌱 Configuração'!$D$51)/7)+1=4,MOD('🌱 Configuração'!$B$51+3-'🌱 Configuração'!$D$51,7)=0),"🌸 Bloom + PK + Boost Floral — EC 2.0",IF(AND('🌱 Configuração'!$B$51+3>='🌱 Configuração'!$D$51,'🌱 Configuração'!$B$51+3<'🌱 Configuração'!$E$51,INT(('🌱 Configuração'!$B$51+3-'🌱 Configuração'!$D$51)/7)+1=5,MOD('🌱 Configuração'!$B$51+3-'🌱 Configuração'!$D$51,7)=0),"🌸 Bloom + Boost + Amino",IF(AND('🌱 Configuração'!$B$51+3>='🌱 Configuração'!$D$51,'🌱 Configuração'!$B$51+3<'🌱 Configuração'!$E$51,INT(('🌱 Configuração'!$B$51+3-'🌱 Configuração'!$D$51)/7)+1=6,MOD('🌱 Configuração'!$B$51+3-'🌱 Configuração'!$D$51,7)=0),"🌸 Bloom + Enzimas + Amino",IF(AND('🌱 Configuração'!$B$51+3>='🌱 Configuração'!$D$51,'🌱 Configuração'!$B$51+3<'🌱 Configuração'!$E$51,INT(('🌱 Configuração'!$B$51+3-'🌱 Configuração'!$D$51)/7)+1=7,MOD('🌱 Configuração'!$B$51+3-'🌱 Configuração'!$D$51,7)=0),"🌸 Reduzir N — Bloom puro — EC 1.6",IF(AND('🌱 Configuração'!$B$51+3>='🌱 Configuração'!$D$51,'🌱 Configuração'!$B$51+3<'🌱 Configuração'!$E$51,INT(('🌱 Configuração'!$B$51+3-'🌱 Configuração'!$D$51)/7)+1=8,MOD('🌱 Configuração'!$B$51+3-'🌱 Configuração'!$D$51,7)=0),"🌸 Bloom puro — EC 1.4 (pré-flush)",IF(AND('🌱 Configuração'!$B$51+3>='🌱 Configuração'!$D$51,'🌱 Configuração'!$B$51+3<'🌱 Configuração'!$E$51,INT(('🌱 Configuração'!$B$51+3-'🌱 Configuração'!$D$51)/7)+1=9,MOD('🌱 Configuração'!$B$51+3-'🌱 Configuração'!$D$51,7)=0),"🌸 Último Bloom — EC 0.8",IF(AND('🌱 Configuração'!$B$51+3>='🌱 Configuração'!$E$51,INT(('🌱 Configuração'!$B$51+3-'🌱 Configuração'!$E$51)/7)+1=1,MOD('🌱 Configuração'!$B$51+3-'🌱 Configuração'!$E$51,7)=0),"🚿 Água pura + Enzimas (EC < 0.3)",IF(AND('🌱 Configuração'!$B$51+3>='🌱 Configuração'!$E$51,INT(('🌱 Configuração'!$B$51+3-'🌱 Configuração'!$E$51)/7)+1=2,MOD('🌱 Configuração'!$B$51+3-'🌱 Configuração'!$E$51,7)=0),"🚿 Água pura (EC < 0.2)","")))))))))))))))))))))) | G9: =IF(4>'🌱 Configuração'!$F$50,"",IF(AND('🌱 Configuração'!$B$51+3<'🌱 Configuração'!$C$51,INT((4-1)/7)+1=1,MOD(4-1,7)=0),"🐛 Nim 2mL/L foliar — preventivo",IF(AND('🌱 Configuração'!$B$51+3<'🌱 Configuração'!$C$51,INT((4-1)/7)+1=2,MOD(4-1,7)=0),"🐛 Beauveria bassiana foliar + solo",IF(AND('🌱 Configuração'!$B$51+3>='🌱 Configuração'!$C$51,'🌱 Configuração'!$B$51+3<'🌱 Configuração'!$D$51,INT(('🌱 Configuração'!$B$51+3-'🌱 Configuração'!$C$51)/7)+1=1,MOD('🌱 Configuração'!$B$51+3-'🌱 Configuração'!$C$51,7)=0),"🐛 Nim 2mL/L foliar",IF(AND('🌱 Configuração'!$B$51+3>='🌱 Configuração'!$C$51,'🌱 Configuração'!$B$51+3<'🌱 Configuração'!$D$51,INT(('🌱 Configuração'!$B$51+3-'🌱 Configuração'!$C$51)/7)+1=2,MOD('🌱 Configuração'!$B$51+3-'🌱 Configuração'!$C$51,7)=0),"🐛 Beauveria bassiana foliar",IF(AND('🌱 Configuração'!$B$51+3>='🌱 Configuração'!$C$51,'🌱 Configuração'!$B$51+3<'🌱 Configuração'!$D$51,INT(('🌱 Configuração'!$B$51+3-'🌱 Configuração'!$C$51)/7)+1=3,MOD('🌱 Configuração'!$B$51+3-'🌱 Configuração'!$C$51,7)=0),"🐛 Nim + Calda Sulfocálcica 1%",IF(AND('🌱 Configuração'!$B$51+3>='🌱 Configuração'!$C$51,'🌱 Configuração'!$B$51+3<'🌱 Configuração'!$D$51,INT(('🌱 Configuração'!$B$51+3-'🌱 Configuração'!$C$51)/7)+1=4,MOD('🌱 Configuração'!$B$51+3-'🌱 Configuração'!$C$51,7)=0),"🐛 Trichoderma solo + Beauveria",IF(AND('🌱 Configuração'!$B$51+3>='🌱 Configuração'!$C$51,'🌱 Configuração'!$B$51+3<'🌱 Configuração'!$D$51,INT(('🌱 Configuração'!$B$51+3-'🌱 Configuração'!$C$51)/7)+1=5,MOD('🌱 Configuração'!$B$51+3-'🌱 Configuração'!$C$51,7)=0),"🐛 Calda Bordalesa 0.5% foliar",IF(AND('🌱 Configuração'!$B$51+3>='🌱 Configuração'!$C$51,'🌱 Configuração'!$B$51+3<'🌱 Configuração'!$D$51,INT(('🌱 Configuração'!$B$51+3-'🌱 Configuração'!$C$51)/7)+1=6,MOD('🌱 Configuração'!$B$51+3-'🌱 Configuração'!$C$51,7)=0),"🐛 Nim 2mL/L — ÚLTIMA foliar",IF(AND('🌱 Configuração'!$B$51+3>='🌱 Configuração'!$D$51,'🌱 Configuração'!$B$51+3<'🌱 Configuração'!$E$51,INT(('🌱 Configuração'!$B$51+3-'🌱 Configuração'!$D$51)/7)+1=1,MOD('🌱 Configuração'!$B$51+3-'🌱 Configuração'!$D$51,7)=0),"🐛 Beauveria bassiana solo (sem foliar)",IF(AND('🌱 Configuração'!$B$51+3>='🌱 Configuração'!$D$51,'🌱 Configuração'!$B$51+3<'🌱 Configuração'!$E$51,INT(('🌱 Configuração'!$B$51+3-'🌱 Configuração'!$D$51)/7)+1=2,MOD('🌱 Configuração'!$B$51+3-'🌱 Configuração'!$D$51,7)=0),"🐛 Trichoderma solo",IF(AND('🌱 Configuração'!$B$51+3>='🌱 Configuração'!$D$51,'🌱 Configuração'!$B$51+3<'🌱 Configuração'!$E$51,INT(('🌱 Configuração'!$B$51+3-'🌱 Configuração'!$D$51)/7)+1=3,MOD('🌱 Configuração'!$B$51+3-'🌱 Configuração'!$D$51,7)=0),"🐛 Beauveria bassiana solo",IF(AND('🌱 Configuração'!$B$51+3>='🌱 Configuração'!$D$51,'🌱 Configuração'!$B$51+3<'🌱 Configuração'!$E$51,INT(('🌱 Configuração'!$B$51+3-'🌱 Configuração'!$D$51)/7)+1=4,MOD('🌱 Configuração'!$B$51+3-'🌱 Configuração'!$D$51,7)=0),"🐛 Trichoderma solo",IF(AND('🌱 Configuração'!$B$51+3>='🌱 Configuração'!$E$51,INT(('🌱 Configuração'!$B$51+3-'🌱 Configuração'!$E$51)/7)+1=1,MOD('🌱 Configuração'!$B$51+3-'🌱 Configuração'!$E$51,7)=0),"🐛 Inspeção final — sem aplicação","")))))))))))))) | H9: =IF(4>'🌱 Configuração'!$F$50,"","💧 1ª rega com enraizador") -> 💧 1ª rega com enraizador
B10: =IF(5<='🌱 Configuração'!$F$50,5,"") -> 5 | C10: =IF(5<='🌱 Configuração'!$F$50,'🌱 Configuração'!$B$51+4,"") -> 46027 | D10: =IF(5>'🌱 Configuração'!$F$50,"",IF('🌱 Configuração'!$B$51+4<'🌱 Configuração'!$C$51,"🌱 Clone",IF('🌱 Configuração'!$B$51+4<'🌱 Configuração'!$D$51,"🌿 Vegetativo",IF('🌱 Configuração'!$B$51+4<'🌱 Configuração'!$E$51,"🌸 Floração","🚿 Flush")))) -> 🌱 Clone | E10: =IF(5>'🌱 Configuração'!$F$50,"",IF('🌱 Configuração'!$B$51+4<'🌱 Configuração'!$C$51,"Clone S"&INT((5-1)/7)+1,IF('🌱 Configuração'!$B$51+4<'🌱 Configuração'!$D$51,"Vega S"&INT(('🌱 Configuração'!$B$51+4-'🌱 Configuração'!$C$51)/7)+1,IF('🌱 Configuração'!$B$51+4<'🌱 Configuração'!$E$51,"Flora S"&INT(('🌱 Configuração'!$B$51+4-'🌱 Configuração'!$D$51)/7)+1,"Flush S"&INT(('🌱 Configuração'!$B$51+4-'🌱 Configuração'!$E$51)/7)+1)))) -> Clone S1 | F10: =IF(5>'🌱 Configuração'!$F$50,"",IF(AND('🌱 Configuração'!$B$51+4<'🌱 Configuração'!$C$51,INT((5-1)/7)+1=1,MOD(5-1,7)=0),"🌱 Enraizador (0.5 mL/L)",IF(AND('🌱 Configuração'!$B$51+4<'🌱 Configuração'!$C$51,INT((5-1)/7)+1=2,MOD(5-1,7)=0),"🌱 Enraizador + Vitamina B1",IF(AND('🌱 Configuração'!$B$51+4>='🌱 Configuração'!$C$51,'🌱 Configuração'!$B$51+4<'🌱 Configuração'!$D$51,INT(('🌱 Configuração'!$B$51+4-'🌱 Configuração'!$C$51)/7)+1=1,MOD('🌱 Configuração'!$B$51+4-'🌱 Configuração'!$C$51,7)=0),"🌿 Grow A+B início — EC 0.8",IF(AND('🌱 Configuração'!$B$51+4>='🌱 Configuração'!$C$51,'🌱 Configuração'!$B$51+4<'🌱 Configuração'!$D$51,INT(('🌱 Configuração'!$B$51+4-'🌱 Configuração'!$C$51)/7)+1=2,MOD('🌱 Configuração'!$B$51+4-'🌱 Configuração'!$C$51,7)=0),"🌿 Grow A+B + CalMag — EC 1.0",IF(AND('🌱 Configuração'!$B$51+4>='🌱 Configuração'!$C$51,'🌱 Configuração'!$B$51+4<'🌱 Configuração'!$D$51,INT(('🌱 Configuração'!$B$51+4-'🌱 Configuração'!$C$51)/7)+1=3,MOD('🌱 Configuração'!$B$51+4-'🌱 Configuração'!$C$51,7)=0),"🌿 Grow A+B + CalMag — EC 1.2",IF(AND('🌱 Configuração'!$B$51+4>='🌱 Configuração'!$C$51,'🌱 Configuração'!$B$51+4<'🌱 Configuração'!$D$51,INT(('🌱 Configuração'!$B$51+4-'🌱 Configuração'!$C$51)/7)+1=4,MOD('🌱 Configuração'!$B$51+4-'🌱 Configuração'!$C$51,7)=0),"🌿 Grow A+B + Enzimas — EC 1.4",IF(AND('🌱 Configuração'!$B$51+4>='🌱 Configuração'!$C$51,'🌱 Configuração'!$B$51+4<'🌱 Configuração'!$D$51,INT(('🌱 Configuração'!$B$51+4-'🌱 Configuração'!$C$51)/7)+1=5,MOD('🌱 Configuração'!$B$51+4-'🌱 Configuração'!$C$51,7)=0),"🌿 Grow A+B + Biorrizas — EC 1.5",IF(AND('🌱 Configuração'!$B$51+4>='🌱 Configuração'!$C$51,'🌱 Configuração'!$B$51+4<'🌱 Configuração'!$D$51,INT(('🌱 Configuração'!$B$51+4-'🌱 Configuração'!$C$51)/7)+1=6,MOD('🌱 Configuração'!$B$51+4-'🌱 Configuração'!$C$51,7)=0),"🌿 Transição Bloom — EC 1.4",IF(AND('🌱 Configuração'!$B$51+4>='🌱 Configuração'!$C$51,'🌱 Configuração'!$B$51+4<'🌱 Configuração'!$D$51,INT(('🌱 Configuração'!$B$51+4-'🌱 Configuração'!$C$51)/7)+1=7,MOD('🌱 Configuração'!$B$51+4-'🌱 Configuração'!$C$51,7)=0),"🌿 Bloom A+B transição — EC 1.4",IF(AND('🌱 Configuração'!$B$51+4>='🌱 Configuração'!$C$51,'🌱 Configuração'!$B$51+4<'🌱 Configuração'!$D$51,INT(('🌱 Configuração'!$B$51+4-'🌱 Configuração'!$C$51)/7)+1=8,MOD('🌱 Configuração'!$B$51+4-'🌱 Configuração'!$C$51,7)=0),"🌿 Bloom A+B — EC 1.4",IF(AND('🌱 Configuração'!$B$51+4>='🌱 Configuração'!$D$51,'🌱 Configuração'!$B$51+4<'🌱 Configuração'!$E$51,INT(('🌱 Configuração'!$B$51+4-'🌱 Configuração'!$D$51)/7)+1=1,MOD('🌱 Configuração'!$B$51+4-'🌱 Configuração'!$D$51,7)=0),"🌸 Bloom A+B — EC 1.6",IF(AND('🌱 Configuração'!$B$51+4>='🌱 Configuração'!$D$51,'🌱 Configuração'!$B$51+4<'🌱 Configuração'!$E$51,INT(('🌱 Configuração'!$B$51+4-'🌱 Configuração'!$D$51)/7)+1=2,MOD('🌱 Configuração'!$B$51+4-'🌱 Configuração'!$D$51,7)=0),"🌸 Bloom + PK 13/14 início",IF(AND('🌱 Configuração'!$B$51+4>='🌱 Configuração'!$D$51,'🌱 Configuração'!$B$51+4<'🌱 Configuração'!$E$51,INT(('🌱 Configuração'!$B$51+4-'🌱 Configuração'!$D$51)/7)+1=3,MOD('🌱 Configuração'!$B$51+4-'🌱 Configuração'!$D$51,7)=0),"🌸 Bloom + PK + CalMag — EC 1.8",IF(AND('🌱 Configuração'!$B$51+4>='🌱 Configuração'!$D$51,'🌱 Configuração'!$B$51+4<'🌱 Configuração'!$E$51,INT(('🌱 Configuração'!$B$51+4-'🌱 Configuração'!$D$51)/7)+1=4,MOD('🌱 Configuração'!$B$51+4-'🌱 Configuração'!$D$51,7)=0),"🌸 Bloom + PK + Boost Floral — EC 2.0",IF(AND('🌱 Configuração'!$B$51+4>='🌱 Configuração'!$D$51,'🌱 Configuração'!$B$51+4<'🌱 Configuração'!$E$51,INT(('🌱 Configuração'!$B$51+4-'🌱 Configuração'!$D$51)/7)+1=5,MOD('🌱 Configuração'!$B$51+4-'🌱 Configuração'!$D$51,7)=0),"🌸 Bloom + Boost + Amino",IF(AND('🌱 Configuração'!$B$51+4>='🌱 Configuração'!$D$51,'🌱 Configuração'!$B$51+4<'🌱 Configuração'!$E$51,INT(('🌱 Configuração'!$B$51+4-'🌱 Configuração'!$D$51)/7)+1=6,MOD('🌱 Configuração'!$B$51+4-'🌱 Configuração'!$D$51,7)=0),"🌸 Bloom + Enzimas + Amino",IF(AND('🌱 Configuração'!$B$51+4>='🌱 Configuração'!$D$51,'🌱 Configuração'!$B$51+4<'🌱 Configuração'!$E$51,INT(('🌱 Configuração'!$B$51+4-'🌱 Configuração'!$D$51)/7)+1=7,MOD('🌱 Configuração'!$B$51+4-'🌱 Configuração'!$D$51,7)=0),"🌸 Reduzir N — Bloom puro — EC 1.6",IF(AND('🌱 Configuração'!$B$51+4>='🌱 Configuração'!$D$51,'🌱 Configuração'!$B$51+4<'🌱 Configuração'!$E$51,INT(('🌱 Configuração'!$B$51+4-'🌱 Configuração'!$D$51)/7)+1=8,MOD('🌱 Configuração'!$B$51+4-'🌱 Configuração'!$D$51,7)=0),"🌸 Bloom puro — EC 1.4 (pré-flush)",IF(AND('🌱 Configuração'!$B$51+4>='🌱 Configuração'!$D$51,'🌱 Configuração'!$B$51+4<'🌱 Configuração'!$E$51,INT(('🌱 Configuração'!$B$51+4-'🌱 Configuração'!$D$51)/7)+1=9,MOD('🌱 Configuração'!$B$51+4-'🌱 Configuração'!$D$51,7)=0),"🌸 Último Bloom — EC 0.8",IF(AND('🌱 Configuração'!$B$51+4>='🌱 Configuração'!$E$51,INT(('🌱 Configuração'!$B$51+4-'🌱 Configuração'!$E$51)/7)+1=1,MOD('🌱 Configuração'!$B$51+4-'🌱 Configuração'!$E$51,7)=0),"🚿 Água pura + Enzimas (EC < 0.3)",IF(AND('🌱 Configuração'!$B$51+4>='🌱 Configuração'!$E$51,INT(('🌱 Configuração'!$B$51+4-'🌱 Configuração'!$E$51)/7)+1=2,MOD('🌱 Configuração'!$B$51+4-'🌱 Configuração'!$E$51,7)=0),"🚿 Água pura (EC < 0.2)","")))))))))))))))))))))) | G10: =IF(5>'🌱 Configuração'!$F$50,"",IF(AND('🌱 Configuração'!$B$51+4<'🌱 Configuração'!$C$51,INT((5-1)/7)+1=1,MOD(5-1,7)=0),"🐛 Nim 2mL/L foliar — preventivo",IF(AND('🌱 Configuração'!$B$51+4<'🌱 Configuração'!$C$51,INT((5-1)/7)+1=2,MOD(5-1,7)=0),"🐛 Beauveria bassiana foliar + solo",IF(AND('🌱 Configuração'!$B$51+4>='🌱 Configuração'!$C$51,'🌱 Configuração'!$B$51+4<'🌱 Configuração'!$D$51,INT(('🌱 Configuração'!$B$51+4-'🌱 Configuração'!$C$51)/7)+1=1,MOD('🌱 Configuração'!$B$51+4-'🌱 Configuração'!$C$51,7)=0),"🐛 Nim 2mL/L foliar",IF(AND('🌱 Configuração'!$B$51+4>='🌱 Configuração'!$C$51,'🌱 Configuração'!$B$51+4<'🌱 Configuração'!$D$51,INT(('🌱 Configuração'!$B$51+4-'🌱 Configuração'!$C$51)/7)+1=2,MOD('🌱 Configuração'!$B$51+4-'🌱 Configuração'!$C$51,7)=0),"🐛 Beauveria bassiana foliar",IF(AND('🌱 Configuração'!$B$51+4>='🌱 Configuração'!$C$51,'🌱 Configuração'!$B$51+4<'🌱 Configuração'!$D$51,INT(('🌱 Configuração'!$B$51+4-'🌱 Configuração'!$C$51)/7)+1=3,MOD('🌱 Configuração'!$B$51+4-'🌱 Configuração'!$C$51,7)=0),"🐛 Nim + Calda Sulfocálcica 1%",IF(AND('🌱 Configuração'!$B$51+4>='🌱 Configuração'!$C$51,'🌱 Configuração'!$B$51+4<'🌱 Configuração'!$D$51,INT(('🌱 Configuração'!$B$51+4-'🌱 Configuração'!$C$51)/7)+1=4,MOD('🌱 Configuração'!$B$51+4-'🌱 Configuração'!$C$51,7)=0),"🐛 Trichoderma solo + Beauveria",IF(AND('🌱 Configuração'!$B$51+4>='🌱 Configuração'!$C$51,'🌱 Configuração'!$B$51+4<'🌱 Configuração'!$D$51,INT(('🌱 Configuração'!$B$51+4-'🌱 Configuração'!$C$51)/7)+1=5,MOD('🌱 Configuração'!$B$51+4-'🌱 Configuração'!$C$51,7)=0),"🐛 Calda Bordalesa 0.5% foliar",IF(AND('🌱 Configuração'!$B$51+4>='🌱 Configuração'!$C$51,'🌱 Configuração'!$B$51+4<'🌱 Configuração'!$D$51,INT(('🌱 Configuração'!$B$51+4-'🌱 Configuração'!$C$51)/7)+1=6,MOD('🌱 Configuração'!$B$51+4-'🌱 Configuração'!$C$51,7)=0),"🐛 Nim 2mL/L — ÚLTIMA foliar",IF(AND('🌱 Configuração'!$B$51+4>='🌱 Configuração'!$D$51,'🌱 Configuração'!$B$51+4<'🌱 Configuração'!$E$51,INT(('🌱 Configuração'!$B$51+4-'🌱 Configuração'!$D$51)/7)+1=1,MOD('🌱 Configuração'!$B$51+4-'🌱 Configuração'!$D$51,7)=0),"🐛 Beauveria bassiana solo (sem foliar)",IF(AND('🌱 Configuração'!$B$51+4>='🌱 Configuração'!$D$51,'🌱 Configuração'!$B$51+4<'🌱 Configuração'!$E$51,INT(('🌱 Configuração'!$B$51+4-'🌱 Configuração'!$D$51)/7)+1=2,MOD('🌱 Configuração'!$B$51+4-'🌱 Configuração'!$D$51,7)=0),"🐛 Trichoderma solo",IF(AND('🌱 Configuração'!$B$51+4>='🌱 Configuração'!$D$51,'🌱 Configuração'!$B$51+4<'🌱 Configuração'!$E$51,INT(('🌱 Configuração'!$B$51+4-'🌱 Configuração'!$D$51)/7)+1=3,MOD('🌱 Configuração'!$B$51+4-'🌱 Configuração'!$D$51,7)=0),"🐛 Beauveria bassiana solo",IF(AND('🌱 Configuração'!$B$51+4>='🌱 Configuração'!$D$51,'🌱 Configuração'!$B$51+4<'🌱 Configuração'!$E$51,INT(('🌱 Configuração'!$B$51+4-'🌱 Configuração'!$D$51)/7)+1=4,MOD('🌱 Configuração'!$B$51+4-'🌱 Configuração'!$D$51,7)=0),"🐛 Trichoderma solo",IF(AND('🌱 Configuração'!$B$51+4>='🌱 Configuração'!$E$51,INT(('🌱 Configuração'!$B$51+4-'🌱 Configuração'!$E$51)/7)+1=1,MOD('🌱 Configuração'!$B$51+4-'🌱 Configuração'!$E$51,7)=0),"🐛 Inspeção final — sem aplicação","")))))))))))))) | H10: =IF(5>'🌱 Configuração'!$F$50,"",IF('🌱 Configuração'!$B$51+4='🌱 Configuração'!$C$51,"🌿 INÍCIO VEGA — ajustar espaço, luz 18h/dia — EC 0.8",IF('🌱 Configuração'!$B$51+4='🌱 Configuração'!$D$51,"🌸 INÍCIO FLORAÇÃO — mudar para 12h/12h — 🔴 atenção ao fotoperíodo",IF('🌱 Configuração'!$B$51+4='🌱 Configuração'!$E$51,"🚿 INÍCIO FLUSH — PARAR nutrição, somente água pura",IF('🌱 Configuração'!$B$51+4='🌱 Configuração'!$F$51-1,"🔬 Véspera da colheita — analisar tricomas âmbar",IF('🌱 Configuração'!$B$51+4='🌱 Configuração'!$F$51,"✂️ COLHEITA! Parabéns! 🎉",""))))))
B11: =IF(6<='🌱 Configuração'!$F$50,6,"") -> 6 | C11: =IF(6<='🌱 Configuração'!$F$50,'🌱 Configuração'!$B$51+5,"") -> 46028 | D11: =IF(6>'🌱 Configuração'!$F$50,"",IF('🌱 Configuração'!$B$51+5<'🌱 Configuração'!$C$51,"🌱 Clone",IF('🌱 Configuração'!$B$51+5<'🌱 Configuração'!$D$51,"🌿 Vegetativo",IF('🌱 Configuração'!$B$51+5<'🌱 Configuração'!$E$51,"🌸 Floração","🚿 Flush")))) -> 🌱 Clone | E11: =IF(6>'🌱 Configuração'!$F$50,"",IF('🌱 Configuração'!$B$51+5<'🌱 Configuração'!$C$51,"Clone S"&INT((6-1)/7)+1,IF('🌱 Configuração'!$B$51+5<'🌱 Configuração'!$D$51,"Vega S"&INT(('🌱 Configuração'!$B$51+5-'🌱 Configuração'!$C$51)/7)+1,IF('🌱 Configuração'!$B$51+5<'🌱 Configuração'!$E$51,"Flora S"&INT(('🌱 Configuração'!$B$51+5-'🌱 Configuração'!$D$51)/7)+1,"Flush S"&INT(('🌱 Configuração'!$B$51+5-'🌱 Configuração'!$E$51)/7)+1)))) -> Clone S1 | F11: =IF(6>'🌱 Configuração'!$F$50,"",IF(AND('🌱 Configuração'!$B$51+5<'🌱 Configuração'!$C$51,INT((6-1)/7)+1=1,MOD(6-1,7)=0),"🌱 Enraizador (0.5 mL/L)",IF(AND('🌱 Configuração'!$B$51+5<'🌱 Configuração'!$C$51,INT((6-1)/7)+1=2,MOD(6-1,7)=0),"🌱 Enraizador + Vitamina B1",IF(AND('🌱 Configuração'!$B$51+5>='🌱 Configuração'!$C$51,'🌱 Configuração'!$B$51+5<'🌱 Configuração'!$D$51,INT(('🌱 Configuração'!$B$51+5-'🌱 Configuração'!$C$51)/7)+1=1,MOD('🌱 Configuração'!$B$51+5-'🌱 Configuração'!$C$51,7)=0),"🌿 Grow A+B início — EC 0.8",IF(AND('🌱 Configuração'!$B$51+5>='🌱 Configuração'!$C$51,'🌱 Configuração'!$B$51+5<'🌱 Configuração'!$D$51,INT(('🌱 Configuração'!$B$51+5-'🌱 Configuração'!$C$51)/7)+1=2,MOD('🌱 Configuração'!$B$51+5-'🌱 Configuração'!$C$51,7)=0),"🌿 Grow A+B + CalMag — EC 1.0",IF(AND('🌱 Configuração'!$B$51+5>='🌱 Configuração'!$C$51,'🌱 Configuração'!$B$51+5<'🌱 Configuração'!$D$51,INT(('🌱 Configuração'!$B$51+5-'🌱 Configuração'!$C$51)/7)+1=3,MOD('🌱 Configuração'!$B$51+5-'🌱 Configuração'!$C$51,7)=0),"🌿 Grow A+B + CalMag — EC 1.2",IF(AND('🌱 Configuração'!$B$51+5>='🌱 Configuração'!$C$51,'🌱 Configuração'!$B$51+5<'🌱 Configuração'!$D$51,INT(('🌱 Configuração'!$B$51+5-'🌱 Configuração'!$C$51)/7)+1=4,MOD('🌱 Configuração'!$B$51+5-'🌱 Configuração'!$C$51,7)=0),"🌿 Grow A+B + Enzimas — EC 1.4",IF(AND('🌱 Configuração'!$B$51+5>='🌱 Configuração'!$C$51,'🌱 Configuração'!$B$51+5<'🌱 Configuração'!$D$51,INT(('🌱 Configuração'!$B$51+5-'🌱 Configuração'!$C$51)/7)+1=5,MOD('🌱 Configuração'!$B$51+5-'🌱 Configuração'!$C$51,7)=0),"🌿 Grow A+B + Biorrizas — EC 1.5",IF(AND('🌱 Configuração'!$B$51+5>='🌱 Configuração'!$C$51,'🌱 Configuração'!$B$51+5<'🌱 Configuração'!$D$51,INT(('🌱 Configuração'!$B$51+5-'🌱 Configuração'!$C$51)/7)+1=6,MOD('🌱 Configuração'!$B$51+5-'🌱 Configuração'!$C$51,7)=0),"🌿 Transição Bloom — EC 1.4",IF(AND('🌱 Configuração'!$B$51+5>='🌱 Configuração'!$C$51,'🌱 Configuração'!$B$51+5<'🌱 Configuração'!$D$51,INT(('🌱 Configuração'!$B$51+5-'🌱 Configuração'!$C$51)/7)+1=7,MOD('🌱 Configuração'!$B$51+5-'🌱 Configuração'!$C$51,7)=0),"🌿 Bloom A+B transição — EC 1.4",IF(AND('🌱 Configuração'!$B$51+5>='🌱 Configuração'!$C$51,'🌱 Configuração'!$B$51+5<'🌱 Configuração'!$D$51,INT(('🌱 Configuração'!$B$51+5-'🌱 Configuração'!$C$51)/7)+1=8,MOD('🌱 Configuração'!$B$51+5-'🌱 Configuração'!$C$51,7)=0),"🌿 Bloom A+B — EC 1.4",IF(AND('🌱 Configuração'!$B$51+5>='🌱 Configuração'!$D$51,'🌱 Configuração'!$B$51+5<'🌱 Configuração'!$E$51,INT(('🌱 Configuração'!$B$51+5-'🌱 Configuração'!$D$51)/7)+1=1,MOD('🌱 Configuração'!$B$51+5-'🌱 Configuração'!$D$51,7)=0),"🌸 Bloom A+B — EC 1.6",IF(AND('🌱 Configuração'!$B$51+5>='🌱 Configuração'!$D$51,'🌱 Configuração'!$B$51+5<'🌱 Configuração'!$E$51,INT(('🌱 Configuração'!$B$51+5-'🌱 Configuração'!$D$51)/7)+1=2,MOD('🌱 Configuração'!$B$51+5-'🌱 Configuração'!$D$51,7)=0),"🌸 Bloom + PK 13/14 início",IF(AND('🌱 Configuração'!$B$51+5>='🌱 Configuração'!$D$51,'🌱 Configuração'!$B$51+5<'🌱 Configuração'!$E$51,INT(('🌱 Configuração'!$B$51+5-'🌱 Configuração'!$D$51)/7)+1=3,MOD('🌱 Configuração'!$B$51+5-'🌱 Configuração'!$D$51,7)=0),"🌸 Bloom + PK + CalMag — EC 1.8",IF(AND('🌱 Configuração'!$B$51+5>='🌱 Configuração'!$D$51,'🌱 Configuração'!$B$51+5<'🌱 Configuração'!$E$51,INT(('🌱 Configuração'!$B$51+5-'🌱 Configuração'!$D$51)/7)+1=4,MOD('🌱 Configuração'!$B$51+5-'🌱 Configuração'!$D$51,7)=0),"🌸 Bloom + PK + Boost Floral — EC 2.0",IF(AND('🌱 Configuração'!$B$51+5>='🌱 Configuração'!$D$51,'🌱 Configuração'!$B$51+5<'🌱 Configuração'!$E$51,INT(('🌱 Configuração'!$B$51+5-'🌱 Configuração'!$D$51)/7)+1=5,MOD('🌱 Configuração'!$B$51+5-'🌱 Configuração'!$D$51,7)=0),"🌸 Bloom + Boost + Amino",IF(AND('🌱 Configuração'!$B$51+5>='🌱 Configuração'!$D$51,'🌱 Configuração'!$B$51+5<'🌱 Configuração'!$E$51,INT(('🌱 Configuração'!$B$51+5-'🌱 Configuração'!$D$51)/7)+1=6,MOD('🌱 Configuração'!$B$51+5-'🌱 Configuração'!$D$51,7)=0),"🌸 Bloom + Enzimas + Amino",IF(AND('🌱 Configuração'!$B$51+5>='🌱 Configuração'!$D$51,'🌱 Configuração'!$B$51+5<'🌱 Configuração'!$E$51,INT(('🌱 Configuração'!$B$51+5-'🌱 Configuração'!$D$51)/7)+1=7,MOD('🌱 Configuração'!$B$51+5-'🌱 Configuração'!$D$51,7)=0),"🌸 Reduzir N — Bloom puro — EC 1.6",IF(AND('🌱 Configuração'!$B$51+5>='🌱 Configuração'!$D$51,'🌱 Configuração'!$B$51+5<'🌱 Configuração'!$E$51,INT(('🌱 Configuração'!$B$51+5-'🌱 Configuração'!$D$51)/7)+1=8,MOD('🌱 Configuração'!$B$51+5-'🌱 Configuração'!$D$51,7)=0),"🌸 Bloom puro — EC 1.4 (pré-flush)",IF(AND('🌱 Configuração'!$B$51+5>='🌱 Configuração'!$D$51,'🌱 Configuração'!$B$51+5<'🌱 Configuração'!$E$51,INT(('🌱 Configuração'!$B$51+5-'🌱 Configuração'!$D$51)/7)+1=9,MOD('🌱 Configuração'!$B$51+5-'🌱 Configuração'!$D$51,7)=0),"🌸 Último Bloom — EC 0.8",IF(AND('🌱 Configuração'!$B$51+5>='🌱 Configuração'!$E$51,INT(('🌱 Configuração'!$B$51+5-'🌱 Configuração'!$E$51)/7)+1=1,MOD('🌱 Configuração'!$B$51+5-'🌱 Configuração'!$E$51,7)=0),"🚿 Água pura + Enzimas (EC < 0.3)",IF(AND('🌱 Configuração'!$B$51+5>='🌱 Configuração'!$E$51,INT(('🌱 Configuração'!$B$51+5-'🌱 Configuração'!$E$51)/7)+1=2,MOD('🌱 Configuração'!$B$51+5-'🌱 Configuração'!$E$51,7)=0),"🚿 Água pura (EC < 0.2)","")))))))))))))))))))))) | G11: =IF(6>'🌱 Configuração'!$F$50,"",IF(AND('🌱 Configuração'!$B$51+5<'🌱 Configuração'!$C$51,INT((6-1)/7)+1=1,MOD(6-1,7)=0),"🐛 Nim 2mL/L foliar — preventivo",IF(AND('🌱 Configuração'!$B$51+5<'🌱 Configuração'!$C$51,INT((6-1)/7)+1=2,MOD(6-1,7)=0),"🐛 Beauveria bassiana foliar + solo",IF(AND('🌱 Configuração'!$B$51+5>='🌱 Configuração'!$C$51,'🌱 Configuração'!$B$51+5<'🌱 Configuração'!$D$51,INT(('🌱 Configuração'!$B$51+5-'🌱 Configuração'!$C$51)/7)+1=1,MOD('🌱 Configuração'!$B$51+5-'🌱 Configuração'!$C$51,7)=0),"🐛 Nim 2mL/L foliar",IF(AND('🌱 Configuração'!$B$51+5>='🌱 Configuração'!$C$51,'🌱 Configuração'!$B$51+5<'🌱 Configuração'!$D$51,INT(('🌱 Configuração'!$B$51+5-'🌱 Configuração'!$C$51)/7)+1=2,MOD('🌱 Configuração'!$B$51+5-'🌱 Configuração'!$C$51,7)=0),"🐛 Beauveria bassiana foliar",IF(AND('🌱 Configuração'!$B$51+5>='🌱 Configuração'!$C$51,'🌱 Configuração'!$B$51+5<'🌱 Configuração'!$D$51,INT(('🌱 Configuração'!$B$51+5-'🌱 Configuração'!$C$51)/7)+1=3,MOD('🌱 Configuração'!$B$51+5-'🌱 Configuração'!$C$51,7)=0),"🐛 Nim + Calda Sulfocálcica 1%",IF(AND('🌱 Configuração'!$B$51+5>='🌱 Configuração'!$C$51,'🌱 Configuração'!$B$51+5<'🌱 Configuração'!$D$51,INT(('🌱 Configuração'!$B$51+5-'🌱 Configuração'!$C$51)/7)+1=4,MOD('🌱 Configuração'!$B$51+5-'🌱 Configuração'!$C$51,7)=0),"🐛 Trichoderma solo + Beauveria",IF(AND('🌱 Configuração'!$B$51+5>='🌱 Configuração'!$C$51,'🌱 Configuração'!$B$51+5<'🌱 Configuração'!$D$51,INT(('🌱 Configuração'!$B$51+5-'🌱 Configuração'!$C$51)/7)+1=5,MOD('🌱 Configuração'!$B$51+5-'🌱 Configuração'!$C$51,7)=0),"🐛 Calda Bordalesa 0.5% foliar",IF(AND('🌱 Configuração'!$B$51+5>='🌱 Configuração'!$C$51,'🌱 Configuração'!$B$51+5<'🌱 Configuração'!$D$51,INT(('🌱 Configuração'!$B$51+5-'🌱 Configuração'!$C$51)/7)+1=6,MOD('🌱 Configuração'!$B$51+5-'🌱 Configuração'!$C$51,7)=0),"🐛 Nim 2mL/L — ÚLTIMA foliar",IF(AND('🌱 Configuração'!$B$51+5>='🌱 Configuração'!$D$51,'🌱 Configuração'!$B$51+5<'🌱 Configuração'!$E$51,INT(('🌱 Configuração'!$B$51+5-'🌱 Configuração'!$D$51)/7)+1=1,MOD('🌱 Configuração'!$B$51+5-'🌱 Configuração'!$D$51,7)=0),"🐛 Beauveria bassiana solo (sem foliar)",IF(AND('🌱 Configuração'!$B$51+5>='🌱 Configuração'!$D$51,'🌱 Configuração'!$B$51+5<'🌱 Configuração'!$E$51,INT(('🌱 Configuração'!$B$51+5-'🌱 Configuração'!$D$51)/7)+1=2,MOD('🌱 Configuração'!$B$51+5-'🌱 Configuração'!$D$51,7)=0),"🐛 Trichoderma solo",IF(AND('🌱 Configuração'!$B$51+5>='🌱 Configuração'!$D$51,'🌱 Configuração'!$B$51+5<'🌱 Configuração'!$E$51,INT(('🌱 Configuração'!$B$51+5-'🌱 Configuração'!$D$51)/7)+1=3,MOD('🌱 Configuração'!$B$51+5-'🌱 Configuração'!$D$51,7)=0),"🐛 Beauveria bassiana solo",IF(AND('🌱 Configuração'!$B$51+5>='🌱 Configuração'!$D$51,'🌱 Configuração'!$B$51+5<'🌱 Configuração'!$E$51,INT(('🌱 Configuração'!$B$51+5-'🌱 Configuração'!$D$51)/7)+1=4,MOD('🌱 Configuração'!$B$51+5-'🌱 Configuração'!$D$51,7)=0),"🐛 Trichoderma solo",IF(AND('🌱 Configuração'!$B$51+5>='🌱 Configuração'!$E$51,INT(('🌱 Configuração'!$B$51+5-'🌱 Configuração'!$E$51)/7)+1=1,MOD('🌱 Configuração'!$B$51+5-'🌱 Configuração'!$E$51,7)=0),"🐛 Inspeção final — sem aplicação","")))))))))))))) | H11: =IF(6>'🌱 Configuração'!$F$50,"",IF('🌱 Configuração'!$B$51+5='🌱 Configuração'!$C$51,"🌿 INÍCIO VEGA — ajustar espaço, luz 18h/dia — EC 0.8",IF('🌱 Configuração'!$B$51+5='🌱 Configuração'!$D$51,"🌸 INÍCIO FLORAÇÃO — mudar para 12h/12h — 🔴 atenção ao fotoperíodo",IF('🌱 Configuração'!$B$51+5='🌱 Configuração'!$E$51,"🚿 INÍCIO FLUSH — PARAR nutrição, somente água pura",IF('🌱 Configuração'!$B$51+5='🌱 Configuração'!$F$51-1,"🔬 Véspera da colheita — analisar tricomas âmbar",IF('🌱 Configuração'!$B$51+5='🌱 Configuração'!$F$51,"✂️ COLHEITA! Parabéns! 🎉",""))))))
