Workbook

Sheet ⭐ Planilha Mestra
B2: ⭐ PLANILHA MESTRA DE CULTIVO — Versão Assinante
B3: Versão completa e exclusiva para assinantes da newsletter • Todos os direitos reservados
B5: ✅ O QUE ESTÁ INCLUSO NESTA VERSÃO
B6: 🌱 Configuração Inteligente | F6: Preencha apenas a Data Dia 1 — todas as datas se calculam automaticamente
B7: 📅 Cronograma Completo (125 dias) | F7: Calendário dia a dia com fase, adubação, MIP e ações — tudo com datas reais
B8: 💊 Protocolo de Adubação | F8: Doses por fase (Clone → Vega → Flora → Flush), EC alvo, pH alvo, suplementos
B9: 🐛 Calendário MIP Preventivo | F9: Calda Sulfocálcica, Calda Bordalesa, Nim, Beauveria, Trichoderma — com datas
B10: ⚠️ Tabela de Compatibilidade | F10: Regras de quais produtos podem ou não ser combinados — evite erros graves
B11: 📊 Diário de Cultivo | F11: 125 linhas para registro diário de temp, umidade, pH, CE com alertas automáticos
B12: 📖 Guia Rápido de Parâmetros | F12: Tabela de referência: temperatura, umidade, pH, EC, análise de tricomas
B14: 📌 COMO USAR: Vá para a aba 🌱 Configuração → preencha a Data Dia 1 (célula amarela) → tudo se calcula automaticamente!

Sheet 🌱 Configuração
B2: 🌿 PLANILHA MESTRA DE CULTIVO — Cannabis Medicinal Indoor
B3: Configure o Dia 1 do Clone abaixo. Todas as datas e recomendações serão calculadas automaticamente.
B5: ⚙️ CONFIGURAÇÕES DO CULTIVO
B6: 📅 Data Dia 1 (Clone) | G6: ⏱️ Duração Clone (dias) | I6: 14
B7: 🌿 Strain / Cultivar | G7: ⏱️ Duração Vega (dias) | I7: 42
B8: 💡 Ambiente | D8: Indoor LED | G8: ⏱️ Duração Flora (dias) | I8: 63
B9: 📐 Área (m²) | D9: 1.2 | G9: ⏱️ Flush (dias) | I9: 7
B10: 🔆 Luz na Vega (h) | D10: 18 | G10: ⏱️ TOTAL CULTIVO (dias) | I10: =I6+I7+I8+I9
B11: 🔆 Luz na Flora (h) | D11: 12
B12: 🪴 Nº de Plantas | D12: 4
B13: 🌡️ Temperatura (°C) | D13: 24
B14: 💧 Umidade Vega (%) | D14: 65
B15: 💧 Umidade Flora (%) | D15: 50
B17: 📆 CALENDÁRIO DE FASES (calculado automaticamente)
B18: Fase | D18: Início | F18: Fim | H18: Duração
B19: 🌱 CLONE | D19: =D6 | F19: =D6+I6-1 | H19: =I6&" dias"
B20: 🌿 VEGETATIVO | D20: =D6+I6 | F20: =D6+I6+I7-1 | H20: =I7&" dias"
B21: 🌸 FLORAÇÃO | D21: =D6+I6+I7 | F21: =D6+I6+I7+I8-1 | H21: =I8&" dias"
B22: 🚿 FLUSH | D22: =D6+I6+I7+I8 | F22: =D6+I6+I7+I8+I9-1 | H22: =I9&" dias"
B23: ✂️ COLHEITA | D23: =D6+I10 | F23: =D6+I10 | H23: "Dia da colheita"
B25: 📌 LEGENDA E INSTRUÇÕES
B26: 🟡 Célula amarela | D26: Campo de entrada — preencha com os dados do seu cultivo
B27: 🟢 Verde | D27: Fase Clone / início do ciclo
B28: 🔵 Azul | D28: Fase Vegetativa
B29: 🟣 Roxo | D29: Fase de Floração
B30: 🔴 Vermelho | D30: Flush (lavagem do substrato)
B31: 📋 Aba Cronograma | D31: Calendário diário completo — gerado após preencher a Data Dia 1
B32: 💊 Aba Adubação | D32: Protocolo de nutrição por fase com doses e produtos
B33: 🐛 Aba Pragas (MIP) | D33: Calendário de controle integrado de pragas preventivo
B34: 📊 Aba Diário | D34: Registro diário de parâmetros — temperatura, pH, CE, observações

Sheet 📅 Cronograma
B2: 📅 CRONOGRAMA COMPLETO DO CULTIVO
B3: Todas as datas são calculadas automaticamente a partir do Dia 1 configurado na aba Configuração
B5: Dia | C5: Data | D5: Fase | E5: Semana | F5: Adubação | G5: MIP / Pragas | H5: Ação Principal | I5: Observação / Alerta
B6: 1 | C6: ='🌱 Configuração'!D6+0 | D6: Clone | E6: Clone S1 | H6: ✂️ Receber clone — verificar raízes
B7: 2 | C7: ='🌱 Configuração'!D6+1 | D7: Clone | E7: Clone S1 | G7: 🐛 MIP: Nim (2mL/L) — preventivo foliar
B8: 3 | C8: ='🌱 Configuração'!D6+2 | D8: Clone | E8: Clone S1 | F8: 🌱 Enraizador (0.5 mL/L) | H8: 💧 1ª rega com enraizador
B9: 4 | C9: ='🌱 Configuração'!D6+3 | D9: Clone | E9: Clone S1
B10: 5 | C10: ='🌱 Configuração'!D6+4 | D10: Clone | E10: Clone S1
B11: 6 | C11: ='🌱 Configuração'!D6+5 | D11: Clone | E11: Clone S1
B12: 7 | C12: ='🌱 Configuração'!D6+6 | D12: Clone | E12: Clone S1 | F12: 🌱 Enraizador (0.5 mL/L) | H12: 🔍 Verificar pegamento do clone | I12: ⚠️ pH ideal: 5.8–6.2 (coco/hidro) | 6.0–6.8 (terra)
B13: 8 | C13: ='🌱 Configuração'!D6+7 | D13: Clone | E13: Clone S2
B14: 9 | C14: ='🌱 Configuração'!D6+8 | D14: Clone | E14: Clone S2 | G14: 🐛 MIP: Beauveria bassiana — preventivo
B15: 10 | C15: ='🌱 Configuração'!D6+9 | D15: Clone | E15: Clone S2
B16: 11 | C16: ='🌱 Configuração'!D6+10 | D16: Clone | E16: Clone S2
B17: 12 | C17: ='🌱 Configuração'!D6+11 | D17: Clone | E17: Clone S2 | F17: 🌱 Enraizador + Vitamina B1
B18: 13 | C18: ='🌱 Configuração'!D6+12 | D18: Clone | E18: Clone S2
B19: 14 | C19: ='🌱 Configuração'!D6+13 | D19: Clone | E19: Clone S2 | G19: 🐛 MIP: Nim (2mL/L) — fim clone | H19: 📐 Medir crescimento — avaliar vega | I19: ⚠️ Clone deve ter raízes visíveis
B20: 15 | C20: ='🌱 Configuração'!D6+14 | D20: Vegetativo | E20: Vega S1 | H20: 🔆 Iniciar Vega — aumentar espaço
B21: 16 | C21: ='🌱 Configuração'!D6+15 | D21: Vegetativo | E21: Vega S1 | F21: 🌿 Grow A+B — Início Vega (EC 0.8) | H21: 🌿 1ª adubação completa
B22: 17 | C22: ='🌱 Configuração'!D6+16 | D22: Vegetativo | E22: Vega S1
B23: 18 | C23: ='🌱 Configuração'!D6+17 | D23: Vegetativo | E23: Vega S1
B24: 19 | C24: ='🌱 Configuração'!D6+18 | D24: Vegetativo | E24: Vega S1
B25: 20 | C25: ='🌱 Configuração'!D6+19 | D25: Vegetativo | E25: Vega S1
B26: 21 | C26: ='🌱 Configuração'!D6+20 | D26: Vegetativo | E26: Vega S1 | F26: 🌿 Grow A+B — EC 1.0 | G26: 🐛 MIP: Beauveria bassiana | H26: ✂️ LST ou Topping (opcional) | I26: ⚠️ Monitorar pH e CE da solução
B27: 22 | C27: ='🌱 Configuração'!D6+21 | D27: Vegetativo | E27: Vega S2
B28: 23 | C28: ='🌱 Configuração'!D6+22 | D28: Vegetativo | E28: Vega S2
B29: 24 | C29: ='🌱 Configuração'!D6+23 | D29: Vegetativo | E29: Vega S2
B30: 25 | C30: ='🌱 Configuração'!D6+24 | D30: Vegetativo | E30: Vega S2 | F30: 🌿 Grow A+B + CalMag (EC 1.2)
B31: 26 | C31: ='🌱 Configuração'!D6+25 | D31: Vegetativo | E31: Vega S2
B32: 27 | C32: ='🌱 Configuração'!D6+26 | D32: Vegetativo | E32: Vega S2
B33: 28 | C33: ='🌱 Configuração'!D6+27 | D33: Vegetativo | E33: Vega S2 | F33: 🌿 Grow A+B + CalMag (EC 1.4) | G33: 🐛 MIP: Nim (2mL/L) foliar | H33: 📏 Avaliar altura e estrutura
B34: 29 | C34: ='🌱 Configuração'!D6+28 | D34: Vegetativo | E34: Vega S3
B35: 30 | C35: ='🌱 Configuração'!D6+29 | D35: Vegetativo | E35: Vega S3
B36: 31 | C36: ='🌱 Configuração'!D6+30 | D36: Vegetativo | E36: Vega S3
B37: 32 | C37: ='🌱 Configuração'!D6+31 | D37: Vegetativo | E37: Vega S3 | F37: 🌿 Grow A+B + Enzimas
B38: 33 | C38: ='🌱 Configuração'!D6+32 | D38: Vegetativo | E38: Vega S3
B39: 34 | C39: ='🌱 Configuração'!D6+33 | D39: Vegetativo | E39: Vega S3
B40: 35 | C40: ='🌱 Configuração'!D6+34 | D40: Vegetativo | E40: Vega S3 | F40: 🌿 Grow A+B + Biorrizas | G40: 🐛 MIP: Trichoderma — solo | H40: ✂️ Lollipopping se necessário | I40: ⚠️ Verificar sinais de deficiência
B41: 36 | C41: ='🌱 Configuração'!D6+35 | D41: Vegetativo | E41: Vega S4
B42: 37 | C42: ='🌱 Configuração'!D6+36 | D42: Vegetativo | E42: Vega S4
...

Sheet 💊 Adubação
B2: 💊 PROTOCOLO DE ADUBAÇÃO — Cannabis Medicinal Indoor
B3: Doses por litro de água. Sempre ajuste EC e pH após mistura. pH ideal: 5.8–6.2 (hidro/coco) | 6.0–6.8 (terra)
B5: 🌱 CLONE (Dia 1–14)
B6: Período | C6: Base N-P-K | D6: Dose | E6: CalMag | F6: PK Booster | G6: Estimulante | H6: Suplemento | I6: pH alvo | J6: EC alvo | K6: Observação
B7: Dia 1–3 | C7: Enraizador | D7: 0.5 mL/L | E7: - | F7: - | G7: - | H7: - | I7: 5.8–6.0 | J7: N/A | K7: Solo úmido
B8: Dia 4–7 | C8: Enraizador | D8: 0.5 mL/L | E8: - | F8: - | G8: - | H8: - | I8: 5.8–6.0 | J8: N/A | K8: Evitar encharcamento
B9: Dia 8–10 | C9: Enraizador + Vit B1 | D9: 0.5 mL/L | E9: 0.5 mL/L | F9: - | G9: - | H9: - | I9: 5.8–6.0 | J9: N/A | K9: B1 fortalece raízes
B10: Dia 11–14 | C10: Enraizador | D10: 0.5 mL/L | E10: - | F10: - | G10: - | H10: Biorrizas | I10: 6.0 | J10: 0.4 | K10: Avaliar pegamento
B12: 🌿 VEGETATIVO (Dia 15–56)
B13: Período | C13: Base N-P-K | D13: Dose | E13: CalMag | F13: PK Booster | G13: Estimulante | H13: Suplemento | I13: pH alvo | J13: EC alvo | K13: Observação
B14: S1 (D15–21) | C14: Grow A+B | D14: 1 mL/L | E14: CalMag 0.5mL | F14: - | G14: - | H14: - | I14: 6.0 | J14: 0.8 | K14: Início suave
B15: S2 (D22–28) | C15: Grow A+B | D15: 2 mL/L | E15: CalMag 1mL | F15: - | G15: - | H15: Enzimas | I15: 6.1 | J15: 1.0 | K15: Monitorar CE
B16: S3 (D29–35) | C16: Grow A+B | D16: 3 mL/L | E16: CalMag 1mL | F16: - | G16: - | H16: Biorrizas | I16: 6.1 | J16: 1.2 | K16: LST/Topping
B17: S4 (D36–42) | C17: Grow A+B | D17: 3 mL/L | E17: CalMag 1.5mL | F17: - | G17: - | H17: Enzimas | I17: 6.2 | J17: 1.4 | K17: Estrutura boa
B18: S5 (D43–49) | C18: Grow A+B | D18: 3 mL/L | E18: CalMag 1.5mL | F18: - | G18: - | H18: - | I18: 6.2 | J18: 1.5 | K18: Pré-transição
B19: S6 (D50–56) | C19: Bloom A+B | D19: 1 mL/L | E19: CalMag 1mL | F19: PK 0.5mL | G19: - | H19: - | I19: 6.0 | J19: 1.4 | K19: Transição 12/12
B21: 🌸 FLORAÇÃO (Dia 57–119)
B22: Período | C22: Base N-P-K | D22: Dose | E22: CalMag | F22: PK Booster | G22: Estimulante | H22: Suplemento | I22: pH alvo | J22: EC alvo | K22: Observação
B23: S1 (D57–63) | C23: Bloom A+B | D23: 3 mL/L | E23: CalMag 1mL | F23: - | G23: Boost 0.5 | H23: - | I23: 6.0 | J23: 1.6 | K23: Formação pistils
B24: S2 (D64–70) | C24: Bloom A+B | D24: 3 mL/L | E24: CalMag 1mL | F24: PK 0.5mL | G24: Boost 1mL | H24: - | I24: 6.0 | J24: 1.7 | K24: Enchimento inicia
B25: S3 (D71–77) | C25: Bloom A+B | D25: 4 mL/L | E25: CalMag 1mL | F25: PK 1mL | G25: Boost 1mL | H25: Amino | I25: 6.1 | J25: 1.8 | K25: Pico de PK
B26: S4 (D78–84) | C26: Bloom A+B | D26: 4 mL/L | E26: CalMag 1mL | F26: PK 1.5mL | G26: Boost 1mL | H26: Amino | I26: 6.1 | J26: 2.0 | K26: Máximo enchimento
B27: S5 (D85–91) | C27: Bloom A+B | D27: 3 mL/L | E27: CalMag 0.5 | F27: PK 1mL | G27: Boost 1mL | H27: Enzimas | I27: 6.1 | J27: 1.8 | K27: Analisar tricomas
B28: S6 (D92–98) | C28: Bloom A+B | D28: 3 mL/L | E28: - | F28: - | G28: Boost 0.5 | H28: Enzimas | I28: 6.0 | J28: 1.6 | K28: Reduzir nutrição
B29: S7 (D99–105) | C29: Bloom A+B | D29: 2 mL/L | E29: - | F29: - | G29: - | H29: - | I29: 6.0 | J29: 1.4 | K29: Pré-flush
B30: S8 (D106–112) | C30: Bloom A+B | D30: 1 mL/L | E30: - | F30: - | G30: - | H30: Enzimas | I30: 6.0 | J30: 0.8 | K30: Últimos nutrientes
B32: 🚿 FLUSH (Dia 113–119)
B33: Período | C33: Base N-P-K | D33: Dose | E33: CalMag | F33: PK Booster | G33: Estimulante | H33: Suplemento | I33: pH alvo | J33: EC alvo | K33: Observação
B34: D113–116 | C34: Água pura | D34: - | E34: - | F34: - | G34: - | H34: Enzimas 1mL | I34: 6.0 | J34: <0.3 | K34: Lavar substrato
B35: D117–119 | C35: Água pura | D35: - | E35: - | F35: - | G35: - | H35: - | I35: 6.0 | J35: <0.2 | K35: Tricomas âmbar?

Sheet 🐛 MIP — Pragas
B2: 🐛 MIP — CONTROLE INTEGRADO DE PRAGAS (Preventivo)
B3: Protocolo preventivo — Nunca aplicar foliar em floração avançada (após semana 3 de flora)
B5: 🛡️ PRODUTOS RECOMENDADOS — Biológicos e Orgânicos
B6: Produto | C6: Dose | D6: Aplicação | E6: Alvo / Ação | F6: Frequência | G6: Observação
B7: 🌿 Óleo de Nim (Neem Oil) | C7: 2–3 mL/L água | D7: Foliar (clone/vega) | Solo (flora) | E7: Acaricida, inseticida, fungicida | F7: A cada 7 dias preventivo | G7: ⚠️ NÃO usar em flora avançada
B8: 🍄 Beauveria bassiana | C8: 5–10 g/L | D8: Foliar e solo | E8: Fungo entomopatogênico — tripes, mosca branca | F8: A cada 14 dias | G8: Refrigerar após abrir
B9: 🦠 Trichoderma harzianum | C9: 2–5 g/L | D9: Solo / substrato | E9: Fungos do solo, Pythium, Fusarium | F9: A cada 21 dias no solo | G9: Aplicar ao regar
B10: 🌱 Extrato de Alho | C10: 3 mL/L | D10: Foliar | E10: Repelente geral, ácaros, pulgões | F10: A cada 10 dias (vega) | G10: Pode combinar com nim
B11: 🐞 Bacillus thuringiensis | C11: 5 mL/L | D11: Foliar | E11: Lagartas, moscas fungosas | F11: Quando detectar larvas | G11: Bioinseticida seletivo
B12: 🔬 Extrato de Quassia | C12: 3 mL/L | D12: Foliar | E12: Pulgões, mosca branca, tripes | F12: A cada 10 dias | G12: Combina bem com nim
B13: 🟡 Calda Sulfocálcica | C13: Brix 20–30° diluído 1–3% (10–30 mL/L) | D13: Foliar (clone/vega) Solo preventivo | E13: Acaricida, fungicida Ácaros, oídio, escamas | F13: A cada 14–21 dias ⚠️ NÃO em floração | G13: ⚠️ Não misturar com óleos. Aplicar ao entardecer.
B14: 🔵 Calda Bordalesa
B16: 📅 CALENDÁRIO DE APLICAÇÕES PREVENTIVAS
B17: Dia | C17: Data | D17: Fase | E17: Produto | F17: Dose | G17: Via de Aplicação | H17: Observação
B18: 2 | C18: ='🌱 Configuração'!D6+1 | D18: Clone | E18: Nim | F18: 2 mL/L | G18: Foliar leve | H18: Preventivo geral — cuidado nas folhas
B19: 7 | C19: ='🌱 Configuração'!D6+6 | D19: Clone | E19: Beauveria bassiana | F19: 5 g/L | G19: Foliar + solo | H19: Fungo entomopatogênico
B20: 10 | C20: ='🌱 Configuração'!D6+9 | D20: Clone | E20: Extrato de Alho | F20: 3 mL/L | G20: Foliar | H20: Repelente preventivo
B21: 14 | C21: ='🌱 Configuração'!D6+13 | D21: Clone | E21: Nim | F21: 2 mL/L | G21: Foliar | H21: Última foliar pré-vega
B22: 21 | C22: ='🌱 Configuração'!D6+20 | D22: Vegetativo | E22: Beauveria bassiana | F22: 5 g/L | G22: Foliar + solo
B23: 28 | C23: ='🌱 Configuração'!D6+27 | D23: Vegetativo | E23: Nim + Alho | F23: 2+3mL/L | G23: Foliar | H23: Combinação eficiente
B24: 35 | C24: ='🌱 Configuração'!D6+34 | D24: Vegetativo | E24: Trichoderma | F24: 3 g/L | G24: Solo (rega) | H24: Solo saudável = planta forte
B25: 42 | C25: ='🌱 Configuração'!D6+41 | D25: Vegetativo | E25: Nim | F25: 2 mL/L | G25: Foliar | H25: ⚠️ ÚLTIMA FOLIAR com Nim
B26: 49 | C26: ='🌱 Configuração'!D6+48 | D26: Floração | E26: Beauveria bassiana | F26: 5 g/L | G26: Solo apenas | H26: ⚠️ SEM FOLIAR em floração
B27: 56 | C27: ='🌱 Configuração'!D6+55 | D27: Floração | E27: Trichoderma | F27: 3 g/L | G27: Solo (rega)
B28: 63 | C28: ='🌱 Configuração'!D6+62 | D28: Floração | E28: B. thuringiensis | F28: 5 mL/L | G28: Solo apenas | H28: Controle larvas solo
B29: 70 | C29: ='🌱 Configuração'!D6+69 | D29: Floração | E29: Beauveria bassiana | F29: 5 g/L | G29: Solo apenas | H29: Inspecionar buds visualmente
B30: 77 | C30: ='🌱 Configuração'!D6+76 | D30: Floração | E30: Trichoderma | F30: 3 g/L | G30: Solo (rega)
B31: 84 | C31: ='🌱 Configuração'!D6+83 | D31: Floração | E31: Inspeção visual | F31: - | G31: Inspecionar tudo | H31: ⚠️ Verificar mofo branco/cinza
B32: 91 | C32: ='🌱 Configuração'!D6+90 | D32: Floração | E32: Inspeção final | F32: - | G32: Inspecionar buds | H32: ⚠️ Tricomas — avaliar colheita
B37: 14 | C37: ='🌱 Configuração'!D6+13 | D37: Clone | E37: Calda Sulfocálcica | F37: 1% (10 mL/L) | G37: Foliar preventivo | H37: ⚠️ Preventivo ácaros — aplicar ao entardecer
B38: 28 | C38: ='🌱 Configuração'!D6+27 | D38: Vegetativo | E38: Calda Bordalesa | F38: 0.5% (5 mL/L) | G38: Foliar preventivo | H38: ⚠️ Preventivo fungos — não combinar com nim
B39: 35 | C39: ='🌱 Configuração'!D6+34 | D39: Vegetativo | E39: Calda Sulfocálcica | F39: 1% (10 mL/L) | G39: Foliar | H39: Ácaros — verificar face inferior das folhas
B40: 42 | C40: ='🌱 Configuração'!D6+41 | D40: Vegetativo | E40: Calda Bordalesa | F40: 0.5% (5 mL/L) | G40: Foliar | H40: ⚠️ ÚLTIMA foliar antes da floração
B42: ⚠️ COMPATIBILIDADE — Calda Sulfocálcica e Calda Bordalesa
B43: Regra | D43: Detalhe / Explicação
B44: ❌ Não misturar | D44: Calda Sulfocálcica + Calda Bordalesa — nunca na mesma semana
B45: ❌ Não misturar | D45: Calda Sulfocálcica + Óleo de Nim — fitotoxidade grave
B46: ❌ Nunca foliar | D46: Ambas as caldas em floração — risco de contaminar buds e alterar sabor
B47: ⏱️ Intervalo mínimo | D47: 7–10 dias entre Calda Sulfocálcica e qualquer outro foliar
B48: 🌡️ Temperatura | D48: Não aplicar Sulfocálcica com temp. > 30°C — risco de queima foliar
...

Sheet 📊 Diário
B2: 📊 DIÁRIO DE CULTIVO — Registro Diário de Parâmetros
B3: Registre diariamente os parâmetros do cultivo. Os alertas em vermelho indicam valores fora do ideal.
B5: Dia | C5: Data | D5: Fase | E5: Temp (°C) | F5: Umidade (%) | G5: pH água | H5: CE (mS/cm) | I5: pH run-off | J5: Rega (L) | K5: Observações | L5: Alertas / Status
B6: 1 | C6: ='🌱 Configuração'!D6+0 | D6: Clone | L6: =IF(AND(F6<>"",F6<22),"⚠️ Temp baixa",IF(AND(F6<>"",F6>28),"⚠️ Temp alta",IF(AND(H6<>"",H6<5.5),"⚠️ pH baixo",IF(AND(H6<>"",H6>6.8),"⚠️ pH alto","✅ OK"))))
B7: 2 | C7: ='🌱 Configuração'!D6+1 | D7: Clone | L7: =IF(AND(F7<>"",F7<22),"⚠️ Temp baixa",IF(AND(F7<>"",F7>28),"⚠️ Temp alta",IF(AND(H7<>"",H7<5.5),"⚠️ pH baixo",IF(AND(H7<>"",H7>6.8),"⚠️ pH alto","✅ OK"))))
B8: 3 | C8: ='🌱 Configuração'!D6+2 | D8: Clone | L8: =IF(AND(F8<>"",F8<22),"⚠️ Temp baixa",IF(AND(F8<>"",F8>28),"⚠️ Temp alta",IF(AND(H8<>"",H8<5.5),"⚠️ pH baixo",IF(AND(H8<>"",H8>6.8),"⚠️ pH alto","✅ OK"))))
B9: 4 | C9: ='🌱 Configuração'!D6+3 | D9: Clone | L9: =IF(AND(F9<>"",F9<22),"⚠️ Temp baixa",IF(AND(F9<>"",F9>28),"⚠️ Temp alta",IF(AND(H9<>"",H9<5.5),"⚠️ pH baixo",IF(AND(H9<>"",H9>6.8),"⚠️ pH alto","✅ OK"))))
B10: 5 | C10: ='🌱 Configuração'!D6+4 | D10: Clone | L10: =IF(AND(F10<>"",F10<22),"⚠️ Temp baixa",IF(AND(F10<>"",F10>28),"⚠️ Temp alta",IF(AND(H10<>"",H10<5.5),"⚠️ pH baixo",IF(AND(H10<>"",H10>6.8),"⚠️ pH alto","✅ OK"))))
B11: 6 | C11: ='🌱 Configuração'!D6+5 | D11: Clone | L11: =IF(AND(F11<>"",F11<22),"⚠️ Temp baixa",IF(AND(F11<>"",F11>28),"⚠️ Temp alta",IF(AND(H11<>"",H11<5.5),"⚠️ pH baixo",IF(AND(H11<>"",H11>6.8),"⚠️ pH alto","✅ OK"))))
B12: 7 | C12: ='🌱 Configuração'!D6+6 | D12: Clone | L12: =IF(AND(F12<>"",F12<22),"⚠️ Temp baixa",IF(AND(F12<>"",F12>28),"⚠️ Temp alta",IF(AND(H12<>"",H12<5.5),"⚠️ pH baixo",IF(AND(H12<>"",H12>6.8),"⚠️ pH alto","✅ OK"))))
B13: 8 | C13: ='🌱 Configuração'!D6+7 | D13: Clone | L13: =IF(AND(F13<>"",F13<22),"⚠️ Temp baixa",IF(AND(F13<>"",F13>28),"⚠️ Temp alta",IF(AND(H13<>"",H13<5.5),"⚠️ pH baixo",IF(AND(H13<>"",H13>6.8),"⚠️ pH alto","✅ OK"))))
B14: 9 | C14: ='🌱 Configuração'!D6+8 | D14: Clone | L14: =IF(AND(F14<>"",F14<22),"⚠️ Temp baixa",IF(AND(F14<>"",F14>28),"⚠️ Temp alta",IF(AND(H14<>"",H14<5.5),"⚠️ pH baixo",IF(AND(H14<>"",H14>6.8),"⚠️ pH alto","✅ OK"))))
B15: 10 | C15: ='🌱 Configuração'!D6+9 | D15: Clone | L15: =IF(AND(F15<>"",F15<22),"⚠️ Temp baixa",IF(AND(F15<>"",F15>28),"⚠️ Temp alta",IF(AND(H15<>"",H15<5.5),"⚠️ pH baixo",IF(AND(H15<>"",H15>6.8),"⚠️ pH alto","✅ OK"))))
B16: 11 | C16: ='🌱 Configuração'!D6+10 | D16: Clone | L16: =IF(AND(F16<>"",F16<22),"⚠️ Temp baixa",IF(AND(F16<>"",F16>28),"⚠️ Temp alta",IF(AND(H16<>"",H16<5.5),"⚠️ pH baixo",IF(AND(H16<>"",H16>6.8),"⚠️ pH alto","✅ OK"))))
B17: 12 | C17: ='🌱 Configuração'!D6+11 | D17: Clone | L17: =IF(AND(F17<>"",F17<22),"⚠️ Temp baixa",IF(AND(F17<>"",F17>28),"⚠️ Temp alta",IF(AND(H17<>"",H17<5.5),"⚠️ pH baixo",IF(AND(H17<>"",H17>6.8),"⚠️ pH alto","✅ OK"))))
B18: 13 | C18: ='🌱 Configuração'!D6+12 | D18: Clone | L18: =IF(AND(F18<>"",F18<22),"⚠️ Temp baixa",IF(AND(F18<>"",F18>28),"⚠️ Temp alta",IF(AND(H18<>"",H18<5.5),"⚠️ pH baixo",IF(AND(H18<>"",H18>6.8),"⚠️ pH alto","✅ OK"))))
B19: 14 | C19: ='🌱 Configuração'!D6+13 | D19: Clone | L19: =IF(AND(F19<>"",F19<22),"⚠️ Temp baixa",IF(AND(F19<>"",F19>28),"⚠️ Temp alta",IF(AND(H19<>"",H19<5.5),"⚠️ pH baixo",IF(AND(H19<>"",H19>6.8),"⚠️ pH alto","✅ OK"))))
B20: 15 | C20: ='🌱 Configuração'!D6+14 | D20: Vegetativo | L20: =IF(AND(F20<>"",F20<22),"⚠️ Temp baixa",IF(AND(F20<>"",F20>28),"⚠️ Temp alta",IF(AND(H20<>"",H20<5.5),"⚠️ pH baixo",IF(AND(H20<>"",H20>6.8),"⚠️ pH alto","✅ OK"))))
B21: 16 | C21: ='🌱 Configuração'!D6+15 | D21: Vegetativo | L21: =IF(AND(F21<>"",F21<22),"⚠️ Temp baixa",IF(AND(F21<>"",F21>28),"⚠️ Temp alta",IF(AND(H21<>"",H21<5.5),"⚠️ pH baixo",IF(AND(H21<>"",H21>6.8),"⚠️ pH alto","✅ OK"))))
B22: 17 | C22: ='🌱 Configuração'!D6+16 | D22: Vegetativo | L22: =IF(AND(F22<>"",F22<22),"⚠️ Temp baixa",IF(AND(F22<>"",F22>28),"⚠️ Temp alta",IF(AND(H22<>"",H22<5.5),"⚠️ pH baixo",IF(AND(H22<>"",H22>6.8),"⚠️ pH alto","✅ OK"))))
B23: 18 | C23: ='🌱 Configuração'!D6+17 | D23: Vegetativo | L23: =IF(AND(F23<>"",F23<22),"⚠️ Temp baixa",IF(AND(F23<>"",F23>28),"⚠️ Temp alta",IF(AND(H23<>"",H23<5.5),"⚠️ pH baixo",IF(AND(H23<>"",H23>6.8),"⚠️ pH alto","✅ OK"))))
B24: 19 | C24: ='🌱 Configuração'!D6+18 | D24: Vegetativo | L24: =IF(AND(F24<>"",F24<22),"⚠️ Temp baixa",IF(AND(F24<>"",F24>28),"⚠️ Temp alta",IF(AND(H24<>"",H24<5.5),"⚠️ pH baixo",IF(AND(H24<>"",H24>6.8),"⚠️ pH alto","✅ OK"))))
B25: 20 | C25: ='🌱 Configuração'!D6+19 | D25: Vegetativo | L25: =IF(AND(F25<>"",F25<22),"⚠️ Temp baixa",IF(AND(F25<>"",F25>28),"⚠️ Temp alta",IF(AND(H25<>"",H25<5.5),"⚠️ pH baixo",IF(AND(H25<>"",H25>6.8),"⚠️ pH alto","✅ OK"))))
B26: 21 | C26: ='🌱 Configuração'!D6+20 | D26: Vegetativo | L26: =IF(AND(F26<>"",F26<22),"⚠️ Temp baixa",IF(AND(F26<>"",F26>28),"⚠️ Temp alta",IF(AND(H26<>"",H26<5.5),"⚠️ pH baixo",IF(AND(H26<>"",H26>6.8),"⚠️ pH alto","✅ OK"))))
B27: 22 | C27: ='🌱 Configuração'!D6+21 | D27: Vegetativo | L27: =IF(AND(F27<>"",F27<22),"⚠️ Temp baixa",IF(AND(F27<>"",F27>28),"⚠️ Temp alta",IF(AND(H27<>"",H27<5.5),"⚠️ pH baixo",IF(AND(H27<>"",H27>6.8),"⚠️ pH alto","✅ OK"))))
B28: 23 | C28: ='🌱 Configuração'!D6+22 | D28: Vegetativo | L28: =IF(AND(F28<>"",F28<22),"⚠️ Temp baixa",IF(AND(F28<>"",F28>28),"⚠️ Temp alta",IF(AND(H28<>"",H28<5.5),"⚠️ pH baixo",IF(AND(H28<>"",H28>6.8),"⚠️ pH alto","✅ OK"))))
B29: 24 | C29: ='🌱 Configuração'!D6+23 | D29: Vegetativo | L29: =IF(AND(F29<>"",F29<22),"⚠️ Temp baixa",IF(AND(F29<>"",F29>28),"⚠️ Temp alta",IF(AND(H29<>"",H29<5.5),"⚠️ pH baixo",IF(AND(H29<>"",H29>6.8),"⚠️ pH alto","✅ OK"))))
B30: 25 | C30: ='🌱 Configuração'!D6+24 | D30: Vegetativo | L30: =IF(AND(F30<>"",F30<22),"⚠️ Temp baixa",IF(AND(F30<>"",F30>28),"⚠️ Temp alta",IF(AND(H30<>"",H30<5.5),"⚠️ pH baixo",IF(AND(H30<>"",H30>6.8),"⚠️ pH alto","✅ OK"))))
B31: 26 | C31: ='🌱 Configuração'!D6+25 | D31: Vegetativo | L31: =IF(AND(F31<>"",F31<22),"⚠️ Temp baixa",IF(AND(F31<>"",F31>28),"⚠️ Temp alta",IF(AND(H31<>"",H31<5.5),"⚠️ pH baixo",IF(AND(H31<>"",H31>6.8),"⚠️ pH alto","✅ OK"))))
B32: 27 | C32: ='🌱 Configuração'!D6+26 | D32: Vegetativo | L32: =IF(AND(F32<>"",F32<22),"⚠️ Temp baixa",IF(AND(F32<>"",F32>28),"⚠️ Temp alta",IF(AND(H32<>"",H32<5.5),"⚠️ pH baixo",IF(AND(H32<>"",H32>6.8),"⚠️ pH alto","✅ OK"))))
B33: 28 | C33: ='🌱 Configuração'!D6+27 | D33: Vegetativo | L33: =IF(AND(F33<>"",F33<22),"⚠️ Temp baixa",IF(AND(F33<>"",F33>28),"⚠️ Temp alta",IF(AND(H33<>"",H33<5.5),"⚠️ pH baixo",IF(AND(H33<>"",H33>6.8),"⚠️ pH alto","✅ OK"))))
B34: 29 | C34: ='🌱 Configuração'!D6+28 | D34: Vegetativo | L34: =IF(AND(F34<>"",F34<22),"⚠️ Temp baixa",IF(AND(F34<>"",F34>28),"⚠️ Temp alta",IF(AND(H34<>"",H34<5.5),"⚠️ pH baixo",IF(AND(H34<>"",H34>6.8),"⚠️ pH alto","✅ OK"))))
B35: 30 | C35: ='🌱 Configuração'!D6+29 | D35: Vegetativo | L35: =IF(AND(F35<>"",F35<22),"⚠️ Temp baixa",IF(AND(F35<>"",F35>28),"⚠️ Temp alta",IF(AND(H35<>"",H35<5.5),"⚠️ pH baixo",IF(AND(H35<>"",H35>6.8),"⚠️ pH alto","✅ OK"))))
B36: 31 | C36: ='🌱 Configuração'!D6+30 | D36: Vegetativo | L36: =IF(AND(F36<>"",F36<22),"⚠️ Temp baixa",IF(AND(F36<>"",F36>28),"⚠️ Temp alta",IF(AND(H36<>"",H36<5.5),"⚠️ pH baixo",IF(AND(H36<>"",H36>6.8),"⚠️ pH alto","✅ OK"))))
B37: 32 | C37: ='🌱 Configuração'!D6+31 | D37: Vegetativo | L37: =IF(AND(F37<>"",F37<22),"⚠️ Temp baixa",IF(AND(F37<>"",F37>28),"⚠️ Temp alta",IF(AND(H37<>"",H37<5.5),"⚠️ pH baixo",IF(AND(H37<>"",H37>6.8),"⚠️ pH alto","✅ OK"))))
B38: 33 | C38: ='🌱 Configuração'!D6+32 | D38: Vegetativo | L38: =IF(AND(F38<>"",F38<22),"⚠️ Temp baixa",IF(AND(F38<>"",F38>28),"⚠️ Temp alta",IF(AND(H38<>"",H38<5.5),"⚠️ pH baixo",IF(AND(H38<>"",H38>6.8),"⚠️ pH alto","✅ OK"))))
B39: 34 | C39: ='🌱 Configuração'!D6+33 | D39: Vegetativo | L39: =IF(AND(F39<>"",F39<22),"⚠️ Temp baixa",IF(AND(F39<>"",F39>28),"⚠️ Temp alta",IF(AND(H39<>"",H39<5.5),"⚠️ pH baixo",IF(AND(H39<>"",H39>6.8),"⚠️ pH alto","✅ OK"))))
B40: 35 | C40: ='🌱 Configuração'!D6+34 | D40: Vegetativo | L40: =IF(AND(F40<>"",F40<22),"⚠️ Temp baixa",IF(AND(F40<>"",F40>28),"⚠️ Temp alta",IF(AND(H40<>"",H40<5.5),"⚠️ pH baixo",IF(AND(H40<>"",H40>6.8),"⚠️ pH alto","✅ OK"))))
B41: 36 | C41: ='🌱 Configuração'!D6+35 | D41: Vegetativo | L41: =IF(AND(F41<>"",F41<22),"⚠️ Temp baixa",IF(AND(F41<>"",F41>28),"⚠️ Temp alta",IF(AND(H41<>"",H41<5.5),"⚠️ pH baixo",IF(AND(H41<>"",H41>6.8),"⚠️ pH alto","✅ OK"))))
B42: 37 | C42: ='🌱 Configuração'!D6+36 | D42: Vegetativo | L42: =IF(AND(F42<>"",F42<22),"⚠️ Temp baixa",IF(AND(F42<>"",F42>28),"⚠️ Temp alta",IF(AND(H42<>"",H42<5.5),"⚠️ pH baixo",IF(AND(H42<>"",H42>6.8),"⚠️ pH alto","✅ OK"))))
...

Sheet 📖 Guia Rápido
B2: 📖 GUIA RÁPIDO — Parâmetros e Referências
B4: 🌡️ TEMPERATURA
B5: Parâmetro | C5: Valor / Faixa Ideal
B6: Dia (luz acesa) | C6: 22–26°C (ideal 24°C)
B7: Noite (luz apagada) | C7: 18–22°C
B8: Máximo tolerável | C8: 30°C (acima: estresse)
B9: Clone — temperatura | C9: 23–26°C (sem variação)
B11: 💧 UMIDADE RELATIVA
B12: Parâmetro | C12: Valor / Faixa Ideal
B13: Clone | C13: 70–80%
B14: Vegetativo | C14: 55–70%
B15: Floração S1–S4 | C15: 40–55%
B16: Floração S5+ | C16: 35–45% (risco de mofo)
B17: Flush / final | C17: < 40%
B19: ⚗️ pH DA ÁGUA
B20: Parâmetro | C20: Valor / Faixa Ideal
B21: Terra / mix orgânico | C21: 6.0–6.8
B22: Coco coir | C22: 5.8–6.2
B23: Hidroponia | C23: 5.5–6.1
B24: Run-off ideal | C24: ± 0.2 do pH de entrada
B26: 📊 CONDUTIVIDADE (EC)
B27: Parâmetro | C27: Valor / Faixa Ideal
B28: Clone | C28: 0.0–0.4 mS/cm
B29: Vegetativo inicial | C29: 0.8–1.2 mS/cm
B30: Vegetativo pleno | C30: 1.2–1.6 mS/cm
B31: Floração inicial | C31: 1.4–1.8 mS/cm
B32: Floração pico | C32: 1.8–2.2 mS/cm
B33: Flush | C33: < 0.3 mS/cm
B35: 🔬 ANÁLISE DE TRICOMAS
B36: Parâmetro | C36: Valor / Faixa Ideal
B37: Transparentes | C37: Imaturos — não colher
B38: Leitosos / opacos | C38: Efeito mais cerebral/alto
B39: Âmbar 10–20% | C39: Efeito equilibrado (ideal médico)
B40: Âmbar 30–50% | C40: Efeito mais sedativo/corporal
B41: Âmbar > 50% | C41: Degradação de THC → CBN
B43: 💡 FOTOPERÍODO
B44: Parâmetro | C44: Valor / Faixa Ideal
B45: Propagação/Clone | C45: 18h luz / 6h escuro (ou 24h)
B46: Vegetativo | C46: 18h luz / 6h escuro
B47: Indução de floração | C47: 12h luz / 12h escuro
...
