Workbook

Sheet 🌱 Configuração
B2: 🌿 PLANILHA MESTRA DE CULTIVO — Cannabis Medicinal Indoor v3
B3: Configure abaixo. Toda a planilha se recalcula automaticamente.
B5: ⚙️ CONFIGURAÇÕES GERAIS
B6: 📅 Data Dia 1 (Clone) | F6: 🌱 Semanas de Clone | H6: 2 | J6: ← semanas
B7: 🌿 Strain / Cultivar | D7: Ex: OG Kush | F7: 🌿 Semanas de Vegetativo | H7: 6 | J7: ← semanas
B8: 💡 Ambiente | D8: Indoor LED | F8: 🌸 Semanas de Floração | H8: 9 | J8: ← semanas
B9: 📐 Área (m²) | D9: 1.2 | F9: 🚿 Semanas de Flush | H9: 1 | J9: ← semanas
B10: 🪴 Nº de Plantas | D10: 4
B11: 💊 PROTOCOLO DE NUTRIÇÃO — Escolha sua linha de produtos
B12: 🧪 Linha de Adubação | H12: BioBizz | J12: ← Escolha no dropdown
B13: BioBizz | D13: Orgânico certificado (Holanda). Solo. Produtos: Bio·Grow, Bio·Bloom, Top·Max, Fish·Mix, Root Juice, Alg·A·Mic. pH: 6.2–6.5
B14: Remo Nutrients | D14: Mineral/orgânico (Canadá). Solo, coco, hidro. Produtos: Micro, Grow, Bloom, Magnifical, Astroflower, Kelp, Roots. pH: 5.8–6.3
B15: General Organics | D15: GO Box da GH (EUA). Solo orgânico. Produtos: BioThrive Grow/Bloom, BioRoot, BioBud, BioWeed, CaMg+, BioMarine. pH: auto
B16: SuperSoil | D16: Solo vivo preparado. Coberturas secas: farinha de osso, torta de mamona, guano de morcego, farinha de alga, cinzas. pH: auto
B17: Genérico | D17: Campos em branco para você preencher com seus próprios produtos e doses. Totalmente personalizável.
B19: 📆 CALENDÁRIO DE FASES (automático)
B20: Fase | D20: Semanas | F20: Início | H20: Fim | J20: Total dias
B21: 🌱 CLONE | D21: =H6&" sem" -> 2 sem | F21: =B56 -> 0 | H21: =B56+B55-1 -> 13 | J21: =B55 -> 14
B22: 🌿 VEGETATIVO | D22: =H7&" sem" -> 6 sem | F22: =C56 -> 14 | H22: =C56+C55-1 -> 55 | J22: =C55 -> 42
B23: 🌸 FLORAÇÃO | D23: =H8&" sem" -> 9 sem | F23: =D56 -> 56 | H23: =D56+D55-1 -> 118 | J23: =D55 -> 63
B24: 🚿 FLUSH | D24: =H9&" sem" -> 1 sem | F24: =E56 -> 119 | H24: =E56+E55-1 -> 125 | J24: =E55 -> 7
B25: ✂️ COLHEITA | D25: "—" | F25: =F56 -> 126 | H25: =F56 -> 126 | J25: "1 dia"
B55: =H6*7 -> 14 | C55: =H7*7 -> 42 | D55: =H8*7 -> 63 | E55: =H9*7 -> 7 | F55: =B55+C55+D55+E55 -> 126
B56: =D6 -> 0 | C56: =B56+B55 -> 14 | D56: =C56+C55 -> 56 | E56: =D56+D55 -> 119 | F56: =E56+E55 -> 126

Sheet 💊 Adubação
B2: 💊 PROTOCOLO DE ADUBAÇÃO — Personalizado conforme linha escolhida na Configuração
B3: Protocolo ativo: veja célula H12 na aba Configuração | Altere lá para mudar todos os produtos e doses
B5: 🌱 CLONE
B6: Semana | C6: Data início | D6: Produto 1 | E6: Dose 1 | F6: Produto 2 | G6: Dose 2 | H6: Produto 3 | I6: Dose 3 | J6: Suplemento | K6: pH alvo | L6: EC alvo | M6: Observação
B7: =IF(1<='🌱 Configuração'!$H$6,"S1","—") -> S1 | C7: =IF(1<='🌱 Configuração'!$H$6,'🌱 Configuração'!$B$56+0,"") -> 0 | D7: =IF('🌱 Configuração'!$B$56="","",IF(1<1,"",IF(1>'🌱 Configuração'!$H$6,"",IF(IFERROR(MATCH('🌱 Configuração'!$H$12,{"BioBizz","Remo Nutrients","General Organics","SuperSoil","Genérico"},0),1)=1,IF(1=1,"Root Juice",IF(1=2,"Root Juice",IF(1=3,"Root Juice",IF(1=4,"Root Juice","")))),IF(IFERROR(MATCH('🌱 Configuração'!$H$12,{"BioBizz","Remo Nutrients","General Organics","SuperSoil","Genérico"},0),1)=2,IF(1=1,"Remo Roots",IF(1=2,"Remo Roots",IF(1=3,"Remo Roots",IF(1=4,"Remo Roots","")))),IF(IFERROR(MATCH('🌱 Configuração'!$H$12,{"BioBizz","Remo Nutrients","General Organics","SuperSoil","Genérico"},0),1)=3,IF(1=1,"BioRoot",IF(1=2,"BioRoot",IF(1=3,"BioRoot",IF(1=4,"BioRoot","")))),IF(IFERROR(MATCH('🌱 Configuração'!$H$12,{"BioBizz","Remo Nutrients","General Organics","SuperSoil","Genérico"},0),1)=4,IF(1=1,"Chá de compostagem",IF(1=2,"Chá de compostagem",IF(1=3,"Cobertura: farinha de alga",IF(1=4,"Molasses 2 mL/L","")))),IF(1=1,"← Preencha",IF(1=2,"← Preencha",IF(1=3,"← Preencha",IF(1=4,"← Preencha",""))))))))))) | E7: =IF('🌱 Configuração'!$B$56="","",IF(1<1,"",IF(1>'🌱 Configuração'!$H$6,"",IF(IFERROR(MATCH('🌱 Configuração'!$H$12,{"BioBizz","Remo Nutrients","General Organics","SuperSoil","Genérico"},0),1)=1,IF(1=1,"0.3 mL/L",IF(1=2,"0.3 mL/L",IF(1=3,"0.5 mL/L",IF(1=4,"0.5 mL/L","")))),IF(IFERROR(MATCH('🌱 Configuração'!$H$12,{"BioBizz","Remo Nutrients","General Organics","SuperSoil","Genérico"},0),1)=2,IF(1=1,"0.5 mL/L",IF(1=2,"1 mL/L",IF(1=3,"1 mL/L",IF(1=4,"1 mL/L","")))),IF(IFERROR(MATCH('🌱 Configuração'!$H$12,{"BioBizz","Remo Nutrients","General Organics","SuperSoil","Genérico"},0),1)=3,IF(1=1,"1.3 mL/L",IF(1=2,"1.3 mL/L",IF(1=3,"2.6 mL/L",IF(1=4,"2.6 mL/L","")))),IF(IFERROR(MATCH('🌱 Configuração'!$H$12,{"BioBizz","Remo Nutrients","General Organics","SuperSoil","Genérico"},0),1)=4,IF(1=1,"1–2L/planta",IF(1=2,"1–2L/planta",IF(1=3,"5g/L solo",IF(1=4,"—","")))),IF(1=1,"—",IF(1=2,"—",IF(1=3,"—",IF(1=4,"—",""))))))))))) | F7: =IF('🌱 Configuração'!$B$56="","",IF(1<1,"",IF(1>'🌱 Configuração'!$H$6,"",IF(IFERROR(MATCH('🌱 Configuração'!$H$12,{"BioBizz","Remo Nutrients","General Organics","SuperSoil","Genérico"},0),1)=1,IF(1=1,"—",IF(1=2,"Alg·A·Mic",IF(1=3,"Bio·Grow",IF(1=4,"Bio·Grow","")))),IF(IFERROR(MATCH('🌱 Configuração'!$H$12,{"BioBizz","Remo Nutrients","General Organics","SuperSoil","Genérico"},0),1)=2,IF(1=1,"Magnifical",IF(1=2,"Magnifical",IF(1=3,"Micro",IF(1=4,"Micro","")))),IF(IFERROR(MATCH('🌱 Configuração'!$H$12,{"BioBizz","Remo Nutrients","General Organics","SuperSoil","Genérico"},0),1)=3,IF(1=1,"CaMg+",IF(1=2,"CaMg+",IF(1=3,"CaMg+",IF(1=4,"CaMg+","")))),IF(IFERROR(MATCH('🌱 Configuração'!$H$12,{"BioBizz","Remo Nutrients","General Organics","SuperSoil","Genérico"},0),1)=4,IF(1=1,"—",IF(1=2,"—",IF(1=3,"—",IF(1=4,"—","")))),IF(1=1,"—",IF(1=2,"—",IF(1=3,"—",IF(1=4,"—",""))))))))))) | G7: =IF('🌱 Configuração'!$B$56="","",IF(1<1,"",IF(1>'🌱 Configuração'!$H$6,"",IF(IFERROR(MATCH('🌱 Configuração'!$H$12,{"BioBizz","Remo Nutrients","General Organics","SuperSoil","Genérico"},0),1)=1,IF(1=1,"—",IF(1=2,"0.5 mL/L",IF(1=3,"0.5 mL/L",IF(1=4,"1 mL/L","")))),IF(IFERROR(MATCH('🌱 Configuração'!$H$12,{"BioBizz","Remo Nutrients","General Organics","SuperSoil","Genérico"},0),1)=2,IF(1=1,"0.5 mL/L",IF(1=2,"0.5 mL/L",IF(1=3,"0.5 mL/L",IF(1=4,"1 mL/L","")))),IF(IFERROR(MATCH('🌱 Configuração'!$H$12,{"BioBizz","Remo Nutrients","General Organics","SuperSoil","Genérico"},0),1)=3,IF(1=1,"1.3 mL/L",IF(1=2,"1.3 mL/L",IF(1=3,"1.3 mL/L",IF(1=4,"1.3 mL/L","")))),IF(IFERROR(MATCH('🌱 Configuração'!$H$12,{"BioBizz","Remo Nutrients","General Organics","SuperSoil","Genérico"},0),1)=4,IF(1=1,"—",IF(1=2,"—",IF(1=3,"—",IF(1=4,"—","")))),IF(1=1,"—",IF(1=2,"—",IF(1=3,"—",IF(1=4,"—",""))))))))))) | H7: =IF('🌱 Configuração'!$B$56="","",IF(1<1,"",IF(1>'🌱 Configuração'!$H$6,"",IF(IFERROR(MATCH('🌱 Configuração'!$H$12,{"BioBizz","Remo Nutrients","General Organics","SuperSoil","Genérico"},0),1)=1,IF(1=1,"—",IF(1=2,"—",IF(1=3,"—",IF(1=4,"—","")))),IF(IFERROR(MATCH('🌱 Configuração'!$H$12,{"BioBizz","Remo Nutrients","General Organics","SuperSoil","Genérico"},0),1)=2,IF(1=1,"—",IF(1=2,"—",IF(1=3,"Grow",IF(1=4,"Grow","")))),IF(IFERROR(MATCH('🌱 Configuração'!$H$12,{"BioBizz","Remo Nutrients","General Organics","SuperSoil","Genérico"},0),1)=3,IF(1=1,"—",IF(1=2,"BioWeed",IF(1=3,"BioThrive G",IF(1=4,"BioThrive G","")))),IF(IFERROR(MATCH('🌱 Configuração'!$H$12,{"BioBizz","Remo Nutrients","General Organics","SuperSoil","Genérico"},0),1)=4,IF(1=1,"—",IF(1=2,"—",IF(1=3,"—",IF(1=4,"—","")))),IF(1=1,"—",IF(1=2,"—",IF(1=3,"—",IF(1=4,"—",""))))))))))) | I7: =IF('🌱 Configuração'!$B$56="","",IF(1<1,"",IF(1>'🌱 Configuração'!$H$6,"",IF(IFERROR(MATCH('🌱 Configuração'!$H$12,{"BioBizz","Remo Nutrients","General Organics","SuperSoil","Genérico"},0),1)=1,IF(1=1,"—",IF(1=2,"—",IF(1=3,"—",IF(1=4,"—","")))),IF(IFERROR(MATCH('🌱 Configuração'!$H$12,{"BioBizz","Remo Nutrients","General Organics","SuperSoil","Genérico"},0),1)=2,IF(1=1,"—",IF(1=2,"—",IF(1=3,"0.5 mL/L",IF(1=4,"1 mL/L","")))),IF(IFERROR(MATCH('🌱 Configuração'!$H$12,{"BioBizz","Remo Nutrients","General Organics","SuperSoil","Genérico"},0),1)=3,IF(1=1,"—",IF(1=2,"0.7 mL/L",IF(1=3,"1.3 mL/L",IF(1=4,"2.6 mL/L","")))),IF(IFERROR(MATCH('🌱 Configuração'!$H$12,{"BioBizz","Remo Nutrients","General Organics","SuperSoil","Genérico"},0),1)=4,IF(1=1,"—",IF(1=2,"—",IF(1=3,"—",IF(1=4,"—","")))),IF(1=1,"—",IF(1=2,"—",IF(1=3,"—",IF(1=4,"—",""))))))))))) | J7: =IF('🌱 Configuração'!$B$56="","",IF(1<1,"",IF(1>'🌱 Configuração'!$H$6,"",IF(IFERROR(MATCH('🌱 Configuração'!$H$12,{"BioBizz","Remo Nutrients","General Organics","SuperSoil","Genérico"},0),1)=1,IF(1=1,"—",IF(1=2,"—",IF(1=3,"—",IF(1=4,"—","")))),IF(IFERROR(MATCH('🌱 Configuração'!$H$12,{"BioBizz","Remo Nutrients","General Organics","SuperSoil","Genérico"},0),1)=2,IF(1=1,"—",IF(1=2,"—",IF(1=3,"—",IF(1=4,"—","")))),IF(IFERROR(MATCH('🌱 Configuração'!$H$12,{"BioBizz","Remo Nutrients","General Organics","SuperSoil","Genérico"},0),1)=3,IF(1=1,"—",IF(1=2,"—",IF(1=3,"—",IF(1=4,"—","")))),IF(IFERROR(MATCH('🌱 Configuração'!$H$12,{"BioBizz","Remo Nutrients","General Organics","SuperSoil","Genérico"},0),1)=4,IF(1=1,"Biorrizas",IF(1=2,"—",IF(1=3,"—",IF(1=4,"Biorrizas","")))),IF(1=1,"—",IF(1=2,"—",IF(1=3,"—",IF(1=4,"—",""))))))))))) | K7: =IF('🌱 Configuração'!$B$56="","",IF(1<1,"",IF(1>'🌱 Configuração'!$H$6,"",IF(IFERROR(MATCH('🌱 Configuração'!$H$12,{"BioBizz","Remo Nutrients","General Organics","SuperSoil","Genérico"},0),1)=1,IF(1=1,"6.2–6.5",IF(1=2,"6.2–6.5",IF(1=3,"6.2–6.5",IF(1=4,"6.2–6.5","")))),IF(IFERROR(MATCH('🌱 Configuração'!$H$12,{"BioBizz","Remo Nutrients","General Organics","SuperSoil","Genérico"},0),1)=2,IF(1=1,"5.8–6.0",IF(1=2,"5.8–6.0",IF(1=3,"5.8–6.2",IF(1=4,"5.8–6.2","")))),IF(IFERROR(MATCH('🌱 Configuração'!$H$12,{"BioBizz","Remo Nutrients","General Organics","SuperSoil","Genérico"},0),1)=3,IF(1=1,"6.2–7.0",IF(1=2,"6.2–7.0",IF(1=3,"6.2–7.0",IF(1=4,"6.2–7.0","")))),IF(IFERROR(MATCH('🌱 Configuração'!$H$12,{"BioBizz","Remo Nutrients","General Organics","SuperSoil","Genérico"},0),1)=4,IF(1=1,"auto",IF(1=2,"auto",IF(1=3,"auto",IF(1=4,"auto","")))),IF(1=1,"—",IF(1=2,"—",IF(1=3,"—",IF(1=4,"—",""))))))))))) | L7: =IF('🌱 Configuração'!$B$56="","",IF(1<1,"",IF(1>'🌱 Configuração'!$H$6,"",IF(IFERROR(MATCH('🌱 Configuração'!$H$12,{"BioBizz","Remo Nutrients","General Organics","SuperSoil","Genérico"},0),1)=1,IF(1=1,"baixo",IF(1=2,"baixo",IF(1=3,"baixo",IF(1=4,"baixo","")))),IF(IFERROR(MATCH('🌱 Configuração'!$H$12,{"BioBizz","Remo Nutrients","General Organics","SuperSoil","Genérico"},0),1)=2,IF(1=1,"baixo",IF(1=2,"baixo",IF(1=3,"0.4",IF(1=4,"0.6","")))),IF(IFERROR(MATCH('🌱 Configuração'!$H$12,{"BioBizz","Remo Nutrients","General Organics","SuperSoil","Genérico"},0),1)=3,IF(1=1,"baixo",IF(1=2,"baixo",IF(1=3,"baixo",IF(1=4,"baixo","")))),IF(IFERROR(MATCH('🌱 Configuração'!$H$12,{"BioBizz","Remo Nutrients","General Organics","SuperSoil","Genérico"},0),1)=4,IF(1=1,"auto",IF(1=2,"auto",IF(1=3,"auto",IF(1=4,"auto","")))),IF(1=1,"—",IF(1=2,"—",IF(1=3,"—",IF(1=4,"—",""))))))))))) | M7: =IF('🌱 Configuração'!$B$56="","",IF(1<1,"",IF(1>'🌱 Configuração'!$H$6,"",IF(IFERROR(MATCH('🌱 Configuração'!$H$12,{"BioBizz","Remo Nutrients","General Organics","SuperSoil","Genérico"},0),1)=1,IF(1=1,"Solo úmido — estimular raízes",IF(1=2,"Alg·A·Mic recupera e fortalece",IF(1=3,"Início suave de N antes da vega",IF(1=4,"Pronto para vegetativo","")))),IF(IFERROR(MATCH('🌱 Configuração'!$H$12,{"BioBizz","Remo Nutrients","General Organics","SuperSoil","Genérico"},0),1)=2,IF(1=1,"Roots = estimulador de raízes Remo",IF(1=2,"Magnifical = CalMag Remo",IF(1=3,"Introduzir base suave antes da vega",IF(1=4,"Pronto para vega — confirmar raízes","")))),IF(IFERROR(MATCH('🌱 Configuração'!$H$12,{"BioBizz","Remo Nutrients","General Organics","SuperSoil","Genérico"},0),1)=3,IF(1=1,"GO não precisa ajustar pH em solo",IF(1=2,"BioWeed = extrato de algas GO",IF(1=3,"Introduzir BioThrive Grow suave",IF(1=4,"Pronto para vega","")))),IF(IFERROR(MATCH('🌱 Configuração'!$H$12,{"BioBizz","Remo Nutrients","General Organics","SuperSoil","Genérico"},0),1)=4,IF(1=1,"Solo vivo — sem adubação química",IF(1=2,"Manter solo úmido e vivo",IF(1=3,"Farinha de alga = fósforo e K suave",IF(1=4,"Mel de cana alimenta microbioma","")))),IF(1=1,"Personalize suas doses",IF(1=2,"Personalize suas doses",IF(1=3,"Personalize suas doses",IF(1=4,"Personalize suas doses","")))))))))))
B8: =IF(2<='🌱 Configuração'!$H$6,"S2","—") -> S2 | C8: =IF(2<='🌱 Configuração'!$H$6,'🌱 Configuração'!$B$56+7,"") -> 7 | D8: =IF('🌱 Configuração'!$B$56="","",IF(2<1,"",IF(2>'🌱 Configuração'!$H$6,"",IF(IFERROR(MATCH('🌱 Configuração'!$H$12,{"BioBizz","Remo Nutrients","General Organics","SuperSoil","Genérico"},0),1)=1,IF(2=1,"Root Juice",IF(2=2,"Root Juice",IF(2=3,"Root Juice",IF(2=4,"Root Juice","")))),IF(IFERROR(MATCH('🌱 Configuração'!$H$12,{"BioBizz","Remo Nutrients","General Organics","SuperSoil","Genérico"},0),1)=2,IF(2=1,"Remo Roots",IF(2=2,"Remo Roots",IF(2=3,"Remo Roots",IF(2=4,"Remo Roots","")))),IF(IFERROR(MATCH('🌱 Configuração'!$H$12,{"BioBizz","Remo Nutrients","General Organics","SuperSoil","Genérico"},0),1)=3,IF(2=1,"BioRoot",IF(2=2,"BioRoot",IF(2=3,"BioRoot",IF(2=4,"BioRoot","")))),IF(IFERROR(MATCH('🌱 Configuração'!$H$12,{"BioBizz","Remo Nutrients","General Organics","SuperSoil","Genérico"},0),1)=4,IF(2=1,"Chá de compostagem",IF(2=2,"Chá de compostagem",IF(2=3,"Cobertura: farinha de alga",IF(2=4,"Molasses 2 mL/L","")))),IF(2=1,"← Preencha",IF(2=2,"← Preencha",IF(2=3,"← Preencha",IF(2=4,"← Preencha",""))))))))))) | E8: =IF('🌱 Configuração'!$B$56="","",IF(2<1,"",IF(2>'🌱 Configuração'!$H$6,"",IF(IFERROR(MATCH('🌱 Configuração'!$H$12,{"BioBizz","Remo Nutrients","General Organics","SuperSoil","Genérico"},0),1)=1,IF(2=1,"0.3 mL/L",IF(2=2,"0.3 mL/L",IF(2=3,"0.5 mL/L",IF(2=4,"0.5 mL/L","")))),IF(IFERROR(MATCH('🌱 Configuração'!$H$12,{"BioBizz","Remo Nutrients","General Organics","SuperSoil","Genérico"},0),1)=2,IF(2=1,"0.5 mL/L",IF(2=2,"1 mL/L",IF(2=3,"1 mL/L",IF(2=4,"1 mL/L","")))),IF(IFERROR(MATCH('🌱 Configuração'!$H$12,{"BioBizz","Remo Nutrients","General Organics","SuperSoil","Genérico"},0),1)=3,IF(2=1,"1.3 mL/L",IF(2=2,"1.3 mL/L",IF(2=3,"2.6 mL/L",IF(2=4,"2.6 mL/L","")))),IF(IFERROR(MATCH('🌱 Configuração'!$H$12,{"BioBizz","Remo Nutrients","General Organics","SuperSoil","Genérico"},0),1)=4,IF(2=1,"1–2L/planta",IF(2=2,"1–2L/planta",IF(2=3,"5g/L solo",IF(2=4,"—","")))),IF(2=1,"—",IF(2=2,"—",IF(2=3,"—",IF(2=4,"—",""))))))))))) | F8: =IF('🌱 Configuração'!$B$56="","",IF(2<1,"",IF(2>'🌱 Configuração'!$H$6,"",IF(IFERROR(MATCH('🌱 Configuração'!$H$12,{"BioBizz","Remo Nutrients","General Organics","SuperSoil","Genérico"},0),1)=1,IF(2=1,"—",IF(2=2,"Alg·A·Mic",IF(2=3,"Bio·Grow",IF(2=4,"Bio·Grow","")))),IF(IFERROR(MATCH('🌱 Configuração'!$H$12,{"BioBizz","Remo Nutrients","General Organics","SuperSoil","Genérico"},0),1)=2,IF(2=1,"Magnifical",IF(2=2,"Magnifical",IF(2=3,"Micro",IF(2=4,"Micro","")))),IF(IFERROR(MATCH('🌱 Configuração'!$H$12,{"BioBizz","Remo Nutrients","General Organics","SuperSoil","Genérico"},0),1)=3,IF(2=1,"CaMg+",IF(2=2,"CaMg+",IF(2=3,"CaMg+",IF(2=4,"CaMg+","")))),IF(IFERROR(MATCH('🌱 Configuração'!$H$12,{"BioBizz","Remo Nutrients","General Organics","SuperSoil","Genérico"},0),1)=4,IF(2=1,"—",IF(2=2,"—",IF(2=3,"—",IF(2=4,"—","")))),IF(2=1,"—",IF(2=2,"—",IF(2=3,"—",IF(2=4,"—",""))))))))))) | G8: =IF('🌱 Configuração'!$B$56="","",IF(2<1,"",IF(2>'🌱 Configuração'!$H$6,"",IF(IFERROR(MATCH('🌱 Configuração'!$H$12,{"BioBizz","Remo Nutrients","General Organics","SuperSoil","Genérico"},0),1)=1,IF(2=1,"—",IF(2=2,"0.5 mL/L",IF(2=3,"0.5 mL/L",IF(2=4,"1 mL/L","")))),IF(IFERROR(MATCH('🌱 Configuração'!$H$12,{"BioBizz","Remo Nutrients","General Organics","SuperSoil","Genérico"},0),1)=2,IF(2=1,"0.5 mL/L",IF(2=2,"0.5 mL/L",IF(2=3,"0.5 mL/L",IF(2=4,"1 mL/L","")))),IF(IFERROR(MATCH('🌱 Configuração'!$H$12,{"BioBizz","Remo Nutrients","General Organics","SuperSoil","Genérico"},0),1)=3,IF(2=1,"1.3 mL/L",IF(2=2,"1.3 mL/L",IF(2=3,"1.3 mL/L",IF(2=4,"1.3 mL/L","")))),IF(IFERROR(MATCH('🌱 Configuração'!$H$12,{"BioBizz","Remo Nutrients","General Organics","SuperSoil","Genérico"},0),1)=4,IF(2=1,"—",IF(2=2,"—",IF(2=3,"—",IF(2=4,"—","")))),IF(2=1,"—",IF(2=2,"—",IF(2=3,"—",IF(2=4,"—",""))))))))))) | H8: =IF('🌱 Configuração'!$B$56="","",IF(2<1,"",IF(2>'🌱 Configuração'!$H$6,"",IF(IFERROR(MATCH('🌱 Configuração'!$H$12,{"BioBizz","Remo Nutrients","General Organics","SuperSoil","Genérico"},0),1)=1,IF(2=1,"—",IF(2=2,"—",IF(2=3,"—",IF(2=4,"—","")))),IF(IFERROR(MATCH('🌱 Configuração'!$H$12,{"BioBizz","Remo Nutrients","General Organics","SuperSoil","Genérico"},0),1)=2,IF(2=1,"—",IF(2=2,"—",IF(2=3,"Grow",IF(2=4,"Grow","")))),IF(IFERROR(MATCH('🌱 Configuração'!$H$12,{"BioBizz","Remo Nutrients","General Organics","SuperSoil","Genérico"},0),1)=3,IF(2=1,"—",IF(2=2,"BioWeed",IF(2=3,"BioThrive G",IF(2=4,"BioThrive G","")))),IF(IFERROR(MATCH('🌱 Configuração'!$H$12,{"BioBizz","Remo Nutrients","General Organics","SuperSoil","Genérico"},0),1)=4,IF(2=1,"—",IF(2=2,"—",IF(2=3,"—",IF(2=4,"—","")))),IF(2=1,"—",IF(2=2,"—",IF(2=3,"—",IF(2=4,"—",""))))))))))) | I8: =IF('🌱 Configuração'!$B$56="","",IF(2<1,"",IF(2>'🌱 Configuração'!$H$6,"",IF(IFERROR(MATCH('🌱 Configuração'!$H$12,{"BioBizz","Remo Nutrients","General Organics","SuperSoil","Genérico"},0),1)=1,IF(2=1,"—",IF(2=2,"—",IF(2=3,"—",IF(2=4,"—","")))),IF(IFERROR(MATCH('🌱 Configuração'!$H$12,{"BioBizz","Remo Nutrients","General Organics","SuperSoil","Genérico"},0),1)=2,IF(2=1,"—",IF(2=2,"—",IF(2=3,"0.5 mL/L",IF(2=4,"1 mL/L","")))),IF(IFERROR(MATCH('🌱 Configuração'!$H$12,{"BioBizz","Remo Nutrients","General Organics","SuperSoil","Genérico"},0),1)=3,IF(2=1,"—",IF(2=2,"0.7 mL/L",IF(2=3,"1.3 mL/L",IF(2=4,"2.6 mL/L","")))),IF(IFERROR(MATCH('🌱 Configuração'!$H$12,{"BioBizz","Remo Nutrients","General Organics","SuperSoil","Genérico"},0),1)=4,IF(2=1,"—",IF(2=2,"—",IF(2=3,"—",IF(2=4,"—","")))),IF(2=1,"—",IF(2=2,"—",IF(2=3,"—",IF(2=4,"—",""))))))))))) | J8: =IF('🌱 Configuração'!$B$56="","",IF(2<1,"",IF(2>'🌱 Configuração'!$H$6,"",IF(IFERROR(MATCH('🌱 Configuração'!$H$12,{"BioBizz","Remo Nutrients","General Organics","SuperSoil","Genérico"},0),1)=1,IF(2=1,"—",IF(2=2,"—",IF(2=3,"—",IF(2=4,"—","")))),IF(IFERROR(MATCH('🌱 Configuração'!$H$12,{"BioBizz","Remo Nutrients","General Organics","SuperSoil","Genérico"},0),1)=2,IF(2=1,"—",IF(2=2,"—",IF(2=3,"—",IF(2=4,"—","")))),IF(IFERROR(MATCH('🌱 Configuração'!$H$12,{"BioBizz","Remo Nutrients","General Organics","SuperSoil","Genérico"},0),1)=3,IF(2=1,"—",IF(2=2,"—",IF(2=3,"—",IF(2=4,"—","")))),IF(IFERROR(MATCH('🌱 Configuração'!$H$12,{"BioBizz","Remo Nutrients","General Organics","SuperSoil","Genérico"},0),1)=4,IF(2=1,"Biorrizas",IF(2=2,"—",IF(2=3,"—",IF(2=4,"Biorrizas","")))),IF(2=1,"—",IF(2=2,"—",IF(2=3,"—",IF(2=4,"—",""))))))))))) | K8: =IF('🌱 Configuração'!$B$56="","",IF(2<1,"",IF(2>'🌱 Configuração'!$H$6,"",IF(IFERROR(MATCH('🌱 Configuração'!$H$12,{"BioBizz","Remo Nutrients","General Organics","SuperSoil","Genérico"},0),1)=1,IF(2=1,"6.2–6.5",IF(2=2,"6.2–6.5",IF(2=3,"6.2–6.5",IF(2=4,"6.2–6.5","")))),IF(IFERROR(MATCH('🌱 Configuração'!$H$12,{"BioBizz","Remo Nutrients","General Organics","SuperSoil","Genérico"},0),1)=2,IF(2=1,"5.8–6.0",IF(2=2,"5.8–6.0",IF(2=3,"5.8–6.2",IF(2=4,"5.8–6.2","")))),IF(IFERROR(MATCH('🌱 Configuração'!$H$12,{"BioBizz","Remo Nutrients","General Organics","SuperSoil","Genérico"},0),1)=3,IF(2=1,"6.2–7.0",IF(2=2,"6.2–7.0",IF(2=3,"6.2–7.0",IF(2=4,"6.2–7.0","")))),IF(IFERROR(MATCH('🌱 Configuração'!$H$12,{"BioBizz","Remo Nutrients","General Organics","SuperSoil","Genérico"},0),1)=4,IF(2=1,"auto",IF(2=2,"auto",IF(2=3,"auto",IF(2=4,"auto","")))),IF(2=1,"—",IF(2=2,"—",IF(2=3,"—",IF(2=4,"—",""))))))))))) | L8: =IF('🌱 Configuração'!$B$56="","",IF(2<1,"",IF(2>'🌱 Configuração'!$H$6,"",IF(IFERROR(MATCH('🌱 Configuração'!$H$12,{"BioBizz","Remo Nutrients","General Organics","SuperSoil","Genérico"},0),1)=1,IF(2=1,"baixo",IF(2=2,"baixo",IF(2=3,"baixo",IF(2=4,"baixo","")))),IF(IFERROR(MATCH('🌱 Configuração'!$H$12,{"BioBizz","Remo Nutrients","General Organics","SuperSoil","Genérico"},0),1)=2,IF(2=1,"baixo",IF(2=2,"baixo",IF(2=3,"0.4",IF(2=4,"0.6","")))),IF(IFERROR(MATCH('🌱 Configuração'!$H$12,{"BioBizz","Remo Nutrients","General Organics","SuperSoil","Genérico"},0),1)=3,IF(2=1,"baixo",IF(2=2,"baixo",IF(2=3,"baixo",IF(2=4,"baixo","")))),IF(IFERROR(MATCH('🌱 Configuração'!$H$12,{"BioBizz","Remo Nutrients","General Organics","SuperSoil","Genérico"},0),1)=4,IF(2=1,"auto",IF(2=2,"auto",IF(2=3,"auto",IF(2=4,"auto","")))),IF(2=1,"—",IF(2=2,"—",IF(2=3,"—",IF(2=4,"—",""))))))))))) | M8: =IF('🌱 Configuração'!$B$56="","",IF(2<1,"",IF(2>'🌱 Configuração'!$H$6,"",IF(IFERROR(MATCH('🌱 Configuração'!$H$12,{"BioBizz","Remo Nutrients","General Organics","SuperSoil","Genérico"},0),1)=1,IF(2=1,"Solo úmido — estimular raízes",IF(2=2,"Alg·A·Mic recupera e fortalece",IF(2=3,"Início suave de N antes da vega",IF(2=4,"Pronto para vegetativo","")))),IF(IFERROR(MATCH('🌱 Configuração'!$H$12,{"BioBizz","Remo Nutrients","General Organics","SuperSoil","Genérico"},0),1)=2,IF(2=1,"Roots = estimulador de raízes Remo",IF(2=2,"Magnifical = CalMag Remo",IF(2=3,"Introduzir base suave antes da vega",IF(2=4,"Pronto para vega — confirmar raízes","")))),IF(IFERROR(MATCH('🌱 Configuração'!$H$12,{"BioBizz","Remo Nutrients","General Organics","SuperSoil","Genérico"},0),1)=3,IF(2=1,"GO não precisa ajustar pH em solo",IF(2=2,"BioWeed = extrato de algas GO",IF(2=3,"Introduzir BioThrive Grow suave",IF(2=4,"Pronto para vega","")))),IF(IFERROR(MATCH('🌱 Configuração'!$H$12,{"BioBizz","Remo Nutrients","General Organics","SuperSoil","Genérico"},0),1)=4,IF(2=1,"Solo vivo — sem adubação química",IF(2=2,"Manter solo úmido e vivo",IF(2=3,"Farinha de alga = fósforo e K suave",IF(2=4,"Mel de cana alimenta microbioma","")))),IF(2=1,"Personalize suas doses",IF(2=2,"Personalize suas doses",IF(2=3,"Personalize suas doses",IF(2=4,"Personalize suas doses","")))))))))))
B9: =IF(3<='🌱 Configuração'!$H$6,"S3","—") -> — | C9: =IF(3<='🌱 Configuração'!$H$6,'🌱 Configuração'!$B$56+14,"") | D9: =IF('🌱 Configuração'!$B$56="","",IF(3<1,"",IF(3>'🌱 Configuração'!$H$6,"",IF(IFERROR(MATCH('🌱 Configuração'!$H$12,{"BioBizz","Remo Nutrients","General Organics","SuperSoil","Genérico"},0),1)=1,IF(3=1,"Root Juice",IF(3=2,"Root Juice",IF(3=3,"Root Juice",IF(3=4,"Root Juice","")))),IF(IFERROR(MATCH('🌱 Configuração'!$H$12,{"BioBizz","Remo Nutrients","General Organics","SuperSoil","Genérico"},0),1)=2,IF(3=1,"Remo Roots",IF(3=2,"Remo Roots",IF(3=3,"Remo Roots",IF(3=4,"Remo Roots","")))),IF(IFERROR(MATCH('🌱 Configuração'!$H$12,{"BioBizz","Remo Nutrients","General Organics","SuperSoil","Genérico"},0),1)=3,IF(3=1,"BioRoot",IF(3=2,"BioRoot",IF(3=3,"BioRoot",IF(3=4,"BioRoot","")))),IF(IFERROR(MATCH('🌱 Configuração'!$H$12,{"BioBizz","Remo Nutrients","General Organics","SuperSoil","Genérico"},0),1)=4,IF(3=1,"Chá de compostagem",IF(3=2,"Chá de compostagem",IF(3=3,"Cobertura: farinha de alga",IF(3=4,"Molasses 2 mL/L","")))),IF(3=1,"← Preencha",IF(3=2,"← Preencha",IF(3=3,"← Preencha",IF(3=4,"← Preencha",""))))))))))) | E9: =IF('🌱 Configuração'!$B$56="","",IF(3<1,"",IF(3>'🌱 Configuração'!$H$6,"",IF(IFERROR(MATCH('🌱 Configuração'!$H$12,{"BioBizz","Remo Nutrients","General Organics","SuperSoil","Genérico"},0),1)=1,IF(3=1,"0.3 mL/L",IF(3=2,"0.3 mL/L",IF(3=3,"0.5 mL/L",IF(3=4,"0.5 mL/L","")))),IF(IFERROR(MATCH('🌱 Configuração'!$H$12,{"BioBizz","Remo Nutrients","General Organics","SuperSoil","Genérico"},0),1)=2,IF(3=1,"0.5 mL/L",IF(3=2,"1 mL/L",IF(3=3,"1 mL/L",IF(3=4,"1 mL/L","")))),IF(IFERROR(MATCH('🌱 Configuração'!$H$12,{"BioBizz","Remo Nutrients","General Organics","SuperSoil","Genérico"},0),1)=3,IF(3=1,"1.3 mL/L",IF(3=2,"1.3 mL/L",IF(3=3,"2.6 mL/L",IF(3=4,"2.6 mL/L","")))),IF(IFERROR(MATCH('🌱 Configuração'!$H$12,{"BioBizz","Remo Nutrients","General Organics","SuperSoil","Genérico"},0),1)=4,IF(3=1,"1–2L/planta",IF(3=2,"1–2L/planta",IF(3=3,"5g/L solo",IF(3=4,"—","")))),IF(3=1,"—",IF(3=2,"—",IF(3=3,"—",IF(3=4,"—",""))))))))))) | F9: =IF('🌱 Configuração'!$B$56="","",IF(3<1,"",IF(3>'🌱 Configuração'!$H$6,"",IF(IFERROR(MATCH('🌱 Configuração'!$H$12,{"BioBizz","Remo Nutrients","General Organics","SuperSoil","Genérico"},0),1)=1,IF(3=1,"—",IF(3=2,"Alg·A·Mic",IF(3=3,"Bio·Grow",IF(3=4,"Bio·Grow","")))),IF(IFERROR(MATCH('🌱 Configuração'!$H$12,{"BioBizz","Remo Nutrients","General Organics","SuperSoil","Genérico"},0),1)=2,IF(3=1,"Magnifical",IF(3=2,"Magnifical",IF(3=3,"Micro",IF(3=4,"Micro","")))),IF(IFERROR(MATCH('🌱 Configuração'!$H$12,{"BioBizz","Remo Nutrients","General Organics","SuperSoil","Genérico"},0),1)=3,IF(3=1,"CaMg+",IF(3=2,"CaMg+",IF(3=3,"CaMg+",IF(3=4,"CaMg+","")))),IF(IFERROR(MATCH('🌱 Configuração'!$H$12,{"BioBizz","Remo Nutrients","General Organics","SuperSoil","Genérico"},0),1)=4,IF(3=1,"—",IF(3=2,"—",IF(3=3,"—",IF(3=4,"—","")))),IF(3=1,"—",IF(3=2,"—",IF(3=3,"—",IF(3=4,"—",""))))))))))) | G9: =IF('🌱 Configuração'!$B$56="","",IF(3<1,"",IF(3>'🌱 Configuração'!$H$6,"",IF(IFERROR(MATCH('🌱 Configuração'!$H$12,{"BioBizz","Remo Nutrients","General Organics","SuperSoil","Genérico"},0),1)=1,IF(3=1,"—",IF(3=2,"0.5 mL/L",IF(3=3,"0.5 mL/L",IF(3=4,"1 mL/L","")))),IF(IFERROR(MATCH('🌱 Configuração'!$H$12,{"BioBizz","Remo Nutrients","General Organics","SuperSoil","Genérico"},0),1)=2,IF(3=1,"0.5 mL/L",IF(3=2,"0.5 mL/L",IF(3=3,"0.5 mL/L",IF(3=4,"1 mL/L","")))),IF(IFERROR(MATCH('🌱 Configuração'!$H$12,{"BioBizz","Remo Nutrients","General Organics","SuperSoil","Genérico"},0),1)=3,IF(3=1,"1.3 mL/L",IF(3=2,"1.3 mL/L",IF(3=3,"1.3 mL/L",IF(3=4,"1.3 mL/L","")))),IF(IFERROR(MATCH('🌱 Configuração'!$H$12,{"BioBizz","Remo Nutrients","General Organics","SuperSoil","Genérico"},0),1)=4,IF(3=1,"—",IF(3=2,"—",IF(3=3,"—",IF(3=4,"—","")))),IF(3=1,"—",IF(3=2,"—",IF(3=3,"—",IF(3=4,"—",""))))))))))) | H9: =IF('🌱 Configuração'!$B$56="","",IF(3<1,"",IF(3>'🌱 Configuração'!$H$6,"",IF(IFERROR(MATCH('🌱 Configuração'!$H$12,{"BioBizz","Remo Nutrients","General Organics","SuperSoil","Genérico"},0),1)=1,IF(3=1,"—",IF(3=2,"—",IF(3=3,"—",IF(3=4,"—","")))),IF(IFERROR(MATCH('🌱 Configuração'!$H$12,{"BioBizz","Remo Nutrients","General Organics","SuperSoil","Genérico"},0),1)=2,IF(3=1,"—",IF(3=2,"—",IF(3=3,"Grow",IF(3=4,"Grow","")))),IF(IFERROR(MATCH('🌱 Configuração'!$H$12,{"BioBizz","Remo Nutrients","General Organics","SuperSoil","Genérico"},0),1)=3,IF(3=1,"—",IF(3=2,"BioWeed",IF(3=3,"BioThrive G",IF(3=4,"BioThrive G","")))),IF(IFERROR(MATCH('🌱 Configuração'!$H$12,{"BioBizz","Remo Nutrients","General Organics","SuperSoil","Genérico"},0),1)=4,IF(3=1,"—",IF(3=2,"—",IF(3=3,"—",IF(3=4,"—","")))),IF(3=1,"—",IF(3=2,"—",IF(3=3,"—",IF(3=4,"—",""))))))))))) | I9: =IF('🌱 Configuração'!$B$56="","",IF(3<1,"",IF(3>'🌱 Configuração'!$H$6,"",IF(IFERROR(MATCH('🌱 Configuração'!$H$12,{"BioBizz","Remo Nutrients","General Organics","SuperSoil","Genérico"},0),1)=1,IF(3=1,"—",IF(3=2,"—",IF(3=3,"—",IF(3=4,"—","")))),IF(IFERROR(MATCH('🌱 Configuração'!$H$12,{"BioBizz","Remo Nutrients","General Organics","SuperSoil","Genérico"},0),1)=2,IF(3=1,"—",IF(3=2,"—",IF(3=3,"0.5 mL/L",IF(3=4,"1 mL/L","")))),IF(IFERROR(MATCH('🌱 Configuração'!$H$12,{"BioBizz","Remo Nutrients","General Organics","SuperSoil","Genérico"},0),1)=3,IF(3=1,"—",IF(3=2,"0.7 mL/L",IF(3=3,"1.3 mL/L",IF(3=4,"2.6 mL/L","")))),IF(IFERROR(MATCH('🌱 Configuração'!$H$12,{"BioBizz","Remo Nutrients","General Organics","SuperSoil","Genérico"},0),1)=4,IF(3=1,"—",IF(3=2,"—",IF(3=3,"—",IF(3=4,"—","")))),IF(3=1,"—",IF(3=2,"—",IF(3=3,"—",IF(3=4,"—",""))))))))))) | J9: =IF('🌱 Configuração'!$B$56="","",IF(3<1,"",IF(3>'🌱 Configuração'!$H$6,"",IF(IFERROR(MATCH('🌱 Configuração'!$H$12,{"BioBizz","Remo Nutrients","General Organics","SuperSoil","Genérico"},0),1)=1,IF(3=1,"—",IF(3=2,"—",IF(3=3,"—",IF(3=4,"—","")))),IF(IFERROR(MATCH('🌱 Configuração'!$H$12,{"BioBizz","Remo Nutrients","General Organics","SuperSoil","Genérico"},0),1)=2,IF(3=1,"—",IF(3=2,"—",IF(3=3,"—",IF(3=4,"—","")))),IF(IFERROR(MATCH('🌱 Configuração'!$H$12,{"BioBizz","Remo Nutrients","General Organics","SuperSoil","Genérico"},0),1)=3,IF(3=1,"—",IF(3=2,"—",IF(3=3,"—",IF(3=4,"—","")))),IF(IFERROR(MATCH('🌱 Configuração'!$H$12,{"BioBizz","Remo Nutrients","General Organics","SuperSoil","Genérico"},0),1)=4,IF(3=1,"Biorrizas",IF(3=2,"—",IF(3=3,"—",IF(3=4,"Biorrizas","")))),IF(3=1,"—",IF(3=2,"—",IF(3=3,"—",IF(3=4,"—",""))))))))))) | K9: =IF('🌱 Configuração'!$B$56="","",IF(3<1,"",IF(3>'🌱 Configuração'!$H$6,"",IF(IFERROR(MATCH('🌱 Configuração'!$H$12,{"BioBizz","Remo Nutrients","General Organics","SuperSoil","Genérico"},0),1)=1,IF(3=1,"6.2–6.5",IF(3=2,"6.2–6.5",IF(3=3,"6.2–6.5",IF(3=4,"6.2–6.5","")))),IF(IFERROR(MATCH('🌱 Configuração'!$H$12,{"BioBizz","Remo Nutrients","General Organics","SuperSoil","Genérico"},0),1)=2,IF(3=1,"5.8–6.0",IF(3=2,"5.8–6.0",IF(3=3,"5.8–6.2",IF(3=4,"5.8–6.2","")))),IF(IFERROR(MATCH('🌱 Configuração'!$H$12,{"BioBizz","Remo Nutrients","General Organics","SuperSoil","Genérico"},0),1)=3,IF(3=1,"6.2–7.0",IF(3=2,"6.2–7.0",IF(3=3,"6.2–7.0",IF(3=4,"6.2–7.0","")))),IF(IFERROR(MATCH('🌱 Configuração'!$H$12,{"BioBizz","Remo Nutrients","General Organics","SuperSoil","Genérico"},0),1)=4,IF(3=1,"auto",IF(3=2,"auto",IF(3=3,"auto",IF(3=4,"auto","")))),IF(3=1,"—",IF(3=2,"—",IF(3=3,"—",IF(3=4,"—",""))))))))))) | L9: =IF('🌱 Configuração'!$B$56="","",IF(3<1,"",IF(3>'🌱 Configuração'!$H$6,"",IF(IFERROR(MATCH('🌱 Configuração'!$H$12,{"BioBizz","Remo Nutrients","General Organics","SuperSoil","Genérico"},0),1)=1,IF(3=1,"baixo",IF(3=2,"baixo",IF(3=3,"baixo",IF(3=4,"baixo","")))),IF(IFERROR(MATCH('🌱 Configuração'!$H$12,{"BioBizz","Remo Nutrients","General Organics","SuperSoil","Genérico"},0),1)=2,IF(3=1,"baixo",IF(3=2,"baixo",IF(3=3,"0.4",IF(3=4,"0.6","")))),IF(IFERROR(MATCH('🌱 Configuração'!$H$12,{"BioBizz","Remo Nutrients","General Organics","SuperSoil","Genérico"},0),1)=3,IF(3=1,"baixo",IF(3=2,"baixo",IF(3=3,"baixo",IF(3=4,"baixo","")))),IF(IFERROR(MATCH('🌱 Configuração'!$H$12,{"BioBizz","Remo Nutrients","General Organics","SuperSoil","Genérico"},0),1)=4,IF(3=1,"auto",IF(3=2,"auto",IF(3=3,"auto",IF(3=4,"auto","")))),IF(3=1,"—",IF(3=2,"—",IF(3=3,"—",IF(3=4,"—",""))))))))))) | M9: =IF('🌱 Configuração'!$B$56="","",IF(3<1,"",IF(3>'🌱 Configuração'!$H$6,"",IF(IFERROR(MATCH('🌱 Configuração'!$H$12,{"BioBizz","Remo Nutrients","General Organics","SuperSoil","Genérico"},0),1)=1,IF(3=1,"Solo úmido — estimular raízes",IF(3=2,"Alg·A·Mic recupera e fortalece",IF(3=3,"Início suave de N antes da vega",IF(3=4,"Pronto para vegetativo","")))),IF(IFERROR(MATCH('🌱 Configuração'!$H$12,{"BioBizz","Remo Nutrients","General Organics","SuperSoil","Genérico"},0),1)=2,IF(3=1,"Roots = estimulador de raízes Remo",IF(3=2,"Magnifical = CalMag Remo",IF(3=3,"Introduzir base suave antes da vega",IF(3=4,"Pronto para vega — confirmar raízes","")))),IF(IFERROR(MATCH('🌱 Configuração'!$H$12,{"BioBizz","Remo Nutrients","General Organics","SuperSoil","Genérico"},0),1)=3,IF(3=1,"GO não precisa ajustar pH em solo",IF(3=2,"BioWeed = extrato de algas GO",IF(3=3,"Introduzir BioThrive Grow suave",IF(3=4,"Pronto para vega","")))),IF(IFERROR(MATCH('🌱 Configuração'!$H$12,{"BioBizz","Remo Nutrients","General Organics","SuperSoil","Genérico"},0),1)=4,IF(3=1,"Solo vivo — sem adubação química",IF(3=2,"Manter solo úmido e vivo",IF(3=3,"Farinha de alga = fósforo e K suave",IF(3=4,"Mel de cana alimenta microbioma","")))),IF(3=1,"Personalize suas doses",IF(3=2,"Personalize suas doses",IF(3=3,"Personalize suas doses",IF(3=4,"Personalize suas doses","")))))))))))
B10: =IF(4<='🌱 Configuração'!$H$6,"S4","—") -> — | C10: =IF(4<='🌱 Configuração'!$H$6,'🌱 Configuração'!$B$56+21,"") | D10: =IF('🌱 Configuração'!$B$56="","",IF(4<1,"",IF(4>'🌱 Configuração'!$H$6,"",IF(IFERROR(MATCH('🌱 Configuração'!$H$12,{"BioBizz","Remo Nutrients","General Organics","SuperSoil","Genérico"},0),1)=1,IF(4=1,"Root Juice",IF(4=2,"Root Juice",IF(4=3,"Root Juice",IF(4=4,"Root Juice","")))),IF(IFERROR(MATCH('🌱 Configuração'!$H$12,{"BioBizz","Remo Nutrients","General Organics","SuperSoil","Genérico"},0),1)=2,IF(4=1,"Remo Roots",IF(4=2,"Remo Roots",IF(4=3,"Remo Roots",IF(4=4,"Remo Roots","")))),IF(IFERROR(MATCH('🌱 Configuração'!$H$12,{"BioBizz","Remo Nutrients","General Organics","SuperSoil","Genérico"},0),1)=3,IF(4=1,"BioRoot",IF(4=2,"BioRoot",IF(4=3,"BioRoot",IF(4=4,"BioRoot","")))),IF(IFERROR(MATCH('🌱 Configuração'!$H$12,{"BioBizz","Remo Nutrients","General Organics","SuperSoil","Genérico"},0),1)=4,IF(4=1,"Chá de compostagem",IF(4=2,"Chá de compostagem",IF(4=3,"Cobertura: farinha de alga",IF(4=4,"Molasses 2 mL/L","")))),IF(4=1,"← Preencha",IF(4=2,"← Preencha",IF(4=3,"← Preencha",IF(4=4,"← Preencha",""))))))))))) | E10: =IF('🌱 Configuração'!$B$56="","",IF(4<1,"",IF(4>'🌱 Configuração'!$H$6,"",IF(IFERROR(MATCH('🌱 Configuração'!$H$12,{"BioBizz","Remo Nutrients","General Organics","SuperSoil","Genérico"},0),1)=1,IF(4=1,"0.3 mL/L",IF(4=2,"0.3 mL/L",IF(4=3,"0.5 mL/L",IF(4=4,"0.5 mL/L","")))),IF(IFERROR(MATCH('🌱 Configuração'!$H$12,{"BioBizz","Remo Nutrients","General Organics","SuperSoil","Genérico"},0),1)=2,IF(4=1,"0.5 mL/L",IF(4=2,"1 mL/L",IF(4=3,"1 mL/L",IF(4=4,"1 mL/L","")))),IF(IFERROR(MATCH('🌱 Configuração'!$H$12,{"BioBizz","Remo Nutrients","General Organics","SuperSoil","Genérico"},0),1)=3,IF(4=1,"1.3 mL/L",IF(4=2,"1.3 mL/L",IF(4=3,"2.6 mL/L",IF(4=4,"2.6 mL/L","")))),IF(IFERROR(MATCH('🌱 Configuração'!$H$12,{"BioBizz","Remo Nutrients","General Organics","SuperSoil","Genérico"},0),1)=4,IF(4=1,"1–2L/planta",IF(4=2,"1–2L/planta",IF(4=3,"5g/L solo",IF(4=4,"—","")))),IF(4=1,"—",IF(4=2,"—",IF(4=3,"—",IF(4=4,"—",""))))))))))) | F10: =IF('🌱 Configuração'!$B$56="","",IF(4<1,"",IF(4>'🌱 Configuração'!$H$6,"",IF(IFERROR(MATCH('🌱 Configuração'!$H$12,{"BioBizz","Remo Nutrients","General Organics","SuperSoil","Genérico"},0),1)=1,IF(4=1,"—",IF(4=2,"Alg·A·Mic",IF(4=3,"Bio·Grow",IF(4=4,"Bio·Grow","")))),IF(IFERROR(MATCH('🌱 Configuração'!$H$12,{"BioBizz","Remo Nutrients","General Organics","SuperSoil","Genérico"},0),1)=2,IF(4=1,"Magnifical",IF(4=2,"Magnifical",IF(4=3,"Micro",IF(4=4,"Micro","")))),IF(IFERROR(MATCH('🌱 Configuração'!$H$12,{"BioBizz","Remo Nutrients","General Organics","SuperSoil","Genérico"},0),1)=3,IF(4=1,"CaMg+",IF(4=2,"CaMg+",IF(4=3,"CaMg+",IF(4=4,"CaMg+","")))),IF(IFERROR(MATCH('🌱 Configuração'!$H$12,{"BioBizz","Remo Nutrients","General Organics","SuperSoil","Genérico"},0),1)=4,IF(4=1,"—",IF(4=2,"—",IF(4=3,"—",IF(4=4,"—","")))),IF(4=1,"—",IF(4=2,"—",IF(4=3,"—",IF(4=4,"—",""))))))))))) | G10: =IF('🌱 Configuração'!$B$56="","",IF(4<1,"",IF(4>'🌱 Configuração'!$H$6,"",IF(IFERROR(MATCH('🌱 Configuração'!$H$12,{"BioBizz","Remo Nutrients","General Organics","SuperSoil","Genérico"},0),1)=1,IF(4=1,"—",IF(4=2,"0.5 mL/L",IF(4=3,"0.5 mL/L",IF(4=4,"1 mL/L","")))),IF(IFERROR(MATCH('🌱 Configuração'!$H$12,{"BioBizz","Remo Nutrients","General Organics","SuperSoil","Genérico"},0),1)=2,IF(4=1,"0.5 mL/L",IF(4=2,"0.5 mL/L",IF(4=3,"0.5 mL/L",IF(4=4,"1 mL/L","")))),IF(IFERROR(MATCH('🌱 Configuração'!$H$12,{"BioBizz","Remo Nutrients","General Organics","SuperSoil","Genérico"},0),1)=3,IF(4=1,"1.3 mL/L",IF(4=2,"1.3 mL/L",IF(4=3,"1.3 mL/L",IF(4=4,"1.3 mL/L","")))),IF(IFERROR(MATCH('🌱 Configuração'!$H$12,{"BioBizz","Remo Nutrients","General Organics","SuperSoil","Genérico"},0),1)=4,IF(4=1,"—",IF(4=2,"—",IF(4=3,"—",IF(4=4,"—","")))),IF(4=1,"—",IF(4=2,"—",IF(4=3,"—",IF(4=4,"—",""))))))))))) | H10: =IF('🌱 Configuração'!$B$56="","",IF(4<1,"",IF(4>'🌱 Configuração'!$H$6,"",IF(IFERROR(MATCH('🌱 Configuração'!$H$12,{"BioBizz","Remo Nutrients","General Organics","SuperSoil","Genérico"},0),1)=1,IF(4=1,"—",IF(4=2,"—",IF(4=3,"—",IF(4=4,"—","")))),IF(IFERROR(MATCH('🌱 Configuração'!$H$12,{"BioBizz","Remo Nutrients","General Organics","SuperSoil","Genérico"},0),1)=2,IF(4=1,"—",IF(4=2,"—",IF(4=3,"Grow",IF(4=4,"Grow","")))),IF(IFERROR(MATCH('🌱 Configuração'!$H$12,{"BioBizz","Remo Nutrients","General Organics","SuperSoil","Genérico"},0),1)=3,IF(4=1,"—",IF(4=2,"BioWeed",IF(4=3,"BioThrive G",IF(4=4,"BioThrive G","")))),IF(IFERROR(MATCH('🌱 Configuração'!$H$12,{"BioBizz","Remo Nutrients","General Organics","SuperSoil","Genérico"},0),1)=4,IF(4=1,"—",IF(4=2,"—",IF(4=3,"—",IF(4=4,"—","")))),IF(4=1,"—",IF(4=2,"—",IF(4=3,"—",IF(4=4,"—",""))))))))))) | I10: =IF('🌱 Configuração'!$B$56="","",IF(4<1,"",IF(4>'🌱 Configuração'!$H$6,"",IF(IFERROR(MATCH('🌱 Configuração'!$H$12,{"BioBizz","Remo Nutrients","General Organics","SuperSoil","Genérico"},0),1)=1,IF(4=1,"—",IF(4=2,"—",IF(4=3,"—",IF(4=4,"—","")))),IF(IFERROR(MATCH('🌱 Configuração'!$H$12,{"BioBizz","Remo Nutrients","General Organics","SuperSoil","Genérico"},0),1)=2,IF(4=1,"—",IF(4=2,"—",IF(4=3,"0.5 mL/L",IF(4=4,"1 mL/L","")))),IF(IFERROR(MATCH('🌱 Configuração'!$H$12,{"BioBizz","Remo Nutrients","General Organics","SuperSoil","Genérico"},0),1)=3,IF(4=1,"—",IF(4=2,"0.7 mL/L",IF(4=3,"1.3 mL/L",IF(4=4,"2.6 mL/L","")))),IF(IFERROR(MATCH('🌱 Configuração'!$H$12,{"BioBizz","Remo Nutrients","General Organics","SuperSoil","Genérico"},0),1)=4,IF(4=1,"—",IF(4=2,"—",IF(4=3,"—",IF(4=4,"—","")))),IF(4=1,"—",IF(4=2,"—",IF(4=3,"—",IF(4=4,"—",""))))))))))) | J10: =IF('🌱 Configuração'!$B$56="","",IF(4<1,"",IF(4>'🌱 Configuração'!$H$6,"",IF(IFERROR(MATCH('🌱 Configuração'!$H$12,{"BioBizz","Remo Nutrients","General Organics","SuperSoil","Genérico"},0),1)=1,IF(4=1,"—",IF(4=2,"—",IF(4=3,"—",IF(4=4,"—","")))),IF(IFERROR(MATCH('🌱 Configuração'!$H$12,{"BioBizz","Remo Nutrients","General Organics","SuperSoil","Genérico"},0),1)=2,IF(4=1,"—",IF(4=2,"—",IF(4=3,"—",IF(4=4,"—","")))),IF(IFERROR(MATCH('🌱 Configuração'!$H$12,{"BioBizz","Remo Nutrients","General Organics","SuperSoil","Genérico"},0),1)=3,IF(4=1,"—",IF(4=2,"—",IF(4=3,"—",IF(4=4,"—","")))),IF(IFERROR(MATCH('🌱 Configuração'!$H$12,{"BioBizz","Remo Nutrients","General Organics","SuperSoil","Genérico"},0),1)=4,IF(4=1,"Biorrizas",IF(4=2,"—",IF(4=3,"—",IF(4=4,"Biorrizas","")))),IF(4=1,"—",IF(4=2,"—",IF(4=3,"—",IF(4=4,"—",""))))))))))) | K10: =IF('🌱 Configuração'!$B$56="","",IF(4<1,"",IF(4>'🌱 Configuração'!$H$6,"",IF(IFERROR(MATCH('🌱 Configuração'!$H$12,{"BioBizz","Remo Nutrients","General Organics","SuperSoil","Genérico"},0),1)=1,IF(4=1,"6.2–6.5",IF(4=2,"6.2–6.5",IF(4=3,"6.2–6.5",IF(4=4,"6.2–6.5","")))),IF(IFERROR(MATCH('🌱 Configuração'!$H$12,{"BioBizz","Remo Nutrients","General Organics","SuperSoil","Genérico"},0),1)=2,IF(4=1,"5.8–6.0",IF(4=2,"5.8–6.0",IF(4=3,"5.8–6.2",IF(4=4,"5.8–6.2","")))),IF(IFERROR(MATCH('🌱 Configuração'!$H$12,{"BioBizz","Remo Nutrients","General Organics","SuperSoil","Genérico"},0),1)=3,IF(4=1,"6.2–7.0",IF(4=2,"6.2–7.0",IF(4=3,"6.2–7.0",IF(4=4,"6.2–7.0","")))),IF(IFERROR(MATCH('🌱 Configuração'!$H$12,{"BioBizz","Remo Nutrients","General Organics","SuperSoil","Genérico"},0),1)=4,IF(4=1,"auto",IF(4=2,"auto",IF(4=3,"auto",IF(4=4,"auto","")))),IF(4=1,"—",IF(4=2,"—",IF(4=3,"—",IF(4=4,"—",""))))))))))) | L10: =IF('🌱 Configuração'!$B$56="","",IF(4<1,"",IF(4>'🌱 Configuração'!$H$6,"",IF(IFERROR(MATCH('🌱 Configuração'!$H$12,{"BioBizz","Remo Nutrients","General Organics","SuperSoil","Genérico"},0),1)=1,IF(4=1,"baixo",IF(4=2,"baixo",IF(4=3,"baixo",IF(4=4,"baixo","")))),IF(IFERROR(MATCH('🌱 Configuração'!$H$12,{"BioBizz","Remo Nutrients","General Organics","SuperSoil","Genérico"},0),1)=2,IF(4=1,"baixo",IF(4=2,"baixo",IF(4=3,"0.4",IF(4=4,"0.6","")))),IF(IFERROR(MATCH('🌱 Configuração'!$H$12,{"BioBizz","Remo Nutrients","General Organics","SuperSoil","Genérico"},0),1)=3,IF(4=1,"baixo",IF(4=2,"baixo",IF(4=3,"baixo",IF(4=4,"baixo","")))),IF(IFERROR(MATCH('🌱 Configuração'!$H$12,{"BioBizz","Remo Nutrients","General Organics","SuperSoil","Genérico"},0),1)=4,IF(4=1,"auto",IF(4=2,"auto",IF(4=3,"auto",IF(4=4,"auto","")))),IF(4=1,"—",IF(4=2,"—",IF(4=3,"—",IF(4=4,"—",""))))))))))) | M10: =IF('🌱 Configuração'!$B$56="","",IF(4<1,"",IF(4>'🌱 Configuração'!$H$6,"",IF(IFERROR(MATCH('🌱 Configuração'!$H$12,{"BioBizz","Remo Nutrients","General Organics","SuperSoil","Genérico"},0),1)=1,IF(4=1,"Solo úmido — estimular raízes",IF(4=2,"Alg·A·Mic recupera e fortalece",IF(4=3,"Início suave de N antes da vega",IF(4=4,"Pronto para vegetativo","")))),IF(IFERROR(MATCH('🌱 Configuração'!$H$12,{"BioBizz","Remo Nutrients","General Organics","SuperSoil","Genérico"},0),1)=2,IF(4=1,"Roots = estimulador de raízes Remo",IF(4=2,"Magnifical = CalMag Remo",IF(4=3,"Introduzir base suave antes da vega",IF(4=4,"Pronto para vega — confirmar raízes","")))),IF(IFERROR(MATCH('🌱 Configuração'!$H$12,{"BioBizz","Remo Nutrients","General Organics","SuperSoil","Genérico"},0),1)=3,IF(4=1,"GO não precisa ajustar pH em solo",IF(4=2,"BioWeed = extrato de algas GO",IF(4=3,"Introduzir BioThrive Grow suave",IF(4=4,"Pronto para vega","")))),IF(IFERROR(MATCH('🌱 Configuração'!$H$12,{"BioBizz","Remo Nutrients","General Organics","SuperSoil","Genérico"},0),1)=4,IF(4=1,"Solo vivo — sem adubação química",IF(4=2,"Manter solo úmido e vivo",IF(4=3,"Farinha de alga = fósforo e K suave",IF(4=4,"Mel de cana alimenta microbioma","")))),IF(4=1,"Personalize suas doses",IF(4=2,"Personalize suas doses",IF(4=3,"Personalize suas doses",IF(4=4,"Personalize suas doses","")))))))))))
B12: 🌿 VEGETATIVO
B13: Semana | C13: Data início | D13: Produto 1 | E13: Dose 1 | F13: Produto 2 | G13: Dose 2 | H13: Produto 3 | I13: Dose 3 | J13: Suplemento | K13: pH alvo | L13: EC alvo | M13: Observação
B14: =IF(1<='🌱 Configuração'!$H$7,"S1","—") -> S1 | C14: =IF(1<='🌱 Configuração'!$H$7,'🌱 Configuração'!$C$56+0,"") -> 14 | D14: =IF('🌱 Configuração'!$C$56="","",IF(1<1,"",IF(1>'🌱 Configuração'!$H$7,"",IF(IFERROR(MATCH('🌱 Configuração'!$H$12,{"BioBizz","Remo Nutrients","General Organics","SuperSoil","Genérico"},0),1)=1,IF(1=1,"Bio·Grow",IF(1=2,"Bio·Grow",IF(1=3,"Bio·Grow",IF(1=4,"Bio·Grow",IF(1=5,"Bio·Grow",IF(1=6,"Bio·Grow",IF(1=7,"Bio·Grow",IF(1=8,"Bio·Grow","")))))))),IF(IFERROR(MATCH('🌱 Configuração'!$H$12,{"BioBizz","Remo Nutrients","General Organics","SuperSoil","Genérico"},0),1)=2,IF(1=1,"Micro",IF(1=2,"Micro",IF(1=3,"Micro",IF(1=4,"Micro",IF(1=5,"Micro",IF(1=6,"Micro",IF(1=7,"Micro",IF(1=8,"Micro","")))))))),IF(IFERROR(MATCH('🌱 Configuração'!$H$12,{"BioBizz","Remo Nutrients","General Organics","SuperSoil","Genérico"},0),1)=3,IF(1=1,"BioThrive G",IF(1=2,"BioThrive G",IF(1=3,"BioThrive G",IF(1=4,"BioThrive G",IF(1=5,"BioThrive G",IF(1=6,"BioThrive G",IF(1=7,"BioThrive G",IF(1=8,"BioThrive G","")))))))),IF(IFERROR(MATCH('🌱 Configuração'!$H$12,{"BioBizz","Remo Nutrients","General Organics","SuperSoil","Genérico"},0),1)=4,IF(1=1,"Chá de compostagem",IF(1=2,"Cobertura: torta de mamona",IF(1=3,"Molasses 2 mL/L",IF(1=4,"Chá de compostagem",IF(1=5,"Cobertura: farinha de alga",IF(1=6,"Molasses 2 mL/L",IF(1=7,"Cobertura: farinha de osso",IF(1=8,"Chá de compostagem","")))))))),IF(1=1,"← Preencha",IF(1=2,"← Preencha",IF(1=3,"← Preencha",IF(1=4,"← Preencha",IF(1=5,"← Preencha",IF(1=6,"← Preencha",IF(1=7,"← Preencha",IF(1=8,"← Preencha",""))))))))))))))) -> Bio·Grow | E14: =IF('🌱 Configuração'!$C$56="","",IF(1<1,"",IF(1>'🌱 Configuração'!$H$7,"",IF(IFERROR(MATCH('🌱 Configuração'!$H$12,{"BioBizz","Remo Nutrients","General Organics","SuperSoil","Genérico"},0),1)=1,IF(1=1,"1 mL/L",IF(1=2,"2 mL/L",IF(1=3,"2 mL/L",IF(1=4,"3 mL/L",IF(1=5,"4 mL/L",IF(1=6,"4 mL/L",IF(1=7,"4 mL/L",IF(1=8,"4 mL/L","")))))))),IF(IFERROR(MATCH('🌱 Configuração'!$H$12,{"BioBizz","Remo Nutrients","General Organics","SuperSoil","Genérico"},0),1)=2,IF(1=1,"1.3 mL/L",IF(1=2,"1.5 mL/L",IF(1=3,"1.8 mL/L",IF(1=4,"2.1 mL/L",IF(1=5,"2.1 mL/L",IF(1=6,"2.1 mL/L",IF(1=7,"2.1 mL/L",IF(1=8,"2.1 mL/L","")))))))),IF(IFERROR(MATCH('🌱 Configuração'!$H$12,{"BioBizz","Remo Nutrients","General Organics","SuperSoil","Genérico"},0),1)=3,IF(1=1,"1.3 mL/L",IF(1=2,"2.6 mL/L",IF(1=3,"2.6 mL/L",IF(1=4,"2.6 mL/L",IF(1=5,"2.6 mL/L",IF(1=6,"2.6 mL/L",IF(1=7,"1.3 mL/L",IF(1=8,"1.3 mL/L","")))))))),IF(IFERROR(MATCH('🌱 Configuração'!$H$12,{"BioBizz","Remo Nutrients","General Organics","SuperSoil","Genérico"},0),1)=4,IF(1=1,"2L/planta",IF(1=2,"10g/vaso",IF(1=3,"—",IF(1=4,"2L/planta",IF(1=5,"5g/L solo",IF(1=6,"—",IF(1=7,"10g/vaso",IF(1=8,"2L/planta","")))))))),IF(1=1,"—",IF(1=2,"—",IF(1=3,"—",IF(1=4,"—",IF(1=5,"—",IF(1=6,"—",IF(1=7,"—",IF(1=8,"—",""))))))))))))))) -> 1 mL/L | F14: =IF('🌱 Configuração'!$C$56="","",IF(1<1,"",IF(1>'🌱 Configuração'!$H$7,"",IF(IFERROR(MATCH('🌱 Configuração'!$H$12,{"BioBizz","Remo Nutrients","General Organics","SuperSoil","Genérico"},0),1)=1,IF(1=1,"Fish·Mix",IF(1=2,"Fish·Mix",IF(1=3,"Fish·Mix",IF(1=4,"Fish·Mix",IF(1=5,"Fish·Mix",IF(1=6,"—",IF(1=7,"Bio·Bloom",IF(1=8,"Bio·Bloom","")))))))),IF(IFERROR(MATCH('🌱 Configuração'!$H$12,{"BioBizz","Remo Nutrients","General Organics","SuperSoil","Genérico"},0),1)=2,IF(1=1,"Grow",IF(1=2,"Grow",IF(1=3,"Grow",IF(1=4,"Grow",IF(1=5,"Grow",IF(1=6,"Grow",IF(1=7,"Grow",IF(1=8,"Grow","")))))))),IF(IFERROR(MATCH('🌱 Configuração'!$H$12,{"BioBizz","Remo Nutrients","General Organics","SuperSoil","Genérico"},0),1)=3,IF(1=1,"BioRoot",IF(1=2,"BioRoot",IF(1=3,"BioRoot",IF(1=4,"BioRoot",IF(1=5,"CaMg+",IF(1=6,"BioThrive B",IF(1=7,"BioThrive B",IF(1=8,"BioThrive B","")))))))),IF(IFERROR(MATCH('🌱 Configuração'!$H$12,{"BioBizz","Remo Nutrients","General Organics","SuperSoil","Genérico"},0),1)=4,IF(1=1,"—",IF(1=2,"Cobertura: farinha de osso",IF(1=3,"—",IF(1=4,"—",IF(1=5,"Cobertura: cinzas de madeira",IF(1=6,"—",IF(1=7,"Cobertura: guano de morcego",IF(1=8,"—","")))))))),IF(1=1,"—",IF(1=2,"—",IF(1=3,"—",IF(1=4,"—",IF(1=5,"—",IF(1=6,"—",IF(1=7,"—",IF(1=8,"—",""))))))))))))))) -> Fish·Mix | G14: =IF('🌱 Configuração'!$C$56="","",IF(1<1,"",IF(1>'🌱 Configuração'!$H$7,"",IF(IFERROR(MATCH('🌱 Configuração'!$H$12,{"BioBizz","Remo Nutrients","General Organics","SuperSoil","Genérico"},0),1)=1,IF(1=1,"1 mL/L",IF(1=2,"2 mL/L",IF(1=3,"2 mL/L",IF(1=4,"3 mL/L",IF(1=5,"3 mL/L",IF(1=6,"—",IF(1=7,"1 mL/L",IF(1=8,"2 mL/L","")))))))),IF(IFERROR(MATCH('🌱 Configuração'!$H$12,{"BioBizz","Remo Nutrients","General Organics","SuperSoil","Genérico"},0),1)=2,IF(1=1,"1.3 mL/L",IF(1=2,"1.5 mL/L",IF(1=3,"1.8 mL/L",IF(1=4,"2.1 mL/L",IF(1=5,"2.1 mL/L",IF(1=6,"2.1 mL/L",IF(1=7,"1.0 mL/L",IF(1=8,"0.5 mL/L","")))))))),IF(IFERROR(MATCH('🌱 Configuração'!$H$12,{"BioBizz","Remo Nutrients","General Organics","SuperSoil","Genérico"},0),1)=3,IF(1=1,"2.6 mL/L",IF(1=2,"2.6 mL/L",IF(1=3,"2.6 mL/L",IF(1=4,"1.3 mL/L",IF(1=5,"1.3 mL/L",IF(1=6,"1.3 mL/L",IF(1=7,"2.6 mL/L",IF(1=8,"2.6 mL/L","")))))))),IF(IFERROR(MATCH('🌱 Configuração'!$H$12,{"BioBizz","Remo Nutrients","General Organics","SuperSoil","Genérico"},0),1)=4,IF(1=1,"—",IF(1=2,"10g/vaso",IF(1=3,"—",IF(1=4,"—",IF(1=5,"3g/L",IF(1=6,"—",IF(1=7,"5g/L",IF(1=8,"—","")))))))),IF(1=1,"—",IF(1=2,"—",IF(1=3,"—",IF(1=4,"—",IF(1=5,"—",IF(1=6,"—",IF(1=7,"—",IF(1=8,"—",""))))))))))))))) -> 1 mL/L | H14: =IF('🌱 Configuração'!$C$56="","",IF(1<1,"",IF(1>'🌱 Configuração'!$H$7,"",IF(IFERROR(MATCH('🌱 Configuração'!$H$12,{"BioBizz","Remo Nutrients","General Organics","SuperSoil","Genérico"},0),1)=1,IF(1=1,"—",IF(1=2,"—",IF(1=3,"—",IF(1=4,"—",IF(1=5,"—",IF(1=6,"—",IF(1=7,"—",IF(1=8,"—","")))))))),IF(IFERROR(MATCH('🌱 Configuração'!$H$12,{"BioBizz","Remo Nutrients","General Organics","SuperSoil","Genérico"},0),1)=2,IF(1=1,"—",IF(1=2,"—",IF(1=3,"—",IF(1=4,"—",IF(1=5,"—",IF(1=6,"Bloom",IF(1=7,"Bloom",IF(1=8,"Bloom","")))))))),IF(IFERROR(MATCH('🌱 Configuração'!$H$12,{"BioBizz","Remo Nutrients","General Organics","SuperSoil","Genérico"},0),1)=3,IF(1=1,"CaMg+",IF(1=2,"CaMg+",IF(1=3,"CaMg+",IF(1=4,"CaMg+",IF(1=5,"—",IF(1=6,"CaMg+",IF(1=7,"CaMg+",IF(1=8,"CaMg+","")))))))),IF(IFERROR(MATCH('🌱 Configuração'!$H$12,{"BioBizz","Remo Nutrients","General Organics","SuperSoil","Genérico"},0),1)=4,IF(1=1,"—",IF(1=2,"—",IF(1=3,"—",IF(1=4,"—",IF(1=5,"—",IF(1=6,"—",IF(1=7,"—",IF(1=8,"—","")))))))),IF(1=1,"—",IF(1=2,"—",IF(1=3,"—",IF(1=4,"—",IF(1=5,"—",IF(1=6,"—",IF(1=7,"—",IF(1=8,"—",""))))))))))))))) -> — | I14: =IF('🌱 Configuração'!$C$56="","",IF(1<1,"",IF(1>'🌱 Configuração'!$H$7,"",IF(IFERROR(MATCH('🌱 Configuração'!$H$12,{"BioBizz","Remo Nutrients","General Organics","SuperSoil","Genérico"},0),1)=1,IF(1=1,"—",IF(1=2,"—",IF(1=3,"—",IF(1=4,"—",IF(1=5,"—",IF(1=6,"—",IF(1=7,"—",IF(1=8,"—","")))))))),IF(IFERROR(MATCH('🌱 Configuração'!$H$12,{"BioBizz","Remo Nutrients","General Organics","SuperSoil","Genérico"},0),1)=2,IF(1=1,"—",IF(1=2,"—",IF(1=3,"—",IF(1=4,"—",IF(1=5,"—",IF(1=6,"1.0 mL/L",IF(1=7,"2.1 mL/L",IF(1=8,"2.1 mL/L","")))))))),IF(IFERROR(MATCH('🌱 Configuração'!$H$12,{"BioBizz","Remo Nutrients","General Organics","SuperSoil","Genérico"},0),1)=3,IF(1=1,"1.3 mL/L",IF(1=2,"1.3 mL/L",IF(1=3,"1.3 mL/L",IF(1=4,"1.3 mL/L",IF(1=5,"—",IF(1=6,"1.3 mL/L",IF(1=7,"1.3 mL/L",IF(1=8,"1.3 mL/L","")))))))),IF(IFERROR(MATCH('🌱 Configuração'!$H$12,{"BioBizz","Remo Nutrients","General Organics","SuperSoil","Genérico"},0),1)=4,IF(1=1,"—",IF(1=2,"—",IF(1=3,"—",IF(1=4,"—",IF(1=5,"—",IF(1=6,"—",IF(1=7,"—",IF(1=8,"—","")))))))),IF(1=1,"—",IF(1=2,"—",IF(1=3,"—",IF(1=4,"—",IF(1=5,"—",IF(1=6,"—",IF(1=7,"—",IF(1=8,"—",""))))))))))))))) -> — | J14: =IF('🌱 Configuração'!$C$56="","",IF(1<1,"",IF(1>'🌱 Configuração'!$H$7,"",IF(IFERROR(MATCH('🌱 Configuração'!$H$12,{"BioBizz","Remo Nutrients","General Organics","SuperSoil","Genérico"},0),1)=1,IF(1=1,"Alg·A·Mic 1mL",IF(1=2,"—",IF(1=3,"Alg·A·Mic 1mL",IF(1=4,"—",IF(1=5,"Alg·A·Mic 1mL",IF(1=6,"—",IF(1=7,"—",IF(1=8,"—","")))))))),IF(IFERROR(MATCH('🌱 Configuração'!$H$12,{"BioBizz","Remo Nutrients","General Organics","SuperSoil","Genérico"},0),1)=2,IF(1=1,"Magnifical 0.5",IF(1=2,"Magnifical 0.5",IF(1=3,"Magnifical 1.0",IF(1=4,"Magnifical 1.0",IF(1=5,"Magnifical 1.0",IF(1=6,"Magnifical 1.0",IF(1=7,"—",IF(1=8,"—","")))))))),IF(IFERROR(MATCH('🌱 Configuração'!$H$12,{"BioBizz","Remo Nutrients","General Organics","SuperSoil","Genérico"},0),1)=3,IF(1=1,"BioWeed 0.7",IF(1=2,"BioWeed 0.7",IF(1=3,"—",IF(1=4,"—",IF(1=5,"—",IF(1=6,"—",IF(1=7,"—",IF(1=8,"—","")))))))),IF(IFERROR(MATCH('🌱 Configuração'!$H$12,{"BioBizz","Remo Nutrients","General Organics","SuperSoil","Genérico"},0),1)=4,IF(1=1,"Vermicomposto",IF(1=2,"—",IF(1=3,"—",IF(1=4,"—",IF(1=5,"—",IF(1=6,"Microrganismos",IF(1=7,"—",IF(1=8,"—","")))))))),IF(1=1,"—",IF(1=2,"—",IF(1=3,"—",IF(1=4,"—",IF(1=5,"—",IF(1=6,"—",IF(1=7,"—",IF(1=8,"—",""))))))))))))))) -> Alg·A·Mic 1mL | K14: =IF('🌱 Configuração'!$C$56="","",IF(1<1,"",IF(1>'🌱 Configuração'!$H$7,"",IF(IFERROR(MATCH('🌱 Configuração'!$H$12,{"BioBizz","Remo Nutrients","General Organics","SuperSoil","Genérico"},0),1)=1,IF(1=1,"6.2–6.5",IF(1=2,"6.2–6.5",IF(1=3,"6.2–6.5",IF(1=4,"6.2–6.5",IF(1=5,"6.2–6.5",IF(1=6,"6.2–6.5",IF(1=7,"6.2–6.5",IF(1=8,"6.2–6.5","")))))))),IF(IFERROR(MATCH('🌱 Configuração'!$H$12,{"BioBizz","Remo Nutrients","General Organics","SuperSoil","Genérico"},0),1)=2,IF(1=1,"6.0–6.3",IF(1=2,"6.0–6.3",IF(1=3,"6.0–6.3",IF(1=4,"6.0–6.3",IF(1=5,"6.0–6.3",IF(1=6,"6.0–6.3",IF(1=7,"6.0–6.3",IF(1=8,"6.0–6.3","")))))))),IF(IFERROR(MATCH('🌱 Configuração'!$H$12,{"BioBizz","Remo Nutrients","General Organics","SuperSoil","Genérico"},0),1)=3,IF(1=1,"6.2–7.0",IF(1=2,"6.2–7.0",IF(1=3,"6.2–7.0",IF(1=4,"6.2–7.0",IF(1=5,"6.2–7.0",IF(1=6,"6.2–7.0",IF(1=7,"6.2–7.0",IF(1=8,"6.2–7.0","")))))))),IF(IFERROR(MATCH('🌱 Configuração'!$H$12,{"BioBizz","Remo Nutrients","General Organics","SuperSoil","Genérico"},0),1)=4,IF(1=1,"auto",IF(1=2,"auto",IF(1=3,"auto",IF(1=4,"auto",IF(1=5,"auto",IF(1=6,"auto",IF(1=7,"auto",IF(1=8,"auto","")))))))),IF(1=1,"—",IF(1=2,"—",IF(1=3,"—",IF(1=4,"—",IF(1=5,"—",IF(1=6,"—",IF(1=7,"—",IF(1=8,"—",""))))))))))))))) -> 6.2–6.5 | L14: =IF('🌱 Configuração'!$C$56="","",IF(1<1,"",IF(1>'🌱 Configuração'!$H$7,"",IF(IFERROR(MATCH('🌱 Configuração'!$H$12,{"BioBizz","Remo Nutrients","General Organics","SuperSoil","Genérico"},0),1)=1,IF(1=1,"0.8",IF(1=2,"1.0",IF(1=3,"1.2",IF(1=4,"1.4",IF(1=5,"1.5",IF(1=6,"1.4",IF(1=7,"1.4",IF(1=8,"1.4","")))))))),IF(IFERROR(MATCH('🌱 Configuração'!$H$12,{"BioBizz","Remo Nutrients","General Organics","SuperSoil","Genérico"},0),1)=2,IF(1=1,"0.8",IF(1=2,"1.0",IF(1=3,"1.2",IF(1=4,"1.4",IF(1=5,"1.5",IF(1=6,"1.5",IF(1=7,"1.4",IF(1=8,"1.4","")))))))),IF(IFERROR(MATCH('🌱 Configuração'!$H$12,{"BioBizz","Remo Nutrients","General Organics","SuperSoil","Genérico"},0),1)=3,IF(1=1,"N/A",IF(1=2,"N/A",IF(1=3,"N/A",IF(1=4,"N/A",IF(1=5,"N/A",IF(1=6,"N/A",IF(1=7,"N/A",IF(1=8,"N/A","")))))))),IF(IFERROR(MATCH('🌱 Configuração'!$H$12,{"BioBizz","Remo Nutrients","General Organics","SuperSoil","Genérico"},0),1)=4,IF(1=1,"auto",IF(1=2,"auto",IF(1=3,"auto",IF(1=4,"auto",IF(1=5,"auto",IF(1=6,"auto",IF(1=7,"auto",IF(1=8,"auto","")))))))),IF(1=1,"—",IF(1=2,"—",IF(1=3,"—",IF(1=4,"—",IF(1=5,"—",IF(1=6,"—",IF(1=7,"—",IF(1=8,"—",""))))))))))))))) -> 0.8 | M14: =IF('🌱 Configuração'!$C$56="","",IF(1<1,"",IF(1>'🌱 Configuração'!$H$7,"",IF(IFERROR(MATCH('🌱 Configuração'!$H$12,{"BioBizz","Remo Nutrients","General Organics","SuperSoil","Genérico"},0),1)=1,IF(1=1,"Fish·Mix em veg = mais N orgânico",IF(1=2,"Aumentar progressivamente",IF(1=3,"Foliar: Fish·Mix + Alg·A·Mic 1mL/L",IF(1=4,"LST / estrutura vegetativa",IF(1=5,"Pré-floração — reduzir Fish·Mix",IF(1=6,"Substituir Fish·Mix por Bio·Grow antes da flora",IF(1=7,"Semana de transição — introduzir Bloom",IF(1=8,"Semana extra de vega","")))))))),IF(IFERROR(MATCH('🌱 Configuração'!$H$12,{"BioBizz","Remo Nutrients","General Organics","SuperSoil","Genérico"},0),1)=2,IF(1=1,"Micro+Grow = base Remo para vega",IF(1=2,"Aumentar conforme tabela oficial",IF(1=3,"Semana 3 da tabela Remo",IF(1=4,"Semana 4 da tabela Remo — pico vega",IF(1=5,"Manter se continuar vega",IF(1=6,"Introduzir Bloom — transição",IF(1=7,"Reduzir Grow, aumentar Bloom",IF(1=8,"Semana extra de vega","")))))))),IF(IFERROR(MATCH('🌱 Configuração'!$H$12,{"BioBizz","Remo Nutrients","General Organics","SuperSoil","Genérico"},0),1)=3,IF(1=1,"GO não requer EC — pH auto-regula",IF(1=2,"Sem necessidade de ajuste pH em solo",IF(1=3,"Semana 3 veg GO",IF(1=4,"Reduzir BioRoot gradualmente",IF(1=5,"Manter Grow puro na vega",IF(1=6,"Semana transição — introduzir Bloom",IF(1=7,"Transição flora — reduzir Grow",IF(1=8,"Semana extra de vega GO","")))))))),IF(IFERROR(MATCH('🌱 Configuração'!$H$12,{"BioBizz","Remo Nutrients","General Organics","SuperSoil","Genérico"},0),1)=4,IF(1=1,"SuperSoil já contém todos os nutrientes",IF(1=2,"Torta de mamona = N lento | Osso = P",IF(1=3,"Mel de cana alimenta fungos e bactérias",IF(1=4,"Observar vigor — solo vivo trabalha",IF(1=5,"Alga = micro. | Cinzas = K e Ca",IF(1=6,"Pré-flora — ativar P e K no solo",IF(1=7,"Guano P alto = preparo para flora",IF(1=8,"Semana extra de vega SuperSoil","")))))))),IF(1=1,"Personalize suas doses",IF(1=2,"Personalize suas doses",IF(1=3,"Personalize suas doses",IF(1=4,"Personalize suas doses",IF(1=5,"Personalize suas doses",IF(1=6,"Personalize suas doses",IF(1=7,"Personalize suas doses",IF(1=8,"Personalize suas doses",""))))))))))))))) -> Fish·Mix em veg = mais N orgânico
