Workbook

Sheet 🌱 Configuração
B2: 🌿 PLANILHA MESTRA DE CULTIVO — Cannabis Medicinal Indoor v3
B3: Configure abaixo. Toda a planilha se recalcula automaticamente.
B5: ⚙️ CONFIGURAÇÕES GERAIS
B6: 📅 Data Dia 1 (Clone) | F6: 🌱 Semanas de Clone | H6: 2 | J6: ← semanas
B7: 🌿 Strain / Cultivar | D7: Ex: OG Kush | F7: 🌿 Semanas de Vegetativo | H7: 6 | J7: ← semanas
B8: 💡 Ambiente | D8: Indoor LED | F8: 🌸 Semanas de Floração | H8: 9 | J8: ← semanas
B9: 📐 Área (m²) | D9: 1.2 | F9: 🚿 Semanas de Flush | H9: 1 | J9: ← semanas
B10: 🪴 Nº de Plantas | D10: 4
B11: 💊 PROTOCOLO DE NUTRIÇÃO — Escolha sua linha de produtos
B12: 🧪 Linha de Adubação | H12: BioBizz | J12: ← Escolha no dropdown
B13: BioBizz | D13: Orgânico certificado (Holanda). Solo. Produtos: Bio·Grow, Bio·Bloom, Top·Max, Fish·Mix, Root Juice, Alg·A·Mic. pH: 6.2–6.5
B14: Remo Nutrients | D14: Mineral/orgânico (Canadá). Solo, coco, hidro. Produtos: Micro, Grow, Bloom, Magnifical, Astroflower, Kelp, Roots. pH: 5.8–6.3
B15: General Organics | D15: GO Box da GH (EUA). Solo orgânico. Produtos: BioThrive Grow/Bloom, BioRoot, BioBud, BioWeed, CaMg+, BioMarine. pH: auto
B16: SuperSoil | D16: Solo vivo preparado. Coberturas secas: farinha de osso, torta de mamona, guano de morcego, farinha de alga, cinzas. pH: auto
B17: Genérico | D17: Campos em branco para você preencher com seus próprios produtos e doses. Totalmente personalizável.
B19: 📆 CALENDÁRIO DE FASES (automático)
B20: Fase | D20: Semanas | F20: Início | H20: Fim | J20: Total dias
B21: 🌱 CLONE | D21: =H6&" sem" -> 2 sem | F21: =B56 -> 0 | H21: =B56+B55-1 -> 13 | J21: =B55 -> 14
B22: 🌿 VEGETATIVO | D22: =H7&" sem" -> 6 sem | F22: =C56 -> 14 | H22: =C56+C55-1 -> 55 | J22: =C55 -> 42
B23: 🌸 FLORAÇÃO | D23: =H8&" sem" -> 9 sem | F23: =D56 -> 56 | H23: =D56+D55-1 -> 118 | J23: =D55 -> 63
B24: 🚿 FLUSH | D24: =H9&" sem" -> 1 sem | F24: =E56 -> 119 | H24: =E56+E55-1 -> 125 | J24: =E55 -> 7
B25: ✂️ COLHEITA | D25: "—" | F25: =F56 -> 126 | H25: =F56 -> 126 | J25: "1 dia"
B55: =H6*7 -> 14 | C55: =H7*7 -> 42 | D55: =H8*7 -> 63 | E55: =H9*7 -> 7 | F55: =B55+C55+D55+E55 -> 126
B56: =D6 -> 0 | C56: =B56+B55 -> 14 | D56: =C56+C55 -> 56 | E56: =D56+D55 -> 119 | F56: =E56+E55 -> 126

Sheet 📅 Cronograma
B2: 📅 CRONOGRAMA COMPLETO DO CULTIVO — Dinâmico por Semanas
B3: Adubação e MIP mostrados apenas no 1º dia de cada semana. Consulte as abas específicas para detalhes e doses completas.
B5: Dia | C5: Data | D5: Fase | E5: Semana | F5: Ação / Marco | G5: 💊 Adubação | H5: 🐛 MIP — Pragas
B6: =IF(1<='🌱 Configuração'!$F$55,1,"") -> 1 | C6: =IF(1<='🌱 Configuração'!$F$55,'🌱 Configuração'!$B$56+0,"") -> 0 | D6: =IF(1>'🌱 Configuração'!$F$55,"",IF('🌱 Configuração'!$B$56+0<'🌱 Configuração'!$C$56,"🌱 Clone",IF('🌱 Configuração'!$B$56+0<'🌱 Configuração'!$D$56,"🌿 Vegetativo",IF('🌱 Configuração'!$B$56+0<'🌱 Configuração'!$E$56,"🌸 Floração","🚿 Flush")))) -> 🌱 Clone | E6: =IF(1>'🌱 Configuração'!$F$55,"",IF('🌱 Configuração'!$B$56+0<'🌱 Configuração'!$C$56,"Clone S"&INT((1-1)/7)+1,IF('🌱 Configuração'!$B$56+0<'🌱 Configuração'!$D$56,"Vega S"&INT(('🌱 Configuração'!$B$56+0-'🌱 Configuração'!$C$56)/7)+1,IF('🌱 Configuração'!$B$56+0<'🌱 Configuração'!$E$56,"Flora S"&INT(('🌱 Configuração'!$B$56+0-'🌱 Configuração'!$D$56)/7)+1,"Flush S"&INT(('🌱 Configuração'!$B$56+0-'🌱 Configuração'!$E$56)/7)+1)))) -> Clone S1 | F6: =IF(1>'🌱 Configuração'!$F$55,"",IF('🌱 Configuração'!$B$56+0='🌱 Configuração'!$C$56,"🌿 INÍCIO VEGA — luz 18h/dia",IF('🌱 Configuração'!$B$56+0='🌱 Configuração'!$D$56,"🌸 INÍCIO FLORAÇÃO — mudar 12/12 🔴",IF('🌱 Configuração'!$B$56+0='🌱 Configuração'!$E$56,"🚿 INÍCIO FLUSH — parar nutrição",IF('🌱 Configuração'!$B$56+0='🌱 Configuração'!$F$56-1,"🔬 Véspera da colheita — analisar tricomas",IF('🌱 Configuração'!$B$56+0='🌱 Configuração'!$F$56,"✂️ COLHEITA — Parabéns! 🎉","")))))) | G6: Root Juice 0.3 mL/L | H6: =IF(1>'🌱 Configuração'!$F$55,"",IF('🌱 Configuração'!$B$56+0<'🌱 Configuração'!$C$56,IF(1=1,"🌿 Nim (2 mL/L) — foliar leve",IF(1=8,"🍄 Beauveria bassiana — foliar + solo","")),IF('🌱 Configuração'!$B$56+0<'🌱 Configuração'!$D$56,IF(AND('🌱 Configuração'!$B$56+0>='🌱 Configuração'!$C$56,'🌱 Configuração'!$B$56+0<'🌱 Configuração'!$D$56,MOD('🌱 Configuração'!$B$56+0-'🌱 Configuração'!$C$56,7)=0,INT(('🌱 Configuração'!$B$56+0-'🌱 Configuração'!$C$56)/7)+1=1),"🌿 Nim (2 mL/L) — foliar preventivo",IF(AND('🌱 Configuração'!$B$56+0>='🌱 Configuração'!$C$56,'🌱 Configuração'!$B$56+0<'🌱 Configuração'!$D$56,MOD('🌱 Configuração'!$B$56+0-'🌱 Configuração'!$C$56,7)=0,INT(('🌱 Configuração'!$B$56+0-'🌱 Configuração'!$C$56)/7)+1=2),"🍄 Beauveria bassiana — foliar + solo",IF(AND('🌱 Configuração'!$B$56+0>='🌱 Configuração'!$C$56,'🌱 Configuração'!$B$56+0<'🌱 Configuração'!$D$56,MOD('🌱 Configuração'!$B$56+0-'🌱 Configuração'!$C$56,7)=0,INT(('🌱 Configuração'!$B$56+0-'🌱 Configuração'!$C$56)/7)+1=3),"🟡 Calda Sulfocálcica (1%) — foliar",IF(AND('🌱 Configuração'!$B$56+0>='🌱 Configuração'!$C$56,'🌱 Configuração'!$B$56+0<'🌱 Configuração'!$D$56,MOD('🌱 Configuração'!$B$56+0-'🌱 Configuração'!$C$56,7)=0,INT(('🌱 Configuração'!$B$56+0-'🌱 Configuração'!$C$56)/7)+1=4),"🦠 Trichoderma (3 g/L) — solo",IF(AND('🌱 Configuração'!$B$56+0>='🌱 Configuração'!$C$56,'🌱 Configuração'!$B$56+0<'🌱 Configuração'!$D$56,MOD('🌱 Configuração'!$B$56+0-'🌱 Configuração'!$C$56,7)=0,INT(('🌱 Configuração'!$B$56+0-'🌱 Configuração'!$C$56)/7)+1=5),"🔵 Calda Bordalesa (0.5%) — foliar",IF(AND('🌱 Configuração'!$B$56+0>='🌱 Configuração'!$C$56,'🌱 Configuração'!$B$56+0<'🌱 Configuração'!$D$56,MOD('🌱 Configuração'!$B$56+0-'🌱 Configuração'!$C$56,7)=0,INT(('🌱 Configuração'!$B$56+0-'🌱 Configuração'!$C$56)/7)+1=6),"🌿 Nim (2 mL/L) — ⚠️ ÚLTIMA foliar",IF(AND('🌱 Configuração'!$B$56+0>='🌱 Configuração'!$C$56,'🌱 Configuração'!$B$56+0<'🌱 Configuração'!$D$56,MOD('🌱 Configuração'!$B$56+0-'🌱 Configuração'!$C$56,7)=0,INT(('🌱 Configuração'!$B$56+0-'🌱 Configuração'!$C$56)/7)+1=7),"🦠 Trichoderma — solo",IF(AND('🌱 Configuração'!$B$56+0>='🌱 Configuração'!$C$56,'🌱 Configuração'!$B$56+0<'🌱 Configuração'!$D$56,MOD('🌱 Configuração'!$B$56+0-'🌱 Configuração'!$C$56,7)=0,INT(('🌱 Configuração'!$B$56+0-'🌱 Configuração'!$C$56)/7)+1=8),"🍄 Beauveria — solo","")))))))),IF('🌱 Configuração'!$B$56+0<'🌱 Configuração'!$E$56,IF(AND('🌱 Configuração'!$B$56+0>='🌱 Configuração'!$D$56,'🌱 Configuração'!$B$56+0<'🌱 Configuração'!$E$56,MOD('🌱 Configuração'!$B$56+0-'🌱 Configuração'!$D$56,7)=0,INT(('🌱 Configuração'!$B$56+0-'🌱 Configuração'!$D$56)/7)+1=1),"🍄 Beauveria bassiana — SOLO apenas",IF(AND('🌱 Configuração'!$B$56+0>='🌱 Configuração'!$D$56,'🌱 Configuração'!$B$56+0<'🌱 Configuração'!$E$56,MOD('🌱 Configuração'!$B$56+0-'🌱 Configuração'!$D$56,7)=0,INT(('🌱 Configuração'!$B$56+0-'🌱 Configuração'!$D$56)/7)+1=2),"🦠 Trichoderma (3 g/L) — solo",IF(AND('🌱 Configuração'!$B$56+0>='🌱 Configuração'!$D$56,'🌱 Configuração'!$B$56+0<'🌱 Configuração'!$E$56,MOD('🌱 Configuração'!$B$56+0-'🌱 Configuração'!$D$56,7)=0,INT(('🌱 Configuração'!$B$56+0-'🌱 Configuração'!$D$56)/7)+1=3),"🍄 Beauveria bassiana — solo | ⚠️ Umid <45%",IF(AND('🌱 Configuração'!$B$56+0>='🌱 Configuração'!$D$56,'🌱 Configuração'!$B$56+0<'🌱 Configuração'!$E$56,MOD('🌱 Configuração'!$B$56+0-'🌱 Configuração'!$D$56,7)=0,INT(('🌱 Configuração'!$B$56+0-'🌱 Configuração'!$D$56)/7)+1=4),"🦠 Trichoderma — solo | Inspecionar buds",IF(AND('🌱 Configuração'!$B$56+0>='🌱 Configuração'!$D$56,'🌱 Configuração'!$B$56+0<'🌱 Configuração'!$E$56,MOD('🌱 Configuração'!$B$56+0-'🌱 Configuração'!$D$56,7)=0,INT(('🌱 Configuração'!$B$56+0-'🌱 Configuração'!$D$56)/7)+1=5),"🍄 Beauveria + inspeção visual buds",IF(AND('🌱 Configuração'!$B$56+0>='🌱 Configuração'!$D$56,'🌱 Configuração'!$B$56+0<'🌱 Configuração'!$E$56,MOD('🌱 Configuração'!$B$56+0-'🌱 Configuração'!$D$56,7)=0,INT(('🌱 Configuração'!$B$56+0-'🌱 Configuração'!$D$56)/7)+1=6),"🦠 Trichoderma + ⚠️ Verificar mofo","")))))),IF(AND('🌱 Configuração'!$B$56+0>='🌱 Configuração'!$E$56,MOD('🌱 Configuração'!$B$56+0-'🌱 Configuração'!$E$56,7)=0),"🔬 Inspeção final — analisar tricomas",""))))) -> 🌿 Nim (2 mL/L) — foliar leve
B7: =IF(2<='🌱 Configuração'!$F$55,2,"") -> 2 | C7: =IF(2<='🌱 Configuração'!$F$55,'🌱 Configuração'!$B$56+1,"") -> 1 | D7: =IF(2>'🌱 Configuração'!$F$55,"",IF('🌱 Configuração'!$B$56+1<'🌱 Configuração'!$C$56,"🌱 Clone",IF('🌱 Configuração'!$B$56+1<'🌱 Configuração'!$D$56,"🌿 Vegetativo",IF('🌱 Configuração'!$B$56+1<'🌱 Configuração'!$E$56,"🌸 Floração","🚿 Flush")))) -> 🌱 Clone | E7: =IF(2>'🌱 Configuração'!$F$55,"",IF('🌱 Configuração'!$B$56+1<'🌱 Configuração'!$C$56,"Clone S"&INT((2-1)/7)+1,IF('🌱 Configuração'!$B$56+1<'🌱 Configuração'!$D$56,"Vega S"&INT(('🌱 Configuração'!$B$56+1-'🌱 Configuração'!$C$56)/7)+1,IF('🌱 Configuração'!$B$56+1<'🌱 Configuração'!$E$56,"Flora S"&INT(('🌱 Configuração'!$B$56+1-'🌱 Configuração'!$D$56)/7)+1,"Flush S"&INT(('🌱 Configuração'!$B$56+1-'🌱 Configuração'!$E$56)/7)+1)))) -> Clone S1 | F7: =IF(2>'🌱 Configuração'!$F$55,"",IF('🌱 Configuração'!$B$56+1='🌱 Configuração'!$C$56,"🌿 INÍCIO VEGA — luz 18h/dia",IF('🌱 Configuração'!$B$56+1='🌱 Configuração'!$D$56,"🌸 INÍCIO FLORAÇÃO — mudar 12/12 🔴",IF('🌱 Configuração'!$B$56+1='🌱 Configuração'!$E$56,"🚿 INÍCIO FLUSH — parar nutrição",IF('🌱 Configuração'!$B$56+1='🌱 Configuração'!$F$56-1,"🔬 Véspera da colheita — analisar tricomas",IF('🌱 Configuração'!$B$56+1='🌱 Configuração'!$F$56,"✂️ COLHEITA — Parabéns! 🎉","")))))) | H7: =IF(2>'🌱 Configuração'!$F$55,"",IF('🌱 Configuração'!$B$56+1<'🌱 Configuração'!$C$56,IF(2=1,"🌿 Nim (2 mL/L) — foliar leve",IF(2=8,"🍄 Beauveria bassiana — foliar + solo","")),IF('🌱 Configuração'!$B$56+1<'🌱 Configuração'!$D$56,IF(AND('🌱 Configuração'!$B$56+1>='🌱 Configuração'!$C$56,'🌱 Configuração'!$B$56+1<'🌱 Configuração'!$D$56,MOD('🌱 Configuração'!$B$56+1-'🌱 Configuração'!$C$56,7)=0,INT(('🌱 Configuração'!$B$56+1-'🌱 Configuração'!$C$56)/7)+1=1),"🌿 Nim (2 mL/L) — foliar preventivo",IF(AND('🌱 Configuração'!$B$56+1>='🌱 Configuração'!$C$56,'🌱 Configuração'!$B$56+1<'🌱 Configuração'!$D$56,MOD('🌱 Configuração'!$B$56+1-'🌱 Configuração'!$C$56,7)=0,INT(('🌱 Configuração'!$B$56+1-'🌱 Configuração'!$C$56)/7)+1=2),"🍄 Beauveria bassiana — foliar + solo",IF(AND('🌱 Configuração'!$B$56+1>='🌱 Configuração'!$C$56,'🌱 Configuração'!$B$56+1<'🌱 Configuração'!$D$56,MOD('🌱 Configuração'!$B$56+1-'🌱 Configuração'!$C$56,7)=0,INT(('🌱 Configuração'!$B$56+1-'🌱 Configuração'!$C$56)/7)+1=3),"🟡 Calda Sulfocálcica (1%) — foliar",IF(AND('🌱 Configuração'!$B$56+1>='🌱 Configuração'!$C$56,'🌱 Configuração'!$B$56+1<'🌱 Configuração'!$D$56,MOD('🌱 Configuração'!$B$56+1-'🌱 Configuração'!$C$56,7)=0,INT(('🌱 Configuração'!$B$56+1-'🌱 Configuração'!$C$56)/7)+1=4),"🦠 Trichoderma (3 g/L) — solo",IF(AND('🌱 Configuração'!$B$56+1>='🌱 Configuração'!$C$56,'🌱 Configuração'!$B$56+1<'🌱 Configuração'!$D$56,MOD('🌱 Configuração'!$B$56+1-'🌱 Configuração'!$C$56,7)=0,INT(('🌱 Configuração'!$B$56+1-'🌱 Configuração'!$C$56)/7)+1=5),"🔵 Calda Bordalesa (0.5%) — foliar",IF(AND('🌱 Configuração'!$B$56+1>='🌱 Configuração'!$C$56,'🌱 Configuração'!$B$56+1<'🌱 Configuração'!$D$56,MOD('🌱 Configuração'!$B$56+1-'🌱 Configuração'!$C$56,7)=0,INT(('🌱 Configuração'!$B$56+1-'🌱 Configuração'!$C$56)/7)+1=6),"🌿 Nim (2 mL/L) — ⚠️ ÚLTIMA foliar",IF(AND('🌱 Configuração'!$B$56+1>='🌱 Configuração'!$C$56,'🌱 Configuração'!$B$56+1<'🌱 Configuração'!$D$56,MOD('🌱 Configuração'!$B$56+1-'🌱 Configuração'!$C$56,7)=0,INT(('🌱 Configuração'!$B$56+1-'🌱 Configuração'!$C$56)/7)+1=7),"🦠 Trichoderma — solo",IF(AND('🌱 Configuração'!$B$56+1>='🌱 Configuração'!$C$56,'🌱 Configuração'!$B$56+1<'🌱 Configuração'!$D$56,MOD('🌱 Configuração'!$B$56+1-'🌱 Configuração'!$C$56,7)=0,INT(('🌱 Configuração'!$B$56+1-'🌱 Configuração'!$C$56)/7)+1=8),"🍄 Beauveria — solo","")))))))),IF('🌱 Configuração'!$B$56+1<'🌱 Configuração'!$E$56,IF(AND('🌱 Configuração'!$B$56+1>='🌱 Configuração'!$D$56,'🌱 Configuração'!$B$56+1<'🌱 Configuração'!$E$56,MOD('🌱 Configuração'!$B$56+1-'🌱 Configuração'!$D$56,7)=0,INT(('🌱 Configuração'!$B$56+1-'🌱 Configuração'!$D$56)/7)+1=1),"🍄 Beauveria bassiana — SOLO apenas",IF(AND('🌱 Configuração'!$B$56+1>='🌱 Configuração'!$D$56,'🌱 Configuração'!$B$56+1<'🌱 Configuração'!$E$56,MOD('🌱 Configuração'!$B$56+1-'🌱 Configuração'!$D$56,7)=0,INT(('🌱 Configuração'!$B$56+1-'🌱 Configuração'!$D$56)/7)+1=2),"🦠 Trichoderma (3 g/L) — solo",IF(AND('🌱 Configuração'!$B$56+1>='🌱 Configuração'!$D$56,'🌱 Configuração'!$B$56+1<'🌱 Configuração'!$E$56,MOD('🌱 Configuração'!$B$56+1-'🌱 Configuração'!$D$56,7)=0,INT(('🌱 Configuração'!$B$56+1-'🌱 Configuração'!$D$56)/7)+1=3),"🍄 Beauveria bassiana — solo | ⚠️ Umid <45%",IF(AND('🌱 Configuração'!$B$56+1>='🌱 Configuração'!$D$56,'🌱 Configuração'!$B$56+1<'🌱 Configuração'!$E$56,MOD('🌱 Configuração'!$B$56+1-'🌱 Configuração'!$D$56,7)=0,INT(('🌱 Configuração'!$B$56+1-'🌱 Configuração'!$D$56)/7)+1=4),"🦠 Trichoderma — solo | Inspecionar buds",IF(AND('🌱 Configuração'!$B$56+1>='🌱 Configuração'!$D$56,'🌱 Configuração'!$B$56+1<'🌱 Configuração'!$E$56,MOD('🌱 Configuração'!$B$56+1-'🌱 Configuração'!$D$56,7)=0,INT(('🌱 Configuração'!$B$56+1-'🌱 Configuração'!$D$56)/7)+1=5),"🍄 Beauveria + inspeção visual buds",IF(AND('🌱 Configuração'!$B$56+1>='🌱 Configuração'!$D$56,'🌱 Configuração'!$B$56+1<'🌱 Configuração'!$E$56,MOD('🌱 Configuração'!$B$56+1-'🌱 Configuração'!$D$56,7)=0,INT(('🌱 Configuração'!$B$56+1-'🌱 Configuração'!$D$56)/7)+1=6),"🦠 Trichoderma + ⚠️ Verificar mofo","")))))),IF(AND('🌱 Configuração'!$B$56+1>='🌱 Configuração'!$E$56,MOD('🌱 Configuração'!$B$56+1-'🌱 Configuração'!$E$56,7)=0),"🔬 Inspeção final — analisar tricomas","")))))
B8: =IF(3<='🌱 Configuração'!$F$55,3,"") -> 3 | C8: =IF(3<='🌱 Configuração'!$F$55,'🌱 Configuração'!$B$56+2,"") -> 2 | D8: =IF(3>'🌱 Configuração'!$F$55,"",IF('🌱 Configuração'!$B$56+2<'🌱 Configuração'!$C$56,"🌱 Clone",IF('🌱 Configuração'!$B$56+2<'🌱 Configuração'!$D$56,"🌿 Vegetativo",IF('🌱 Configuração'!$B$56+2<'🌱 Configuração'!$E$56,"🌸 Floração","🚿 Flush")))) -> 🌱 Clone | E8: =IF(3>'🌱 Configuração'!$F$55,"",IF('🌱 Configuração'!$B$56+2<'🌱 Configuração'!$C$56,"Clone S"&INT((3-1)/7)+1,IF('🌱 Configuração'!$B$56+2<'🌱 Configuração'!$D$56,"Vega S"&INT(('🌱 Configuração'!$B$56+2-'🌱 Configuração'!$C$56)/7)+1,IF('🌱 Configuração'!$B$56+2<'🌱 Configuração'!$E$56,"Flora S"&INT(('🌱 Configuração'!$B$56+2-'🌱 Configuração'!$D$56)/7)+1,"Flush S"&INT(('🌱 Configuração'!$B$56+2-'🌱 Configuração'!$E$56)/7)+1)))) -> Clone S1 | F8: =IF(3>'🌱 Configuração'!$F$55,"",IF('🌱 Configuração'!$B$56+2='🌱 Configuração'!$C$56,"🌿 INÍCIO VEGA — luz 18h/dia",IF('🌱 Configuração'!$B$56+2='🌱 Configuração'!$D$56,"🌸 INÍCIO FLORAÇÃO — mudar 12/12 🔴",IF('🌱 Configuração'!$B$56+2='🌱 Configuração'!$E$56,"🚿 INÍCIO FLUSH — parar nutrição",IF('🌱 Configuração'!$B$56+2='🌱 Configuração'!$F$56-1,"🔬 Véspera da colheita — analisar tricomas",IF('🌱 Configuração'!$B$56+2='🌱 Configuração'!$F$56,"✂️ COLHEITA — Parabéns! 🎉","")))))) | H8: =IF(3>'🌱 Configuração'!$F$55,"",IF('🌱 Configuração'!$B$56+2<'🌱 Configuração'!$C$56,IF(3=1,"🌿 Nim (2 mL/L) — foliar leve",IF(3=8,"🍄 Beauveria bassiana — foliar + solo","")),IF('🌱 Configuração'!$B$56+2<'🌱 Configuração'!$D$56,IF(AND('🌱 Configuração'!$B$56+2>='🌱 Configuração'!$C$56,'🌱 Configuração'!$B$56+2<'🌱 Configuração'!$D$56,MOD('🌱 Configuração'!$B$56+2-'🌱 Configuração'!$C$56,7)=0,INT(('🌱 Configuração'!$B$56+2-'🌱 Configuração'!$C$56)/7)+1=1),"🌿 Nim (2 mL/L) — foliar preventivo",IF(AND('🌱 Configuração'!$B$56+2>='🌱 Configuração'!$C$56,'🌱 Configuração'!$B$56+2<'🌱 Configuração'!$D$56,MOD('🌱 Configuração'!$B$56+2-'🌱 Configuração'!$C$56,7)=0,INT(('🌱 Configuração'!$B$56+2-'🌱 Configuração'!$C$56)/7)+1=2),"🍄 Beauveria bassiana — foliar + solo",IF(AND('🌱 Configuração'!$B$56+2>='🌱 Configuração'!$C$56,'🌱 Configuração'!$B$56+2<'🌱 Configuração'!$D$56,MOD('🌱 Configuração'!$B$56+2-'🌱 Configuração'!$C$56,7)=0,INT(('🌱 Configuração'!$B$56+2-'🌱 Configuração'!$C$56)/7)+1=3),"🟡 Calda Sulfocálcica (1%) — foliar",IF(AND('🌱 Configuração'!$B$56+2>='🌱 Configuração'!$C$56,'🌱 Configuração'!$B$56+2<'🌱 Configuração'!$D$56,MOD('🌱 Configuração'!$B$56+2-'🌱 Configuração'!$C$56,7)=0,INT(('🌱 Configuração'!$B$56+2-'🌱 Configuração'!$C$56)/7)+1=4),"🦠 Trichoderma (3 g/L) — solo",IF(AND('🌱 Configuração'!$B$56+2>='🌱 Configuração'!$C$56,'🌱 Configuração'!$B$56+2<'🌱 Configuração'!$D$56,MOD('🌱 Configuração'!$B$56+2-'🌱 Configuração'!$C$56,7)=0,INT(('🌱 Configuração'!$B$56+2-'🌱 Configuração'!$C$56)/7)+1=5),"🔵 Calda Bordalesa (0.5%) — foliar",IF(AND('🌱 Configuração'!$B$56+2>='🌱 Configuração'!$C$56,'🌱 Configuração'!$B$56+2<'🌱 Configuração'!$D$56,MOD('🌱 Configuração'!$B$56+2-'🌱 Configuração'!$C$56,7)=0,INT(('🌱 Configuração'!$B$56+2-'🌱 Configuração'!$C$56)/7)+1=6),"🌿 Nim (2 mL/L) — ⚠️ ÚLTIMA foliar",IF(AND('🌱 Configuração'!$B$56+2>='🌱 Configuração'!$C$56,'🌱 Configuração'!$B$56+2<'🌱 Configuração'!$D$56,MOD('🌱 Configuração'!$B$56+2-'🌱 Configuração'!$C$56,7)=0,INT(('🌱 Configuração'!$B$56+2-'🌱 Configuração'!$C$56)/7)+1=7),"🦠 Trichoderma — solo",IF(AND('🌱 Configuração'!$B$56+2>='🌱 Configuração'!$C$56,'🌱 Configuração'!$B$56+2<'🌱 Configuração'!$D$56,MOD('🌱 Configuração'!$B$56+2-'🌱 Configuração'!$C$56,7)=0,INT(('🌱 Configuração'!$B$56+2-'🌱 Configuração'!$C$56)/7)+1=8),"🍄 Beauveria — solo","")))))))),IF('🌱 Configuração'!$B$56+2<'🌱 Configuração'!$E$56,IF(AND('🌱 Configuração'!$B$56+2>='🌱 Configuração'!$D$56,'🌱 Configuração'!$B$56+2<'🌱 Configuração'!$E$56,MOD('🌱 Configuração'!$B$56+2-'🌱 Configuração'!$D$56,7)=0,INT(('🌱 Configuração'!$B$56+2-'🌱 Configuração'!$D$56)/7)+1=1),"🍄 Beauveria bassiana — SOLO apenas",IF(AND('🌱 Configuração'!$B$56+2>='🌱 Configuração'!$D$56,'🌱 Configuração'!$B$56+2<'🌱 Configuração'!$E$56,MOD('🌱 Configuração'!$B$56+2-'🌱 Configuração'!$D$56,7)=0,INT(('🌱 Configuração'!$B$56+2-'🌱 Configuração'!$D$56)/7)+1=2),"🦠 Trichoderma (3 g/L) — solo",IF(AND('🌱 Configuração'!$B$56+2>='🌱 Configuração'!$D$56,'🌱 Configuração'!$B$56+2<'🌱 Configuração'!$E$56,MOD('🌱 Configuração'!$B$56+2-'🌱 Configuração'!$D$56,7)=0,INT(('🌱 Configuração'!$B$56+2-'🌱 Configuração'!$D$56)/7)+1=3),"🍄 Beauveria bassiana — solo | ⚠️ Umid <45%",IF(AND('🌱 Configuração'!$B$56+2>='🌱 Configuração'!$D$56,'🌱 Configuração'!$B$56+2<'🌱 Configuração'!$E$56,MOD('🌱 Configuração'!$B$56+2-'🌱 Configuração'!$D$56,7)=0,INT(('🌱 Configuração'!$B$56+2-'🌱 Configuração'!$D$56)/7)+1=4),"🦠 Trichoderma — solo | Inspecionar buds",IF(AND('🌱 Configuração'!$B$56+2>='🌱 Configuração'!$D$56,'🌱 Configuração'!$B$56+2<'🌱 Configuração'!$E$56,MOD('🌱 Configuração'!$B$56+2-'🌱 Configuração'!$D$56,7)=0,INT(('🌱 Configuração'!$B$56+2-'🌱 Configuração'!$D$56)/7)+1=5),"🍄 Beauveria + inspeção visual buds",IF(AND('🌱 Configuração'!$B$56+2>='🌱 Configuração'!$D$56,'🌱 Configuração'!$B$56+2<'🌱 Configuração'!$E$56,MOD('🌱 Configuração'!$B$56+2-'🌱 Configuração'!$D$56,7)=0,INT(('🌱 Configuração'!$B$56+2-'🌱 Configuração'!$D$56)/7)+1=6),"🦠 Trichoderma + ⚠️ Verificar mofo","")))))),IF(AND('🌱 Configuração'!$B$56+2>='🌱 Configuração'!$E$56,MOD('🌱 Configuração'!$B$56+2-'🌱 Configuração'!$E$56,7)=0),"🔬 Inspeção final — analisar tricomas","")))))
B9: =IF(4<='🌱 Configuração'!$F$55,4,"") -> 4 | C9: =IF(4<='🌱 Configuração'!$F$55,'🌱 Configuração'!$B$56+3,"") -> 3 | D9: =IF(4>'🌱 Configuração'!$F$55,"",IF('🌱 Configuração'!$B$56+3<'🌱 Configuração'!$C$56,"🌱 Clone",IF('🌱 Configuração'!$B$56+3<'🌱 Configuração'!$D$56,"🌿 Vegetativo",IF('🌱 Configuração'!$B$56+3<'🌱 Configuração'!$E$56,"🌸 Floração","🚿 Flush")))) -> 🌱 Clone | E9: =IF(4>'🌱 Configuração'!$F$55,"",IF('🌱 Configuração'!$B$56+3<'🌱 Configuração'!$C$56,"Clone S"&INT((4-1)/7)+1,IF('🌱 Configuração'!$B$56+3<'🌱 Configuração'!$D$56,"Vega S"&INT(('🌱 Configuração'!$B$56+3-'🌱 Configuração'!$C$56)/7)+1,IF('🌱 Configuração'!$B$56+3<'🌱 Configuração'!$E$56,"Flora S"&INT(('🌱 Configuração'!$B$56+3-'🌱 Configuração'!$D$56)/7)+1,"Flush S"&INT(('🌱 Configuração'!$B$56+3-'🌱 Configuração'!$E$56)/7)+1)))) -> Clone S1 | F9: =IF(4>'🌱 Configuração'!$F$55,"",IF('🌱 Configuração'!$B$56+3='🌱 Configuração'!$C$56,"🌿 INÍCIO VEGA — luz 18h/dia",IF('🌱 Configuração'!$B$56+3='🌱 Configuração'!$D$56,"🌸 INÍCIO FLORAÇÃO — mudar 12/12 🔴",IF('🌱 Configuração'!$B$56+3='🌱 Configuração'!$E$56,"🚿 INÍCIO FLUSH — parar nutrição",IF('🌱 Configuração'!$B$56+3='🌱 Configuração'!$F$56-1,"🔬 Véspera da colheita — analisar tricomas",IF('🌱 Configuração'!$B$56+3='🌱 Configuração'!$F$56,"✂️ COLHEITA — Parabéns! 🎉","")))))) | H9: =IF(4>'🌱 Configuração'!$F$55,"",IF('🌱 Configuração'!$B$56+3<'🌱 Configuração'!$C$56,IF(4=1,"🌿 Nim (2 mL/L) — foliar leve",IF(4=8,"🍄 Beauveria bassiana — foliar + solo","")),IF('🌱 Configuração'!$B$56+3<'🌱 Configuração'!$D$56,IF(AND('🌱 Configuração'!$B$56+3>='🌱 Configuração'!$C$56,'🌱 Configuração'!$B$56+3<'🌱 Configuração'!$D$56,MOD('🌱 Configuração'!$B$56+3-'🌱 Configuração'!$C$56,7)=0,INT(('🌱 Configuração'!$B$56+3-'🌱 Configuração'!$C$56)/7)+1=1),"🌿 Nim (2 mL/L) — foliar preventivo",IF(AND('🌱 Configuração'!$B$56+3>='🌱 Configuração'!$C$56,'🌱 Configuração'!$B$56+3<'🌱 Configuração'!$D$56,MOD('🌱 Configuração'!$B$56+3-'🌱 Configuração'!$C$56,7)=0,INT(('🌱 Configuração'!$B$56+3-'🌱 Configuração'!$C$56)/7)+1=2),"🍄 Beauveria bassiana — foliar + solo",IF(AND('🌱 Configuração'!$B$56+3>='🌱 Configuração'!$C$56,'🌱 Configuração'!$B$56+3<'🌱 Configuração'!$D$56,MOD('🌱 Configuração'!$B$56+3-'🌱 Configuração'!$C$56,7)=0,INT(('🌱 Configuração'!$B$56+3-'🌱 Configuração'!$C$56)/7)+1=3),"🟡 Calda Sulfocálcica (1%) — foliar",IF(AND('🌱 Configuração'!$B$56+3>='🌱 Configuração'!$C$56,'🌱 Configuração'!$B$56+3<'🌱 Configuração'!$D$56,MOD('🌱 Configuração'!$B$56+3-'🌱 Configuração'!$C$56,7)=0,INT(('🌱 Configuração'!$B$56+3-'🌱 Configuração'!$C$56)/7)+1=4),"🦠 Trichoderma (3 g/L) — solo",IF(AND('🌱 Configuração'!$B$56+3>='🌱 Configuração'!$C$56,'🌱 Configuração'!$B$56+3<'🌱 Configuração'!$D$56,MOD('🌱 Configuração'!$B$56+3-'🌱 Configuração'!$C$56,7)=0,INT(('🌱 Configuração'!$B$56+3-'🌱 Configuração'!$C$56)/7)+1=5),"🔵 Calda Bordalesa (0.5%) — foliar",IF(AND('🌱 Configuração'!$B$56+3>='🌱 Configuração'!$C$56,'🌱 Configuração'!$B$56+3<'🌱 Configuração'!$D$56,MOD('🌱 Configuração'!$B$56+3-'🌱 Configuração'!$C$56,7)=0,INT(('🌱 Configuração'!$B$56+3-'🌱 Configuração'!$C$56)/7)+1=6),"🌿 Nim (2 mL/L) — ⚠️ ÚLTIMA foliar",IF(AND('🌱 Configuração'!$B$56+3>='🌱 Configuração'!$C$56,'🌱 Configuração'!$B$56+3<'🌱 Configuração'!$D$56,MOD('🌱 Configuração'!$B$56+3-'🌱 Configuração'!$C$56,7)=0,INT(('🌱 Configuração'!$B$56+3-'🌱 Configuração'!$C$56)/7)+1=7),"🦠 Trichoderma — solo",IF(AND('🌱 Configuração'!$B$56+3>='🌱 Configuração'!$C$56,'🌱 Configuração'!$B$56+3<'🌱 Configuração'!$D$56,MOD('🌱 Configuração'!$B$56+3-'🌱 Configuração'!$C$56,7)=0,INT(('🌱 Configuração'!$B$56+3-'🌱 Configuração'!$C$56)/7)+1=8),"🍄 Beauveria — solo","")))))))),IF('🌱 Configuração'!$B$56+3<'🌱 Configuração'!$E$56,IF(AND('🌱 Configuração'!$B$56+3>='🌱 Configuração'!$D$56,'🌱 Configuração'!$B$56+3<'🌱 Configuração'!$E$56,MOD('🌱 Configuração'!$B$56+3-'🌱 Configuração'!$D$56,7)=0,INT(('🌱 Configuração'!$B$56+3-'🌱 Configuração'!$D$56)/7)+1=1),"🍄 Beauveria bassiana — SOLO apenas",IF(AND('🌱 Configuração'!$B$56+3>='🌱 Configuração'!$D$56,'🌱 Configuração'!$B$56+3<'🌱 Configuração'!$E$56,MOD('🌱 Configuração'!$B$56+3-'🌱 Configuração'!$D$56,7)=0,INT(('🌱 Configuração'!$B$56+3-'🌱 Configuração'!$D$56)/7)+1=2),"🦠 Trichoderma (3 g/L) — solo",IF(AND('🌱 Configuração'!$B$56+3>='🌱 Configuração'!$D$56,'🌱 Configuração'!$B$56+3<'🌱 Configuração'!$E$56,MOD('🌱 Configuração'!$B$56+3-'🌱 Configuração'!$D$56,7)=0,INT(('🌱 Configuração'!$B$56+3-'🌱 Configuração'!$D$56)/7)+1=3),"🍄 Beauveria bassiana — solo | ⚠️ Umid <45%",IF(AND('🌱 Configuração'!$B$56+3>='🌱 Configuração'!$D$56,'🌱 Configuração'!$B$56+3<'🌱 Configuração'!$E$56,MOD('🌱 Configuração'!$B$56+3-'🌱 Configuração'!$D$56,7)=0,INT(('🌱 Configuração'!$B$56+3-'🌱 Configuração'!$D$56)/7)+1=4),"🦠 Trichoderma — solo | Inspecionar buds",IF(AND('🌱 Configuração'!$B$56+3>='🌱 Configuração'!$D$56,'🌱 Configuração'!$B$56+3<'🌱 Configuração'!$E$56,MOD('🌱 Configuração'!$B$56+3-'🌱 Configuração'!$D$56,7)=0,INT(('🌱 Configuração'!$B$56+3-'🌱 Configuração'!$D$56)/7)+1=5),"🍄 Beauveria + inspeção visual buds",IF(AND('🌱 Configuração'!$B$56+3>='🌱 Configuração'!$D$56,'🌱 Configuração'!$B$56+3<'🌱 Configuração'!$E$56,MOD('🌱 Configuração'!$B$56+3-'🌱 Configuração'!$D$56,7)=0,INT(('🌱 Configuração'!$B$56+3-'🌱 Configuração'!$D$56)/7)+1=6),"🦠 Trichoderma + ⚠️ Verificar mofo","")))))),IF(AND('🌱 Configuração'!$B$56+3>='🌱 Configuração'!$E$56,MOD('🌱 Configuração'!$B$56+3-'🌱 Configuração'!$E$56,7)=0),"🔬 Inspeção final — analisar tricomas","")))))
B10: =IF(5<='🌱 Configuração'!$F$55,5,"") -> 5 | C10: =IF(5<='🌱 Configuração'!$F$55,'🌱 Configuração'!$B$56+4,"") -> 4 | D10: =IF(5>'🌱 Configuração'!$F$55,"",IF('🌱 Configuração'!$B$56+4<'🌱 Configuração'!$C$56,"🌱 Clone",IF('🌱 Configuração'!$B$56+4<'🌱 Configuração'!$D$56,"🌿 Vegetativo",IF('🌱 Configuração'!$B$56+4<'🌱 Configuração'!$E$56,"🌸 Floração","🚿 Flush")))) -> 🌱 Clone | E10: =IF(5>'🌱 Configuração'!$F$55,"",IF('🌱 Configuração'!$B$56+4<'🌱 Configuração'!$C$56,"Clone S"&INT((5-1)/7)+1,IF('🌱 Configuração'!$B$56+4<'🌱 Configuração'!$D$56,"Vega S"&INT(('🌱 Configuração'!$B$56+4-'🌱 Configuração'!$C$56)/7)+1,IF('🌱 Configuração'!$B$56+4<'🌱 Configuração'!$E$56,"Flora S"&INT(('🌱 Configuração'!$B$56+4-'🌱 Configuração'!$D$56)/7)+1,"Flush S"&INT(('🌱 Configuração'!$B$56+4-'🌱 Configuração'!$E$56)/7)+1)))) -> Clone S1 | F10: =IF(5>'🌱 Configuração'!$F$55,"",IF('🌱 Configuração'!$B$56+4='🌱 Configuração'!$C$56,"🌿 INÍCIO VEGA — luz 18h/dia",IF('🌱 Configuração'!$B$56+4='🌱 Configuração'!$D$56,"🌸 INÍCIO FLORAÇÃO — mudar 12/12 🔴",IF('🌱 Configuração'!$B$56+4='🌱 Configuração'!$E$56,"🚿 INÍCIO FLUSH — parar nutrição",IF('🌱 Configuração'!$B$56+4='🌱 Configuração'!$F$56-1,"🔬 Véspera da colheita — analisar tricomas",IF('🌱 Configuração'!$B$56+4='🌱 Configuração'!$F$56,"✂️ COLHEITA — Parabéns! 🎉","")))))) | H10: =IF(5>'🌱 Configuração'!$F$55,"",IF('🌱 Configuração'!$B$56+4<'🌱 Configuração'!$C$56,IF(5=1,"🌿 Nim (2 mL/L) — foliar leve",IF(5=8,"🍄 Beauveria bassiana — foliar + solo","")),IF('🌱 Configuração'!$B$56+4<'🌱 Configuração'!$D$56,IF(AND('🌱 Configuração'!$B$56+4>='🌱 Configuração'!$C$56,'🌱 Configuração'!$B$56+4<'🌱 Configuração'!$D$56,MOD('🌱 Configuração'!$B$56+4-'🌱 Configuração'!$C$56,7)=0,INT(('🌱 Configuração'!$B$56+4-'🌱 Configuração'!$C$56)/7)+1=1),"🌿 Nim (2 mL/L) — foliar preventivo",IF(AND('🌱 Configuração'!$B$56+4>='🌱 Configuração'!$C$56,'🌱 Configuração'!$B$56+4<'🌱 Configuração'!$D$56,MOD('🌱 Configuração'!$B$56+4-'🌱 Configuração'!$C$56,7)=0,INT(('🌱 Configuração'!$B$56+4-'🌱 Configuração'!$C$56)/7)+1=2),"🍄 Beauveria bassiana — foliar + solo",IF(AND('🌱 Configuração'!$B$56+4>='🌱 Configuração'!$C$56,'🌱 Configuração'!$B$56+4<'🌱 Configuração'!$D$56,MOD('🌱 Configuração'!$B$56+4-'🌱 Configuração'!$C$56,7)=0,INT(('🌱 Configuração'!$B$56+4-'🌱 Configuração'!$C$56)/7)+1=3),"🟡 Calda Sulfocálcica (1%) — foliar",IF(AND('🌱 Configuração'!$B$56+4>='🌱 Configuração'!$C$56,'🌱 Configuração'!$B$56+4<'🌱 Configuração'!$D$56,MOD('🌱 Configuração'!$B$56+4-'🌱 Configuração'!$C$56,7)=0,INT(('🌱 Configuração'!$B$56+4-'🌱 Configuração'!$C$56)/7)+1=4),"🦠 Trichoderma (3 g/L) — solo",IF(AND('🌱 Configuração'!$B$56+4>='🌱 Configuração'!$C$56,'🌱 Configuração'!$B$56+4<'🌱 Configuração'!$D$56,MOD('🌱 Configuração'!$B$56+4-'🌱 Configuração'!$C$56,7)=0,INT(('🌱 Configuração'!$B$56+4-'🌱 Configuração'!$C$56)/7)+1=5),"🔵 Calda Bordalesa (0.5%) — foliar",IF(AND('🌱 Configuração'!$B$56+4>='🌱 Configuração'!$C$56,'🌱 Configuração'!$B$56+4<'🌱 Configuração'!$D$56,MOD('🌱 Configuração'!$B$56+4-'🌱 Configuração'!$C$56,7)=0,INT(('🌱 Configuração'!$B$56+4-'🌱 Configuração'!$C$56)/7)+1=6),"🌿 Nim (2 mL/L) — ⚠️ ÚLTIMA foliar",IF(AND('🌱 Configuração'!$B$56+4>='🌱 Configuração'!$C$56,'🌱 Configuração'!$B$56+4<'🌱 Configuração'!$D$56,MOD('🌱 Configuração'!$B$56+4-'🌱 Configuração'!$C$56,7)=0,INT(('🌱 Configuração'!$B$56+4-'🌱 Configuração'!$C$56)/7)+1=7),"🦠 Trichoderma — solo",IF(AND('🌱 Configuração'!$B$56+4>='🌱 Configuração'!$C$56,'🌱 Configuração'!$B$56+4<'🌱 Configuração'!$D$56,MOD('🌱 Configuração'!$B$56+4-'🌱 Configuração'!$C$56,7)=0,INT(('🌱 Configuração'!$B$56+4-'🌱 Configuração'!$C$56)/7)+1=8),"🍄 Beauveria — solo","")))))))),IF('🌱 Configuração'!$B$56+4<'🌱 Configuração'!$E$56,IF(AND('🌱 Configuração'!$B$56+4>='🌱 Configuração'!$D$56,'🌱 Configuração'!$B$56+4<'🌱 Configuração'!$E$56,MOD('🌱 Configuração'!$B$56+4-'🌱 Configuração'!$D$56,7)=0,INT(('🌱 Configuração'!$B$56+4-'🌱 Configuração'!$D$56)/7)+1=1),"🍄 Beauveria bassiana — SOLO apenas",IF(AND('🌱 Configuração'!$B$56+4>='🌱 Configuração'!$D$56,'🌱 Configuração'!$B$56+4<'🌱 Configuração'!$E$56,MOD('🌱 Configuração'!$B$56+4-'🌱 Configuração'!$D$56,7)=0,INT(('🌱 Configuração'!$B$56+4-'🌱 Configuração'!$D$56)/7)+1=2),"🦠 Trichoderma (3 g/L) — solo",IF(AND('🌱 Configuração'!$B$56+4>='🌱 Configuração'!$D$56,'🌱 Configuração'!$B$56+4<'🌱 Configuração'!$E$56,MOD('🌱 Configuração'!$B$56+4-'🌱 Configuração'!$D$56,7)=0,INT(('🌱 Configuração'!$B$56+4-'🌱 Configuração'!$D$56)/7)+1=3),"🍄 Beauveria bassiana — solo | ⚠️ Umid <45%",IF(AND('🌱 Configuração'!$B$56+4>='🌱 Configuração'!$D$56,'🌱 Configuração'!$B$56+4<'🌱 Configuração'!$E$56,MOD('🌱 Configuração'!$B$56+4-'🌱 Configuração'!$D$56,7)=0,INT(('🌱 Configuração'!$B$56+4-'🌱 Configuração'!$D$56)/7)+1=4),"🦠 Trichoderma — solo | Inspecionar buds",IF(AND('🌱 Configuração'!$B$56+4>='🌱 Configuração'!$D$56,'🌱 Configuração'!$B$56+4<'🌱 Configuração'!$E$56,MOD('🌱 Configuração'!$B$56+4-'🌱 Configuração'!$D$56,7)=0,INT(('🌱 Configuração'!$B$56+4-'🌱 Configuração'!$D$56)/7)+1=5),"🍄 Beauveria + inspeção visual buds",IF(AND('🌱 Configuração'!$B$56+4>='🌱 Configuração'!$D$56,'🌱 Configuração'!$B$56+4<'🌱 Configuração'!$E$56,MOD('🌱 Configuração'!$B$56+4-'🌱 Configuração'!$D$56,7)=0,INT(('🌱 Configuração'!$B$56+4-'🌱 Configuração'!$D$56)/7)+1=6),"🦠 Trichoderma + ⚠️ Verificar mofo","")))))),IF(AND('🌱 Configuração'!$B$56+4>='🌱 Configuração'!$E$56,MOD('🌱 Configuração'!$B$56+4-'🌱 Configuração'!$E$56,7)=0),"🔬 Inspeção final — analisar tricomas","")))))
B11: =IF(6<='🌱 Configuração'!$F$55,6,"") -> 6 | C11: =IF(6<='🌱 Configuração'!$F$55,'🌱 Configuração'!$B$56+5,"") -> 5 | D11: =IF(6>'🌱 Configuração'!$F$55,"",IF('🌱 Configuração'!$B$56+5<'🌱 Configuração'!$C$56,"🌱 Clone",IF('🌱 Configuração'!$B$56+5<'🌱 Configuração'!$D$56,"🌿 Vegetativo",IF('🌱 Configuração'!$B$56+5<'🌱 Configuração'!$E$56,"🌸 Floração","🚿 Flush")))) -> 🌱 Clone | E11: =IF(6>'🌱 Configuração'!$F$55,"",IF('🌱 Configuração'!$B$56+5<'🌱 Configuração'!$C$56,"Clone S"&INT((6-1)/7)+1,IF('🌱 Configuração'!$B$56+5<'🌱 Configuração'!$D$56,"Vega S"&INT(('🌱 Configuração'!$B$56+5-'🌱 Configuração'!$C$56)/7)+1,IF('🌱 Configuração'!$B$56+5<'🌱 Configuração'!$E$56,"Flora S"&INT(('🌱 Configuração'!$B$56+5-'🌱 Configuração'!$D$56)/7)+1,"Flush S"&INT(('🌱 Configuração'!$B$56+5-'🌱 Configuração'!$E$56)/7)+1)))) -> Clone S1 | F11: =IF(6>'🌱 Configuração'!$F$55,"",IF('🌱 Configuração'!$B$56+5='🌱 Configuração'!$C$56,"🌿 INÍCIO VEGA — luz 18h/dia",IF('🌱 Configuração'!$B$56+5='🌱 Configuração'!$D$56,"🌸 INÍCIO FLORAÇÃO — mudar 12/12 🔴",IF('🌱 Configuração'!$B$56+5='🌱 Configuração'!$E$56,"🚿 INÍCIO FLUSH — parar nutrição",IF('🌱 Configuração'!$B$56+5='🌱 Configuração'!$F$56-1,"🔬 Véspera da colheita — analisar tricomas",IF('🌱 Configuração'!$B$56+5='🌱 Configuração'!$F$56,"✂️ COLHEITA — Parabéns! 🎉","")))))) | H11: =IF(6>'🌱 Configuração'!$F$55,"",IF('🌱 Configuração'!$B$56+5<'🌱 Configuração'!$C$56,IF(6=1,"🌿 Nim (2 mL/L) — foliar leve",IF(6=8,"🍄 Beauveria bassiana — foliar + solo","")),IF('🌱 Configuração'!$B$56+5<'🌱 Configuração'!$D$56,IF(AND('🌱 Configuração'!$B$56+5>='🌱 Configuração'!$C$56,'🌱 Configuração'!$B$56+5<'🌱 Configuração'!$D$56,MOD('🌱 Configuração'!$B$56+5-'🌱 Configuração'!$C$56,7)=0,INT(('🌱 Configuração'!$B$56+5-'🌱 Configuração'!$C$56)/7)+1=1),"🌿 Nim (2 mL/L) — foliar preventivo",IF(AND('🌱 Configuração'!$B$56+5>='🌱 Configuração'!$C$56,'🌱 Configuração'!$B$56+5<'🌱 Configuração'!$D$56,MOD('🌱 Configuração'!$B$56+5-'🌱 Configuração'!$C$56,7)=0,INT(('🌱 Configuração'!$B$56+5-'🌱 Configuração'!$C$56)/7)+1=2),"🍄 Beauveria bassiana — foliar + solo",IF(AND('🌱 Configuração'!$B$56+5>='🌱 Configuração'!$C$56,'🌱 Configuração'!$B$56+5<'🌱 Configuração'!$D$56,MOD('🌱 Configuração'!$B$56+5-'🌱 Configuração'!$C$56,7)=0,INT(('🌱 Configuração'!$B$56+5-'🌱 Configuração'!$C$56)/7)+1=3),"🟡 Calda Sulfocálcica (1%) — foliar",IF(AND('🌱 Configuração'!$B$56+5>='🌱 Configuração'!$C$56,'🌱 Configuração'!$B$56+5<'🌱 Configuração'!$D$56,MOD('🌱 Configuração'!$B$56+5-'🌱 Configuração'!$C$56,7)=0,INT(('🌱 Configuração'!$B$56+5-'🌱 Configuração'!$C$56)/7)+1=4),"🦠 Trichoderma (3 g/L) — solo",IF(AND('🌱 Configuração'!$B$56+5>='🌱 Configuração'!$C$56,'🌱 Configuração'!$B$56+5<'🌱 Configuração'!$D$56,MOD('🌱 Configuração'!$B$56+5-'🌱 Configuração'!$C$56,7)=0,INT(('🌱 Configuração'!$B$56+5-'🌱 Configuração'!$C$56)/7)+1=5),"🔵 Calda Bordalesa (0.5%) — foliar",IF(AND('🌱 Configuração'!$B$56+5>='🌱 Configuração'!$C$56,'🌱 Configuração'!$B$56+5<'🌱 Configuração'!$D$56,MOD('🌱 Configuração'!$B$56+5-'🌱 Configuração'!$C$56,7)=0,INT(('🌱 Configuração'!$B$56+5-'🌱 Configuração'!$C$56)/7)+1=6),"🌿 Nim (2 mL/L) — ⚠️ ÚLTIMA foliar",IF(AND('🌱 Configuração'!$B$56+5>='🌱 Configuração'!$C$56,'🌱 Configuração'!$B$56+5<'🌱 Configuração'!$D$56,MOD('🌱 Configuração'!$B$56+5-'🌱 Configuração'!$C$56,7)=0,INT(('🌱 Configuração'!$B$56+5-'🌱 Configuração'!$C$56)/7)+1=7),"🦠 Trichoderma — solo",IF(AND('🌱 Configuração'!$B$56+5>='🌱 Configuração'!$C$56,'🌱 Configuração'!$B$56+5<'🌱 Configuração'!$D$56,MOD('🌱 Configuração'!$B$56+5-'🌱 Configuração'!$C$56,7)=0,INT(('🌱 Configuração'!$B$56+5-'🌱 Configuração'!$C$56)/7)+1=8),"🍄 Beauveria — solo","")))))))),IF('🌱 Configuração'!$B$56+5<'🌱 Configuração'!$E$56,IF(AND('🌱 Configuração'!$B$56+5>='🌱 Configuração'!$D$56,'🌱 Configuração'!$B$56+5<'🌱 Configuração'!$E$56,MOD('🌱 Configuração'!$B$56+5-'🌱 Configuração'!$D$56,7)=0,INT(('🌱 Configuração'!$B$56+5-'🌱 Configuração'!$D$56)/7)+1=1),"🍄 Beauveria bassiana — SOLO apenas",IF(AND('🌱 Configuração'!$B$56+5>='🌱 Configuração'!$D$56,'🌱 Configuração'!$B$56+5<'🌱 Configuração'!$E$56,MOD('🌱 Configuração'!$B$56+5-'🌱 Configuração'!$D$56,7)=0,INT(('🌱 Configuração'!$B$56+5-'🌱 Configuração'!$D$56)/7)+1=2),"🦠 Trichoderma (3 g/L) — solo",IF(AND('🌱 Configuração'!$B$56+5>='🌱 Configuração'!$D$56,'🌱 Configuração'!$B$56+5<'🌱 Configuração'!$E$56,MOD('🌱 Configuração'!$B$56+5-'🌱 Configuração'!$D$56,7)=0,INT(('🌱 Configuração'!$B$56+5-'🌱 Configuração'!$D$56)/7)+1=3),"🍄 Beauveria bassiana — solo | ⚠️ Umid <45%",IF(AND('🌱 Configuração'!$B$56+5>='🌱 Configuração'!$D$56,'🌱 Configuração'!$B$56+5<'🌱 Configuração'!$E$56,MOD('🌱 Configuração'!$B$56+5-'🌱 Configuração'!$D$56,7)=0,INT(('🌱 Configuração'!$B$56+5-'🌱 Configuração'!$D$56)/7)+1=4),"🦠 Trichoderma — solo | Inspecionar buds",IF(AND('🌱 Configuração'!$B$56+5>='🌱 Configuração'!$D$56,'🌱 Configuração'!$B$56+5<'🌱 Configuração'!$E$56,MOD('🌱 Configuração'!$B$56+5-'🌱 Configuração'!$D$56,7)=0,INT(('🌱 Configuração'!$B$56+5-'🌱 Configuração'!$D$56)/7)+1=5),"🍄 Beauveria + inspeção visual buds",IF(AND('🌱 Configuração'!$B$56+5>='🌱 Configuração'!$D$56,'🌱 Configuração'!$B$56+5<'🌱 Configuração'!$E$56,MOD('🌱 Configuração'!$B$56+5-'🌱 Configuração'!$D$56,7)=0,INT(('🌱 Configuração'!$B$56+5-'🌱 Configuração'!$D$56)/7)+1=6),"🦠 Trichoderma + ⚠️ Verificar mofo","")))))),IF(AND('🌱 Configuração'!$B$56+5>='🌱 Configuração'!$E$56,MOD('🌱 Configuração'!$B$56+5-'🌱 Configuração'!$E$56,7)=0),"🔬 Inspeção final — analisar tricomas","")))))
B12: =IF(7<='🌱 Configuração'!$F$55,7,"") -> 7 | C12: =IF(7<='🌱 Configuração'!$F$55,'🌱 Configuração'!$B$56+6,"") -> 6 | D12: =IF(7>'🌱 Configuração'!$F$55,"",IF('🌱 Configuração'!$B$56+6<'🌱 Configuração'!$C$56,"🌱 Clone",IF('🌱 Configuração'!$B$56+6<'🌱 Configuração'!$D$56,"🌿 Vegetativo",IF('🌱 Configuração'!$B$56+6<'🌱 Configuração'!$E$56,"🌸 Floração","🚿 Flush")))) -> 🌱 Clone | E12: =IF(7>'🌱 Configuração'!$F$55,"",IF('🌱 Configuração'!$B$56+6<'🌱 Configuração'!$C$56,"Clone S"&INT((7-1)/7)+1,IF('🌱 Configuração'!$B$56+6<'🌱 Configuração'!$D$56,"Vega S"&INT(('🌱 Configuração'!$B$56+6-'🌱 Configuração'!$C$56)/7)+1,IF('🌱 Configuração'!$B$56+6<'🌱 Configuração'!$E$56,"Flora S"&INT(('🌱 Configuração'!$B$56+6-'🌱 Configuração'!$D$56)/7)+1,"Flush S"&INT(('🌱 Configuração'!$B$56+6-'🌱 Configuração'!$E$56)/7)+1)))) -> Clone S1 | F12: =IF(7>'🌱 Configuração'!$F$55,"",IF('🌱 Configuração'!$B$56+6='🌱 Configuração'!$C$56,"🌿 INÍCIO VEGA — luz 18h/dia",IF('🌱 Configuração'!$B$56+6='🌱 Configuração'!$D$56,"🌸 INÍCIO FLORAÇÃO — mudar 12/12 🔴",IF('🌱 Configuração'!$B$56+6='🌱 Configuração'!$E$56,"🚿 INÍCIO FLUSH — parar nutrição",IF('🌱 Configuração'!$B$56+6='🌱 Configuração'!$F$56-1,"🔬 Véspera da colheita — analisar tricomas",IF('🌱 Configuração'!$B$56+6='🌱 Configuração'!$F$56,"✂️ COLHEITA — Parabéns! 🎉","")))))) | H12: =IF(7>'🌱 Configuração'!$F$55,"",IF('🌱 Configuração'!$B$56+6<'🌱 Configuração'!$C$56,IF(7=1,"🌿 Nim (2 mL/L) — foliar leve",IF(7=8,"🍄 Beauveria bassiana — foliar + solo","")),IF('🌱 Configuração'!$B$56+6<'🌱 Configuração'!$D$56,IF(AND('🌱 Configuração'!$B$56+6>='🌱 Configuração'!$C$56,'🌱 Configuração'!$B$56+6<'🌱 Configuração'!$D$56,MOD('🌱 Configuração'!$B$56+6-'🌱 Configuração'!$C$56,7)=0,INT(('🌱 Configuração'!$B$56+6-'🌱 Configuração'!$C$56)/7)+1=1),"🌿 Nim (2 mL/L) — foliar preventivo",IF(AND('🌱 Configuração'!$B$56+6>='🌱 Configuração'!$C$56,'🌱 Configuração'!$B$56+6<'🌱 Configuração'!$D$56,MOD('🌱 Configuração'!$B$56+6-'🌱 Configuração'!$C$56,7)=0,INT(('🌱 Configuração'!$B$56+6-'🌱 Configuração'!$C$56)/7)+1=2),"🍄 Beauveria bassiana — foliar + solo",IF(AND('🌱 Configuração'!$B$56+6>='🌱 Configuração'!$C$56,'🌱 Configuração'!$B$56+6<'🌱 Configuração'!$D$56,MOD('🌱 Configuração'!$B$56+6-'🌱 Configuração'!$C$56,7)=0,INT(('🌱 Configuração'!$B$56+6-'🌱 Configuração'!$C$56)/7)+1=3),"🟡 Calda Sulfocálcica (1%) — foliar",IF(AND('🌱 Configuração'!$B$56+6>='🌱 Configuração'!$C$56,'🌱 Configuração'!$B$56+6<'🌱 Configuração'!$D$56,MOD('🌱 Configuração'!$B$56+6-'🌱 Configuração'!$C$56,7)=0,INT(('🌱 Configuração'!$B$56+6-'🌱 Configuração'!$C$56)/7)+1=4),"🦠 Trichoderma (3 g/L) — solo",IF(AND('🌱 Configuração'!$B$56+6>='🌱 Configuração'!$C$56,'🌱 Configuração'!$B$56+6<'🌱 Configuração'!$D$56,MOD('🌱 Configuração'!$B$56+6-'🌱 Configuração'!$C$56,7)=0,INT(('🌱 Configuração'!$B$56+6-'🌱 Configuração'!$C$56)/7)+1=5),"🔵 Calda Bordalesa (0.5%) — foliar",IF(AND('🌱 Configuração'!$B$56+6>='🌱 Configuração'!$C$56,'🌱 Configuração'!$B$56+6<'🌱 Configuração'!$D$56,MOD('🌱 Configuração'!$B$56+6-'🌱 Configuração'!$C$56,7)=0,INT(('🌱 Configuração'!$B$56+6-'🌱 Configuração'!$C$56)/7)+1=6),"🌿 Nim (2 mL/L) — ⚠️ ÚLTIMA foliar",IF(AND('🌱 Configuração'!$B$56+6>='🌱 Configuração'!$C$56,'🌱 Configuração'!$B$56+6<'🌱 Configuração'!$D$56,MOD('🌱 Configuração'!$B$56+6-'🌱 Configuração'!$C$56,7)=0,INT(('🌱 Configuração'!$B$56+6-'🌱 Configuração'!$C$56)/7)+1=7),"🦠 Trichoderma — solo",IF(AND('🌱 Configuração'!$B$56+6>='🌱 Configuração'!$C$56,'🌱 Configuração'!$B$56+6<'🌱 Configuração'!$D$56,MOD('🌱 Configuração'!$B$56+6-'🌱 Configuração'!$C$56,7)=0,INT(('🌱 Configuração'!$B$56+6-'🌱 Configuração'!$C$56)/7)+1=8),"🍄 Beauveria — solo","")))))))),IF('🌱 Configuração'!$B$56+6<'🌱 Configuração'!$E$56,IF(AND('🌱 Configuração'!$B$56+6>='🌱 Configuração'!$D$56,'🌱 Configuração'!$B$56+6<'🌱 Configuração'!$E$56,MOD('🌱 Configuração'!$B$56+6-'🌱 Configuração'!$D$56,7)=0,INT(('🌱 Configuração'!$B$56+6-'🌱 Configuração'!$D$56)/7)+1=1),"🍄 Beauveria bassiana — SOLO apenas",IF(AND('🌱 Configuração'!$B$56+6>='🌱 Configuração'!$D$56,'🌱 Configuração'!$B$56+6<'🌱 Configuração'!$E$56,MOD('🌱 Configuração'!$B$56+6-'🌱 Configuração'!$D$56,7)=0,INT(('🌱 Configuração'!$B$56+6-'🌱 Configuração'!$D$56)/7)+1=2),"🦠 Trichoderma (3 g/L) — solo",IF(AND('🌱 Configuração'!$B$56+6>='🌱 Configuração'!$D$56,'🌱 Configuração'!$B$56+6<'🌱 Configuração'!$E$56,MOD('🌱 Configuração'!$B$56+6-'🌱 Configuração'!$D$56,7)=0,INT(('🌱 Configuração'!$B$56+6-'🌱 Configuração'!$D$56)/7)+1=3),"🍄 Beauveria bassiana — solo | ⚠️ Umid <45%",IF(AND('🌱 Configuração'!$B$56+6>='🌱 Configuração'!$D$56,'🌱 Configuração'!$B$56+6<'🌱 Configuração'!$E$56,MOD('🌱 Configuração'!$B$56+6-'🌱 Configuração'!$D$56,7)=0,INT(('🌱 Configuração'!$B$56+6-'🌱 Configuração'!$D$56)/7)+1=4),"🦠 Trichoderma — solo | Inspecionar buds",IF(AND('🌱 Configuração'!$B$56+6>='🌱 Configuração'!$D$56,'🌱 Configuração'!$B$56+6<'🌱 Configuração'!$E$56,MOD('🌱 Configuração'!$B$56+6-'🌱 Configuração'!$D$56,7)=0,INT(('🌱 Configuração'!$B$56+6-'🌱 Configuração'!$D$56)/7)+1=5),"🍄 Beauveria + inspeção visual buds",IF(AND('🌱 Configuração'!$B$56+6>='🌱 Configuração'!$D$56,'🌱 Configuração'!$B$56+6<'🌱 Configuração'!$E$56,MOD('🌱 Configuração'!$B$56+6-'🌱 Configuração'!$D$56,7)=0,INT(('🌱 Configuração'!$B$56+6-'🌱 Configuração'!$D$56)/7)+1=6),"🦠 Trichoderma + ⚠️ Verificar mofo","")))))),IF(AND('🌱 Configuração'!$B$56+6>='🌱 Configuração'!$E$56,MOD('🌱 Configuração'!$B$56+6-'🌱 Configuração'!$E$56,7)=0),"🔬 Inspeção final — analisar tricomas","")))))
B13: =IF(8<='🌱 Configuração'!$F$55,8,"") -> 8 | C13: =IF(8<='🌱 Configuração'!$F$55,'🌱 Configuração'!$B$56+7,"") -> 7 | D13: =IF(8>'🌱 Configuração'!$F$55,"",IF('🌱 Configuração'!$B$56+7<'🌱 Configuração'!$C$56,"🌱 Clone",IF('🌱 Configuração'!$B$56+7<'🌱 Configuração'!$D$56,"🌿 Vegetativo",IF('🌱 Configuração'!$B$56+7<'🌱 Configuração'!$E$56,"🌸 Floração","🚿 Flush")))) -> 🌱 Clone | E13: =IF(8>'🌱 Configuração'!$F$55,"",IF('🌱 Configuração'!$B$56+7<'🌱 Configuração'!$C$56,"Clone S"&INT((8-1)/7)+1,IF('🌱 Configuração'!$B$56+7<'🌱 Configuração'!$D$56,"Vega S"&INT(('🌱 Configuração'!$B$56+7-'🌱 Configuração'!$C$56)/7)+1,IF('🌱 Configuração'!$B$56+7<'🌱 Configuração'!$E$56,"Flora S"&INT(('🌱 Configuração'!$B$56+7-'🌱 Configuração'!$D$56)/7)+1,"Flush S"&INT(('🌱 Configuração'!$B$56+7-'🌱 Configuração'!$E$56)/7)+1)))) -> Clone S2 | F13: =IF(8>'🌱 Configuração'!$F$55,"",IF('🌱 Configuração'!$B$56+7='🌱 Configuração'!$C$56,"🌿 INÍCIO VEGA — luz 18h/dia",IF('🌱 Configuração'!$B$56+7='🌱 Configuração'!$D$56,"🌸 INÍCIO FLORAÇÃO — mudar 12/12 🔴",IF('🌱 Configuração'!$B$56+7='🌱 Configuração'!$E$56,"🚿 INÍCIO FLUSH — parar nutrição",IF('🌱 Configuração'!$B$56+7='🌱 Configuração'!$F$56-1,"🔬 Véspera da colheita — analisar tricomas",IF('🌱 Configuração'!$B$56+7='🌱 Configuração'!$F$56,"✂️ COLHEITA — Parabéns! 🎉","")))))) | G13: Root Juice 0.3 mL/L | Alg·A·Mic 0.5 mL/L | H13: =IF(8>'🌱 Configuração'!$F$55,"",IF('🌱 Configuração'!$B$56+7<'🌱 Configuração'!$C$56,IF(8=1,"🌿 Nim (2 mL/L) — foliar leve",IF(8=8,"🍄 Beauveria bassiana — foliar + solo","")),IF('🌱 Configuração'!$B$56+7<'🌱 Configuração'!$D$56,IF(AND('🌱 Configuração'!$B$56+7>='🌱 Configuração'!$C$56,'🌱 Configuração'!$B$56+7<'🌱 Configuração'!$D$56,MOD('🌱 Configuração'!$B$56+7-'🌱 Configuração'!$C$56,7)=0,INT(('🌱 Configuração'!$B$56+7-'🌱 Configuração'!$C$56)/7)+1=1),"🌿 Nim (2 mL/L) — foliar preventivo",IF(AND('🌱 Configuração'!$B$56+7>='🌱 Configuração'!$C$56,'🌱 Configuração'!$B$56+7<'🌱 Configuração'!$D$56,MOD('🌱 Configuração'!$B$56+7-'🌱 Configuração'!$C$56,7)=0,INT(('🌱 Configuração'!$B$56+7-'🌱 Configuração'!$C$56)/7)+1=2),"🍄 Beauveria bassiana — foliar + solo",IF(AND('🌱 Configuração'!$B$56+7>='🌱 Configuração'!$C$56,'🌱 Configuração'!$B$56+7<'🌱 Configuração'!$D$56,MOD('🌱 Configuração'!$B$56+7-'🌱 Configuração'!$C$56,7)=0,INT(('🌱 Configuração'!$B$56+7-'🌱 Configuração'!$C$56)/7)+1=3),"🟡 Calda Sulfocálcica (1%) — foliar",IF(AND('🌱 Configuração'!$B$56+7>='🌱 Configuração'!$C$56,'🌱 Configuração'!$B$56+7<'🌱 Configuração'!$D$56,MOD('🌱 Configuração'!$B$56+7-'🌱 Configuração'!$C$56,7)=0,INT(('🌱 Configuração'!$B$56+7-'🌱 Configuração'!$C$56)/7)+1=4),"🦠 Trichoderma (3 g/L) — solo",IF(AND('🌱 Configuração'!$B$56+7>='🌱 Configuração'!$C$56,'🌱 Configuração'!$B$56+7<'🌱 Configuração'!$D$56,MOD('🌱 Configuração'!$B$56+7-'🌱 Configuração'!$C$56,7)=0,INT(('🌱 Configuração'!$B$56+7-'🌱 Configuração'!$C$56)/7)+1=5),"🔵 Calda Bordalesa (0.5%) — foliar",IF(AND('🌱 Configuração'!$B$56+7>='🌱 Configuração'!$C$56,'🌱 Configuração'!$B$56+7<'🌱 Configuração'!$D$56,MOD('🌱 Configuração'!$B$56+7-'🌱 Configuração'!$C$56,7)=0,INT(('🌱 Configuração'!$B$56+7-'🌱 Configuração'!$C$56)/7)+1=6),"🌿 Nim (2 mL/L) — ⚠️ ÚLTIMA foliar",IF(AND('🌱 Configuração'!$B$56+7>='🌱 Configuração'!$C$56,'🌱 Configuração'!$B$56+7<'🌱 Configuração'!$D$56,MOD('🌱 Configuração'!$B$56+7-'🌱 Configuração'!$C$56,7)=0,INT(('🌱 Configuração'!$B$56+7-'🌱 Configuração'!$C$56)/7)+1=7),"🦠 Trichoderma — solo",IF(AND('🌱 Configuração'!$B$56+7>='🌱 Configuração'!$C$56,'🌱 Configuração'!$B$56+7<'🌱 Configuração'!$D$56,MOD('🌱 Configuração'!$B$56+7-'🌱 Configuração'!$C$56,7)=0,INT(('🌱 Configuração'!$B$56+7-'🌱 Configuração'!$C$56)/7)+1=8),"🍄 Beauveria — solo","")))))))),IF('🌱 Configuração'!$B$56+7<'🌱 Configuração'!$E$56,IF(AND('🌱 Configuração'!$B$56+7>='🌱 Configuração'!$D$56,'🌱 Configuração'!$B$56+7<'🌱 Configuração'!$E$56,MOD('🌱 Configuração'!$B$56+7-'🌱 Configuração'!$D$56,7)=0,INT(('🌱 Configuração'!$B$56+7-'🌱 Configuração'!$D$56)/7)+1=1),"🍄 Beauveria bassiana — SOLO apenas",IF(AND('🌱 Configuração'!$B$56+7>='🌱 Configuração'!$D$56,'🌱 Configuração'!$B$56+7<'🌱 Configuração'!$E$56,MOD('🌱 Configuração'!$B$56+7-'🌱 Configuração'!$D$56,7)=0,INT(('🌱 Configuração'!$B$56+7-'🌱 Configuração'!$D$56)/7)+1=2),"🦠 Trichoderma (3 g/L) — solo",IF(AND('🌱 Configuração'!$B$56+7>='🌱 Configuração'!$D$56,'🌱 Configuração'!$B$56+7<'🌱 Configuração'!$E$56,MOD('🌱 Configuração'!$B$56+7-'🌱 Configuração'!$D$56,7)=0,INT(('🌱 Configuração'!$B$56+7-'🌱 Configuração'!$D$56)/7)+1=3),"🍄 Beauveria bassiana — solo | ⚠️ Umid <45%",IF(AND('🌱 Configuração'!$B$56+7>='🌱 Configuração'!$D$56,'🌱 Configuração'!$B$56+7<'🌱 Configuração'!$E$56,MOD('🌱 Configuração'!$B$56+7-'🌱 Configuração'!$D$56,7)=0,INT(('🌱 Configuração'!$B$56+7-'🌱 Configuração'!$D$56)/7)+1=4),"🦠 Trichoderma — solo | Inspecionar buds",IF(AND('🌱 Configuração'!$B$56+7>='🌱 Configuração'!$D$56,'🌱 Configuração'!$B$56+7<'🌱 Configuração'!$E$56,MOD('🌱 Configuração'!$B$56+7-'🌱 Configuração'!$D$56,7)=0,INT(('🌱 Configuração'!$B$56+7-'🌱 Configuração'!$D$56)/7)+1=5),"🍄 Beauveria + inspeção visual buds",IF(AND('🌱 Configuração'!$B$56+7>='🌱 Configuração'!$D$56,'🌱 Configuração'!$B$56+7<'🌱 Configuração'!$E$56,MOD('🌱 Configuração'!$B$56+7-'🌱 Configuração'!$D$56,7)=0,INT(('🌱 Configuração'!$B$56+7-'🌱 Configuração'!$D$56)/7)+1=6),"🦠 Trichoderma + ⚠️ Verificar mofo","")))))),IF(AND('🌱 Configuração'!$B$56+7>='🌱 Configuração'!$E$56,MOD('🌱 Configuração'!$B$56+7-'🌱 Configuração'!$E$56,7)=0),"🔬 Inspeção final — analisar tricomas",""))))) -> 🍄 Beauveria bassiana — foliar + solo
B14: =IF(9<='🌱 Configuração'!$F$55,9,"") -> 9 | C14: =IF(9<='🌱 Configuração'!$F$55,'🌱 Configuração'!$B$56+8,"") -> 8 | D14: =IF(9>'🌱 Configuração'!$F$55,"",IF('🌱 Configuração'!$B$56+8<'🌱 Configuração'!$C$56,"🌱 Clone",IF('🌱 Configuração'!$B$56+8<'🌱 Configuração'!$D$56,"🌿 Vegetativo",IF('🌱 Configuração'!$B$56+8<'🌱 Configuração'!$E$56,"🌸 Floração","🚿 Flush")))) -> 🌱 Clone | E14: =IF(9>'🌱 Configuração'!$F$55,"",IF('🌱 Configuração'!$B$56+8<'🌱 Configuração'!$C$56,"Clone S"&INT((9-1)/7)+1,IF('🌱 Configuração'!$B$56+8<'🌱 Configuração'!$D$56,"Vega S"&INT(('🌱 Configuração'!$B$56+8-'🌱 Configuração'!$C$56)/7)+1,IF('🌱 Configuração'!$B$56+8<'🌱 Configuração'!$E$56,"Flora S"&INT(('🌱 Configuração'!$B$56+8-'🌱 Configuração'!$D$56)/7)+1,"Flush S"&INT(('🌱 Configuração'!$B$56+8-'🌱 Configuração'!$E$56)/7)+1)))) -> Clone S2 | F14: =IF(9>'🌱 Configuração'!$F$55,"",IF('🌱 Configuração'!$B$56+8='🌱 Configuração'!$C$56,"🌿 INÍCIO VEGA — luz 18h/dia",IF('🌱 Configuração'!$B$56+8='🌱 Configuração'!$D$56,"🌸 INÍCIO FLORAÇÃO — mudar 12/12 🔴",IF('🌱 Configuração'!$B$56+8='🌱 Configuração'!$E$56,"🚿 INÍCIO FLUSH — parar nutrição",IF('🌱 Configuração'!$B$56+8='🌱 Configuração'!$F$56-1,"🔬 Véspera da colheita — analisar tricomas",IF('🌱 Configuração'!$B$56+8='🌱 Configuração'!$F$56,"✂️ COLHEITA — Parabéns! 🎉","")))))) | H14: =IF(9>'🌱 Configuração'!$F$55,"",IF('🌱 Configuração'!$B$56+8<'🌱 Configuração'!$C$56,IF(9=1,"🌿 Nim (2 mL/L) — foliar leve",IF(9=8,"🍄 Beauveria bassiana — foliar + solo","")),IF('🌱 Configuração'!$B$56+8<'🌱 Configuração'!$D$56,IF(AND('🌱 Configuração'!$B$56+8>='🌱 Configuração'!$C$56,'🌱 Configuração'!$B$56+8<'🌱 Configuração'!$D$56,MOD('🌱 Configuração'!$B$56+8-'🌱 Configuração'!$C$56,7)=0,INT(('🌱 Configuração'!$B$56+8-'🌱 Configuração'!$C$56)/7)+1=1),"🌿 Nim (2 mL/L) — foliar preventivo",IF(AND('🌱 Configuração'!$B$56+8>='🌱 Configuração'!$C$56,'🌱 Configuração'!$B$56+8<'🌱 Configuração'!$D$56,MOD('🌱 Configuração'!$B$56+8-'🌱 Configuração'!$C$56,7)=0,INT(('🌱 Configuração'!$B$56+8-'🌱 Configuração'!$C$56)/7)+1=2),"🍄 Beauveria bassiana — foliar + solo",IF(AND('🌱 Configuração'!$B$56+8>='🌱 Configuração'!$C$56,'🌱 Configuração'!$B$56+8<'🌱 Configuração'!$D$56,MOD('🌱 Configuração'!$B$56+8-'🌱 Configuração'!$C$56,7)=0,INT(('🌱 Configuração'!$B$56+8-'🌱 Configuração'!$C$56)/7)+1=3),"🟡 Calda Sulfocálcica (1%) — foliar",IF(AND('🌱 Configuração'!$B$56+8>='🌱 Configuração'!$C$56,'🌱 Configuração'!$B$56+8<'🌱 Configuração'!$D$56,MOD('🌱 Configuração'!$B$56+8-'🌱 Configuração'!$C$56,7)=0,INT(('🌱 Configuração'!$B$56+8-'🌱 Configuração'!$C$56)/7)+1=4),"🦠 Trichoderma (3 g/L) — solo",IF(AND('🌱 Configuração'!$B$56+8>='🌱 Configuração'!$C$56,'🌱 Configuração'!$B$56+8<'🌱 Configuração'!$D$56,MOD('🌱 Configuração'!$B$56+8-'🌱 Configuração'!$C$56,7)=0,INT(('🌱 Configuração'!$B$56+8-'🌱 Configuração'!$C$56)/7)+1=5),"🔵 Calda Bordalesa (0.5%) — foliar",IF(AND('🌱 Configuração'!$B$56+8>='🌱 Configuração'!$C$56,'🌱 Configuração'!$B$56+8<'🌱 Configuração'!$D$56,MOD('🌱 Configuração'!$B$56+8-'🌱 Configuração'!$C$56,7)=0,INT(('🌱 Configuração'!$B$56+8-'🌱 Configuração'!$C$56)/7)+1=6),"🌿 Nim (2 mL/L) — ⚠️ ÚLTIMA foliar",IF(AND('🌱 Configuração'!$B$56+8>='🌱 Configuração'!$C$56,'🌱 Configuração'!$B$56+8<'🌱 Configuração'!$D$56,MOD('🌱 Configuração'!$B$56+8-'🌱 Configuração'!$C$56,7)=0,INT(('🌱 Configuração'!$B$56+8-'🌱 Configuração'!$C$56)/7)+1=7),"🦠 Trichoderma — solo",IF(AND('🌱 Configuração'!$B$56+8>='🌱 Configuração'!$C$56,'🌱 Configuração'!$B$56+8<'🌱 Configuração'!$D$56,MOD('🌱 Configuração'!$B$56+8-'🌱 Configuração'!$C$56,7)=0,INT(('🌱 Configuração'!$B$56+8-'🌱 Configuração'!$C$56)/7)+1=8),"🍄 Beauveria — solo","")))))))),IF('🌱 Configuração'!$B$56+8<'🌱 Configuração'!$E$56,IF(AND('🌱 Configuração'!$B$56+8>='🌱 Configuração'!$D$56,'🌱 Configuração'!$B$56+8<'🌱 Configuração'!$E$56,MOD('🌱 Configuração'!$B$56+8-'🌱 Configuração'!$D$56,7)=0,INT(('🌱 Configuração'!$B$56+8-'🌱 Configuração'!$D$56)/7)+1=1),"🍄 Beauveria bassiana — SOLO apenas",IF(AND('🌱 Configuração'!$B$56+8>='🌱 Configuração'!$D$56,'🌱 Configuração'!$B$56+8<'🌱 Configuração'!$E$56,MOD('🌱 Configuração'!$B$56+8-'🌱 Configuração'!$D$56,7)=0,INT(('🌱 Configuração'!$B$56+8-'🌱 Configuração'!$D$56)/7)+1=2),"🦠 Trichoderma (3 g/L) — solo",IF(AND('🌱 Configuração'!$B$56+8>='🌱 Configuração'!$D$56,'🌱 Configuração'!$B$56+8<'🌱 Configuração'!$E$56,MOD('🌱 Configuração'!$B$56+8-'🌱 Configuração'!$D$56,7)=0,INT(('🌱 Configuração'!$B$56+8-'🌱 Configuração'!$D$56)/7)+1=3),"🍄 Beauveria bassiana — solo | ⚠️ Umid <45%",IF(AND('🌱 Configuração'!$B$56+8>='🌱 Configuração'!$D$56,'🌱 Configuração'!$B$56+8<'🌱 Configuração'!$E$56,MOD('🌱 Configuração'!$B$56+8-'🌱 Configuração'!$D$56,7)=0,INT(('🌱 Configuração'!$B$56+8-'🌱 Configuração'!$D$56)/7)+1=4),"🦠 Trichoderma — solo | Inspecionar buds",IF(AND('🌱 Configuração'!$B$56+8>='🌱 Configuração'!$D$56,'🌱 Configuração'!$B$56+8<'🌱 Configuração'!$E$56,MOD('🌱 Configuração'!$B$56+8-'🌱 Configuração'!$D$56,7)=0,INT(('🌱 Configuração'!$B$56+8-'🌱 Configuração'!$D$56)/7)+1=5),"🍄 Beauveria + inspeção visual buds",IF(AND('🌱 Configuração'!$B$56+8>='🌱 Configuração'!$D$56,'🌱 Configuração'!$B$56+8<'🌱 Configuração'!$E$56,MOD('🌱 Configuração'!$B$56+8-'🌱 Configuração'!$D$56,7)=0,INT(('🌱 Configuração'!$B$56+8-'🌱 Configuração'!$D$56)/7)+1=6),"🦠 Trichoderma + ⚠️ Verificar mofo","")))))),IF(AND('🌱 Configuração'!$B$56+8>='🌱 Configuração'!$E$56,MOD('🌱 Configuração'!$B$56+8-'🌱 Configuração'!$E$56,7)=0),"🔬 Inspeção final — analisar tricomas","")))))
B15: =IF(10<='🌱 Configuração'!$F$55,10,"") -> 10 | C15: =IF(10<='🌱 Configuração'!$F$55,'🌱 Configuração'!$B$56+9,"") -> 9 | D15: =IF(10>'🌱 Configuração'!$F$55,"",IF('🌱 Configuração'!$B$56+9<'🌱 Configuração'!$C$56,"🌱 Clone",IF('🌱 Configuração'!$B$56+9<'🌱 Configuração'!$D$56,"🌿 Vegetativo",IF('🌱 Configuração'!$B$56+9<'🌱 Configuração'!$E$56,"🌸 Floração","🚿 Flush")))) -> 🌱 Clone | E15: =IF(10>'🌱 Configuração'!$F$55,"",IF('🌱 Configuração'!$B$56+9<'🌱 Configuração'!$C$56,"Clone S"&INT((10-1)/7)+1,IF('🌱 Configuração'!$B$56+9<'🌱 Configuração'!$D$56,"Vega S"&INT(('🌱 Configuração'!$B$56+9-'🌱 Configuração'!$C$56)/7)+1,IF('🌱 Configuração'!$B$56+9<'🌱 Configuração'!$E$56,"Flora S"&INT(('🌱 Configuração'!$B$56+9-'🌱 Configuração'!$D$56)/7)+1,"Flush S"&INT(('🌱 Configuração'!$B$56+9-'🌱 Configuração'!$E$56)/7)+1)))) -> Clone S2 | F15: =IF(10>'🌱 Configuração'!$F$55,"",IF('🌱 Configuração'!$B$56+9='🌱 Configuração'!$C$56,"🌿 INÍCIO VEGA — luz 18h/dia",IF('🌱 Configuração'!$B$56+9='🌱 Configuração'!$D$56,"🌸 INÍCIO FLORAÇÃO — mudar 12/12 🔴",IF('🌱 Configuração'!$B$56+9='🌱 Configuração'!$E$56,"🚿 INÍCIO FLUSH — parar nutrição",IF('🌱 Configuração'!$B$56+9='🌱 Configuração'!$F$56-1,"🔬 Véspera da colheita — analisar tricomas",IF('🌱 Configuração'!$B$56+9='🌱 Configuração'!$F$56,"✂️ COLHEITA — Parabéns! 🎉","")))))) | H15: =IF(10>'🌱 Configuração'!$F$55,"",IF('🌱 Configuração'!$B$56+9<'🌱 Configuração'!$C$56,IF(10=1,"🌿 Nim (2 mL/L) — foliar leve",IF(10=8,"🍄 Beauveria bassiana — foliar + solo","")),IF('🌱 Configuração'!$B$56+9<'🌱 Configuração'!$D$56,IF(AND('🌱 Configuração'!$B$56+9>='🌱 Configuração'!$C$56,'🌱 Configuração'!$B$56+9<'🌱 Configuração'!$D$56,MOD('🌱 Configuração'!$B$56+9-'🌱 Configuração'!$C$56,7)=0,INT(('🌱 Configuração'!$B$56+9-'🌱 Configuração'!$C$56)/7)+1=1),"🌿 Nim (2 mL/L) — foliar preventivo",IF(AND('🌱 Configuração'!$B$56+9>='🌱 Configuração'!$C$56,'🌱 Configuração'!$B$56+9<'🌱 Configuração'!$D$56,MOD('🌱 Configuração'!$B$56+9-'🌱 Configuração'!$C$56,7)=0,INT(('🌱 Configuração'!$B$56+9-'🌱 Configuração'!$C$56)/7)+1=2),"🍄 Beauveria bassiana — foliar + solo",IF(AND('🌱 Configuração'!$B$56+9>='🌱 Configuração'!$C$56,'🌱 Configuração'!$B$56+9<'🌱 Configuração'!$D$56,MOD('🌱 Configuração'!$B$56+9-'🌱 Configuração'!$C$56,7)=0,INT(('🌱 Configuração'!$B$56+9-'🌱 Configuração'!$C$56)/7)+1=3),"🟡 Calda Sulfocálcica (1%) — foliar",IF(AND('🌱 Configuração'!$B$56+9>='🌱 Configuração'!$C$56,'🌱 Configuração'!$B$56+9<'🌱 Configuração'!$D$56,MOD('🌱 Configuração'!$B$56+9-'🌱 Configuração'!$C$56,7)=0,INT(('🌱 Configuração'!$B$56+9-'🌱 Configuração'!$C$56)/7)+1=4),"🦠 Trichoderma (3 g/L) — solo",IF(AND('🌱 Configuração'!$B$56+9>='🌱 Configuração'!$C$56,'🌱 Configuração'!$B$56+9<'🌱 Configuração'!$D$56,MOD('🌱 Configuração'!$B$56+9-'🌱 Configuração'!$C$56,7)=0,INT(('🌱 Configuração'!$B$56+9-'🌱 Configuração'!$C$56)/7)+1=5),"🔵 Calda Bordalesa (0.5%) — foliar",IF(AND('🌱 Configuração'!$B$56+9>='🌱 Configuração'!$C$56,'🌱 Configuração'!$B$56+9<'🌱 Configuração'!$D$56,MOD('🌱 Configuração'!$B$56+9-'🌱 Configuração'!$C$56,7)=0,INT(('🌱 Configuração'!$B$56+9-'🌱 Configuração'!$C$56)/7)+1=6),"🌿 Nim (2 mL/L) — ⚠️ ÚLTIMA foliar",IF(AND('🌱 Configuração'!$B$56+9>='🌱 Configuração'!$C$56,'🌱 Configuração'!$B$56+9<'🌱 Configuração'!$D$56,MOD('🌱 Configuração'!$B$56+9-'🌱 Configuração'!$C$56,7)=0,INT(('🌱 Configuração'!$B$56+9-'🌱 Configuração'!$C$56)/7)+1=7),"🦠 Trichoderma — solo",IF(AND('🌱 Configuração'!$B$56+9>='🌱 Configuração'!$C$56,'🌱 Configuração'!$B$56+9<'🌱 Configuração'!$D$56,MOD('🌱 Configuração'!$B$56+9-'🌱 Configuração'!$C$56,7)=0,INT(('🌱 Configuração'!$B$56+9-'🌱 Configuração'!$C$56)/7)+1=8),"🍄 Beauveria — solo","")))))))),IF('🌱 Configuração'!$B$56+9<'🌱 Configuração'!$E$56,IF(AND('🌱 Configuração'!$B$56+9>='🌱 Configuração'!$D$56,'🌱 Configuração'!$B$56+9<'🌱 Configuração'!$E$56,MOD('🌱 Configuração'!$B$56+9-'🌱 Configuração'!$D$56,7)=0,INT(('🌱 Configuração'!$B$56+9-'🌱 Configuração'!$D$56)/7)+1=1),"🍄 Beauveria bassiana — SOLO apenas",IF(AND('🌱 Configuração'!$B$56+9>='🌱 Configuração'!$D$56,'🌱 Configuração'!$B$56+9<'🌱 Configuração'!$E$56,MOD('🌱 Configuração'!$B$56+9-'🌱 Configuração'!$D$56,7)=0,INT(('🌱 Configuração'!$B$56+9-'🌱 Configuração'!$D$56)/7)+1=2),"🦠 Trichoderma (3 g/L) — solo",IF(AND('🌱 Configuração'!$B$56+9>='🌱 Configuração'!$D$56,'🌱 Configuração'!$B$56+9<'🌱 Configuração'!$E$56,MOD('🌱 Configuração'!$B$56+9-'🌱 Configuração'!$D$56,7)=0,INT(('🌱 Configuração'!$B$56+9-'🌱 Configuração'!$D$56)/7)+1=3),"🍄 Beauveria bassiana — solo | ⚠️ Umid <45%",IF(AND('🌱 Configuração'!$B$56+9>='🌱 Configuração'!$D$56,'🌱 Configuração'!$B$56+9<'🌱 Configuração'!$E$56,MOD('🌱 Configuração'!$B$56+9-'🌱 Configuração'!$D$56,7)=0,INT(('🌱 Configuração'!$B$56+9-'🌱 Configuração'!$D$56)/7)+1=4),"🦠 Trichoderma — solo | Inspecionar buds",IF(AND('🌱 Configuração'!$B$56+9>='🌱 Configuração'!$D$56,'🌱 Configuração'!$B$56+9<'🌱 Configuração'!$E$56,MOD('🌱 Configuração'!$B$56+9-'🌱 Configuração'!$D$56,7)=0,INT(('🌱 Configuração'!$B$56+9-'🌱 Configuração'!$D$56)/7)+1=5),"🍄 Beauveria + inspeção visual buds",IF(AND('🌱 Configuração'!$B$56+9>='🌱 Configuração'!$D$56,'🌱 Configuração'!$B$56+9<'🌱 Configuração'!$E$56,MOD('🌱 Configuração'!$B$56+9-'🌱 Configuração'!$D$56,7)=0,INT(('🌱 Configuração'!$B$56+9-'🌱 Configuração'!$D$56)/7)+1=6),"🦠 Trichoderma + ⚠️ Verificar mofo","")))))),IF(AND('🌱 Configuração'!$B$56+9>='🌱 Configuração'!$E$56,MOD('🌱 Configuração'!$B$56+9-'🌱 Configuração'!$E$56,7)=0),"🔬 Inspeção final — analisar tricomas","")))))
